==5813== Memcheck, a memory error detector
==5813== Copyright (C) 2002-2022, and GNU GPL'd, by Julian Seward et al.
==5813== Using Valgrind-3.19.0-8d3c8034b8-20220411 and LibVEX; rerun with -h for copyright info
==5813== Command: /home/rut/.local/bin/main
==5813== Parent PID: 4724
==5813== 
--5813-- 
--5813-- Valgrind options:
--5813--    --leak-check=full
--5813--    --show-leak-kinds=all
--5813--    --track-origins=yes
--5813--    --verbose
--5813--    --log-file=valgrind-out.txt
--5813-- Contents of /proc/version:
--5813--   Linux version 6.1.0-17-amd64 (debian-kernel@lists.debian.org) (gcc-12 (Debian 12.2.0-14) 12.2.0, GNU ld (GNU Binutils for Debian) 2.40) #1 SMP PREEMPT_DYNAMIC Debian 6.1.69-1 (2023-12-30)
--5813-- 
--5813-- Arch and hwcaps: AMD64, LittleEndian, amd64-cx16-lzcnt-rdtscp-sse3-ssse3-avx-avx2-bmi-f16c-rdrand-rdseed
--5813-- Page sizes: currently 4096, max supported 4096
--5813-- Valgrind library directory: /usr/libexec/valgrind
--5813-- Reading syms from /usr/bin/python3.11
--5813--    object doesn't have a symbol table
--5813-- Reading syms from /usr/lib/x86_64-linux-gnu/ld-linux-x86-64.so.2
--5813--   Considering /usr/lib/debug/.build-id/38/e7d4a67acf053c794b3b8094e6900b5163f37d.debug ..
--5813--   .. build-id is valid
--5813-- Reading syms from /usr/libexec/valgrind/memcheck-amd64-linux
--5813--   Considering /usr/lib/debug/.build-id/82/26c2aa6b808ebd5a6fafb694a7fb3287f33590.debug ..
--5813--   .. build-id is valid
--5813--    object doesn't have a dynamic symbol table
--5813-- Scheduler: using generic scheduler lock implementation.
--5813-- Reading suppressions file: /usr/libexec/valgrind/default.supp
==5813== embedded gdbserver: reading from /tmp/vgdb-pipe-from-vgdb-to-5813-by-rut-on-???
==5813== embedded gdbserver: writing to   /tmp/vgdb-pipe-to-vgdb-from-5813-by-rut-on-???
==5813== embedded gdbserver: shared mem   /tmp/vgdb-pipe-shared-mem-vgdb-5813-by-rut-on-???
==5813== 
==5813== TO CONTROL THIS PROCESS USING vgdb (which you probably
==5813== don't want to do, unless you know exactly what you're doing,
==5813== or are doing some strange experiment):
==5813==   /usr/bin/vgdb --pid=5813 ...command...
==5813== 
==5813== TO DEBUG THIS PROCESS USING GDB: start GDB like this
==5813==   /path/to/gdb /home/rut/.local/bin/main
==5813== and then give GDB the following command
==5813==   target remote | /usr/bin/vgdb --pid=5813
==5813== --pid is optional if only one valgrind process is running
==5813== 
--5813-- REDIR: 0x40236e0 (ld-linux-x86-64.so.2:strlen) redirected to 0x580bb0e2 (vgPlain_amd64_linux_REDIR_FOR_strlen)
--5813-- REDIR: 0x4021ec0 (ld-linux-x86-64.so.2:index) redirected to 0x580bb0fc (vgPlain_amd64_linux_REDIR_FOR_index)
--5813-- Reading syms from /usr/libexec/valgrind/vgpreload_core-amd64-linux.so
--5813--   Considering /usr/lib/debug/.build-id/ad/f1388be4d8781737b0c83fe111a5a9c6e930aa.debug ..
--5813--   .. build-id is valid
--5813-- Reading syms from /usr/libexec/valgrind/vgpreload_memcheck-amd64-linux.so
--5813--   Considering /usr/lib/debug/.build-id/d8/ec66cffcb23a75c3f15940674d6028709121f8.debug ..
--5813--   .. build-id is valid
==5813== WARNING: new redirection conflicts with existing -- ignoring it
--5813--     old: 0x040236e0 (strlen              ) R-> (0000.0) 0x580bb0e2 vgPlain_amd64_linux_REDIR_FOR_strlen
--5813--     new: 0x040236e0 (strlen              ) R-> (2007.0) 0x048468a0 strlen
--5813-- REDIR: 0x40220e0 (ld-linux-x86-64.so.2:strcmp) redirected to 0x4847780 (strcmp)
--5813-- REDIR: 0x4021350 (ld-linux-x86-64.so.2:mempcpy) redirected to 0x484b1a0 (mempcpy)
--5813-- Reading syms from /usr/lib/x86_64-linux-gnu/libm.so.6
--5813--   Considering /usr/lib/debug/.build-id/ea/87e1b3daf095cd53f1f99ab34a88827eccce80.debug ..
--5813--   .. build-id is valid
--5813-- Reading syms from /usr/lib/x86_64-linux-gnu/libz.so.1.2.13
--5813--    object doesn't have a symbol table
--5813-- Reading syms from /usr/lib/x86_64-linux-gnu/libexpat.so.1.8.10
--5813--    object doesn't have a symbol table
--5813-- Reading syms from /usr/lib/x86_64-linux-gnu/libc.so.6
--5813--   Considering /usr/lib/debug/.build-id/82/ce4e6e4ef08fa58a3535f7437bd3e592db5ac0.debug ..
--5813--   .. build-id is valid
==5813== WARNING: new redirection conflicts with existing -- ignoring it
--5813--     old: 0x04a36540 (memalign            ) R-> (1011.0) 0x04845bc0 memalign
--5813--     new: 0x04a36540 (memalign            ) R-> (1017.0) 0x04845b90 aligned_alloc
==5813== WARNING: new redirection conflicts with existing -- ignoring it
--5813--     old: 0x04a36540 (memalign            ) R-> (1011.0) 0x04845bc0 memalign
--5813--     new: 0x04a36540 (memalign            ) R-> (1017.0) 0x04845b60 aligned_alloc
--5813-- REDIR: 0x4a3c490 (libc.so.6:strnlen) redirected to 0x48371b0 (_vgnU_ifunc_wrapper)
--5813-- REDIR: 0x4a3c520 (libc.so.6:strpbrk) redirected to 0x48371b0 (_vgnU_ifunc_wrapper)
--5813-- REDIR: 0x4a3a640 (libc.so.6:strcmp) redirected to 0x48371b0 (_vgnU_ifunc_wrapper)
--5813-- REDIR: 0x4a4f420 (libc.so.6:wcsnlen) redirected to 0x48371b0 (_vgnU_ifunc_wrapper)
--5813-- REDIR: 0x4a39780 (libc.so.6:memset) redirected to 0x48371b0 (_vgnU_ifunc_wrapper)
--5813-- REDIR: 0x4a4dd60 (libc.so.6:wcslen) redirected to 0x48371b0 (_vgnU_ifunc_wrapper)
--5813-- REDIR: 0x4a38db0 (libc.so.6:memcpy@@GLIBC_2.14) redirected to 0x48371b0 (_vgnU_ifunc_wrapper)
--5813-- REDIR: 0x4a4db90 (libc.so.6:wcschr) redirected to 0x48371b0 (_vgnU_ifunc_wrapper)
--5813-- REDIR: 0x4a3a530 (libc.so.6:index) redirected to 0x48371b0 (_vgnU_ifunc_wrapper)
--5813-- REDIR: 0x4a3c550 (libc.so.6:rindex) redirected to 0x48371b0 (_vgnU_ifunc_wrapper)
--5813-- REDIR: 0x4a4dc20 (libc.so.6:wcscmp) redirected to 0x48371b0 (_vgnU_ifunc_wrapper)
--5813-- REDIR: 0x4a399c0 (libc.so.6:stpncpy) redirected to 0x48371b0 (_vgnU_ifunc_wrapper)
--5813-- REDIR: 0x4a4e170 (libc.so.6:wmemchr) redirected to 0x48371b0 (_vgnU_ifunc_wrapper)
--5813-- REDIR: 0x4a3c340 (libc.so.6:strncmp) redirected to 0x48371b0 (_vgnU_ifunc_wrapper)
--5813-- REDIR: 0x4a39a30 (libc.so.6:strcasecmp) redirected to 0x48371b0 (_vgnU_ifunc_wrapper)
--5813-- REDIR: 0x4a3b8a0 (libc.so.6:strcspn) redirected to 0x48371b0 (_vgnU_ifunc_wrapper)
--5813-- REDIR: 0x4a4dcb0 (libc.so.6:wcscpy) redirected to 0x48371b0 (_vgnU_ifunc_wrapper)
--5813-- REDIR: 0x4a3a4b0 (libc.so.6:strcat) redirected to 0x48371b0 (_vgnU_ifunc_wrapper)
--5813-- REDIR: 0x4a3c230 (libc.so.6:strncasecmp_l) redirected to 0x48371b0 (_vgnU_ifunc_wrapper)
--5813-- REDIR: 0x4a38cc0 (libc.so.6:bcmp) redirected to 0x48371b0 (_vgnU_ifunc_wrapper)
--5813-- REDIR: 0x4a396f0 (libc.so.6:memrchr) redirected to 0x48371b0 (_vgnU_ifunc_wrapper)
--5813-- REDIR: 0x4a3a5b0 (libc.so.6:strchrnul) redirected to 0x48371b0 (_vgnU_ifunc_wrapper)
--5813-- REDIR: 0x4a3b820 (libc.so.6:strcpy) redirected to 0x48371b0 (_vgnU_ifunc_wrapper)
--5813-- REDIR: 0x4a39ad0 (libc.so.6:strcasecmp_l) redirected to 0x48371b0 (_vgnU_ifunc_wrapper)
--5813-- REDIR: 0x4a3c100 (libc.so.6:strlen) redirected to 0x48371b0 (_vgnU_ifunc_wrapper)
--5813-- REDIR: 0x4a3c3e0 (libc.so.6:strncpy) redirected to 0x48371b0 (_vgnU_ifunc_wrapper)
--5813-- REDIR: 0x4a39940 (libc.so.6:stpcpy) redirected to 0x48371b0 (_vgnU_ifunc_wrapper)
--5813-- REDIR: 0x4a394d0 (libc.so.6:memmove) redirected to 0x48371b0 (_vgnU_ifunc_wrapper)
==5813== Preferring higher priority redirection:
--5813--     old: 0x04aef780 (__memcpy_avx_unalign) R-> (2018.0) 0x04848a60 __memcpy_avx_unaligned_erms
--5813--     new: 0x04aef780 (__memcpy_avx_unalign) R-> (2018.1) 0x0484a2b0 memmove
--5813-- REDIR: 0x4a38c40 (libc.so.6:memchr) redirected to 0x48371b0 (_vgnU_ifunc_wrapper)
--5813-- REDIR: 0x4a3c710 (libc.so.6:strspn) redirected to 0x48371b0 (_vgnU_ifunc_wrapper)
--5813-- REDIR: 0x4a395e0 (libc.so.6:mempcpy) redirected to 0x48371b0 (_vgnU_ifunc_wrapper)
--5813-- REDIR: 0x4a3c190 (libc.so.6:strncasecmp) redirected to 0x48371b0 (_vgnU_ifunc_wrapper)
--5813-- REDIR: 0x4a39880 (libc.so.6:rawmemchr) redirected to 0x48371b0 (_vgnU_ifunc_wrapper)
--5813-- REDIR: 0x4af5850 (libc.so.6:__strrchr_avx2) redirected to 0x48462e0 (rindex)
--5813-- REDIR: 0x4a35860 (libc.so.6:malloc) redirected to 0x4840740 (malloc)
--5813-- REDIR: 0x4af2f00 (libc.so.6:__strlen_avx2) redirected to 0x4846780 (strlen)
--5813-- REDIR: 0x4aef780 (libc.so.6:__memcpy_avx_unaligned_erms) redirected to 0x484a2b0 (memmove)
--5813-- REDIR: 0x4af2610 (libc.so.6:__strcmp_avx2) redirected to 0x4847680 (strcmp)
--5813-- REDIR: 0x4af45d0 (libc.so.6:__strncmp_avx2) redirected to 0x4846ed0 (strncmp)
--5813-- REDIR: 0x4aeed80 (libc.so.6:__memchr_avx2) redirected to 0x4847800 (memchr)
--5813-- REDIR: 0x4af21e0 (libc.so.6:__strchr_avx2) redirected to 0x4846460 (index)
--5813-- REDIR: 0x4af2420 (libc.so.6:__strchrnul_avx2) redirected to 0x484aca0 (strchrnul)
--5813-- REDIR: 0x4aef730 (libc.so.6:__mempcpy_avx_unaligned_erms) redirected to 0x484adb0 (mempcpy)
--5813-- REDIR: 0x4a35e20 (libc.so.6:free) redirected to 0x4843110 (free)
--5813-- REDIR: 0x4af0420 (libc.so.6:__stpcpy_avx2) redirected to 0x4849b60 (stpcpy)
--5813-- REDIR: 0x4a36610 (libc.so.6:calloc) redirected to 0x4845540 (calloc)
--5813-- REDIR: 0x4af5580 (libc.so.6:__strnlen_avx2) redirected to 0x4846720 (strnlen)
--5813-- REDIR: 0x4af6260 (libc.so.6:__wcslen_avx2) redirected to 0x484b7c0 (wcslen)
--5813-- REDIR: 0x4af5d40 (libc.so.6:__wcscmp_avx2) redirected to 0x484b850 (wcscmp)
--5813-- REDIR: 0x4a36060 (libc.so.6:realloc) redirected to 0x48457b0 (realloc)
--5813-- REDIR: 0x4af0180 (libc.so.6:__memset_avx2_unaligned_erms) redirected to 0x484a1c0 (memset)
--5813-- REDIR: 0x4aef020 (libc.so.6:__memcmp_avx2_movbe) redirected to 0x4849aa0 (bcmp)
--5813-- REDIR: 0x4aefe80 (libc.so.6:__memrchr_avx2) redirected to 0x4847860 (memrchr)
--5813-- REDIR: 0x49de420 (libc.so.6:unsetenv) redirected to 0x484bb00 (unsetenv)
--5813-- REDIR: 0x4b0c500 (libc.so.6:__wcscpy_ssse3) redirected to 0x484b8f0 (wcscpy)
--5813-- REDIR: 0x4af6a80 (libc.so.6:__wcsnlen_avx2) redirected to 0x484b7f0 (wcsnlen)
--5813-- REDIR: 0x4a4df50 (libc.so.6:wcsrchr) redirected to 0x48371b0 (_vgnU_ifunc_wrapper)
--5813-- REDIR: 0x4af6df0 (libc.so.6:__wcsrchr_avx2) redirected to 0x484b9e0 (wcsrchr)
--5813-- REDIR: 0x4af5b00 (libc.so.6:__wcschr_avx2) redirected to 0x484b9b0 (wcschr)
--5813-- REDIR: 0x4af4c20 (libc.so.6:__strncpy_avx2) redirected to 0x4846a50 (strncpy)
--5813-- REDIR: 0x4af2b70 (libc.so.6:__strcpy_avx2) redirected to 0x48468d0 (strcpy)
--5813-- Reading syms from /usr/lib/python3.11/lib-dynload/_curses.cpython-311-x86_64-linux-gnu.so
--5813--    object doesn't have a symbol table
--5813-- Reading syms from /usr/lib/x86_64-linux-gnu/libncursesw.so.6.4
--5813--    object doesn't have a symbol table
--5813-- Reading syms from /usr/lib/x86_64-linux-gnu/libtinfo.so.6.4
--5813--    object doesn't have a symbol table
--5813-- REDIR: 0x4a3c2d0 (libc.so.6:strncat) redirected to 0x48371b0 (_vgnU_ifunc_wrapper)
--5813-- REDIR: 0x4ab2fc0 (libc.so.6:__memcpy_chk) redirected to 0x48371b0 (_vgnU_ifunc_wrapper)
--5813-- REDIR: 0x4a3ceb0 (libc.so.6:strstr) redirected to 0x48371b0 (_vgnU_ifunc_wrapper)
--5813-- Reading syms from /usr/lib/python3.11/lib-dynload/termios.cpython-311-x86_64-linux-gnu.so
--5813--    object doesn't have a symbol table
--5813-- Reading syms from /usr/lib/python3.11/lib-dynload/_bz2.cpython-311-x86_64-linux-gnu.so
--5813--    object doesn't have a symbol table
--5813-- Reading syms from /usr/lib/x86_64-linux-gnu/libbz2.so.1.0.4
--5813--    object doesn't have a symbol table
--5813-- Reading syms from /usr/lib/python3.11/lib-dynload/_lzma.cpython-311-x86_64-linux-gnu.so
--5813--    object doesn't have a symbol table
--5813-- Reading syms from /usr/lib/x86_64-linux-gnu/liblzma.so.5.4.1
--5813--    object doesn't have a symbol table
--5813-- REDIR: 0x4aef740 (libc.so.6:__memcpy_chk_avx_unaligned_erms) redirected to 0x484b290 (__memcpy_chk)
--5813-- Reading syms from /usr/lib/python3.11/lib-dynload/_decimal.cpython-311-x86_64-linux-gnu.so
--5813--    object doesn't have a symbol table
--5813-- Reading syms from /usr/lib/python3.11/lib-dynload/_ctypes.cpython-311-x86_64-linux-gnu.so
--5813--    object doesn't have a symbol table
--5813-- Reading syms from /usr/lib/x86_64-linux-gnu/libffi.so.8.1.2
--5813--    object doesn't have a symbol table
--5813-- Reading syms from /usr/lib/python3.11/lib-dynload/resource.cpython-311-x86_64-linux-gnu.so
--5813--    object doesn't have a symbol table
--5813-- Reading syms from /usr/lib/python3.11/lib-dynload/_hashlib.cpython-311-x86_64-linux-gnu.so
--5813--    object doesn't have a symbol table
--5813-- Reading syms from /usr/lib/x86_64-linux-gnu/libcrypto.so.3
--5813--    object doesn't have a symbol table
--5813-- Reading syms from /usr/lib/python3.11/lib-dynload/_queue.cpython-311-x86_64-linux-gnu.so
--5813--    object doesn't have a symbol table
--5813-- Reading syms from /usr/lib/python3/dist-packages/psutil/_psutil_linux.cpython-311-x86_64-linux-gnu.so
--5813--    object doesn't have a symbol table
--5813-- Reading syms from /usr/lib/python3/dist-packages/psutil/_psutil_posix.cpython-311-x86_64-linux-gnu.so
--5813--    object doesn't have a symbol table
--5813-- REDIR: 0x4af1b70 (libc.so.6:__strcat_avx2) redirected to 0x4846490 (strcat)
--5813-- Reading syms from /usr/lib/python3.11/lib-dynload/_typing.cpython-311-x86_64-linux-gnu.so
--5813--    object doesn't have a symbol table
--5813-- Reading syms from /usr/lib/python3.11/lib-dynload/mmap.cpython-311-x86_64-linux-gnu.so
--5813--    object doesn't have a symbol table
--5813-- Reading syms from /usr/lib/python3.11/lib-dynload/_json.cpython-311-x86_64-linux-gnu.so
--5813--    object doesn't have a symbol table
--5813-- Reading syms from /usr/lib/python3/dist-packages/markupsafe/_speedups.cpython-311-x86_64-linux-gnu.so
--5813--    object doesn't have a symbol table
==5813== 
==5813== HEAP SUMMARY:
==5813==     in use at exit: 886,700 bytes in 531 blocks
==5813==   total heap usage: 24,206 allocs, 23,675 frees, 46,470,566 bytes allocated
==5813== 
==5813== Searching for pointers to 531 not-freed blocks
==5813== Checked 21,652,736 bytes
==5813== 
==5813== 1 bytes in 1 blocks are still reachable in loss record 1 of 174
==5813==    at 0x48407B4: malloc (vg_replace_malloc.c:381)
==5813==    by 0x50601E: PyMem_Malloc (in /usr/bin/python3.11)
==5813==    by 0x55A8FF: PyModule_ExecDef (in /usr/bin/python3.11)
==5813==    by 0x63BFCB: ??? (in /usr/bin/python3.11)
==5813==    by 0x5458A2: ??? (in /usr/bin/python3.11)
==5813==    by 0x5343AF: _PyEval_EvalFrameDefault (in /usr/bin/python3.11)
==5813==    by 0x55C930: _PyFunction_Vectorcall (in /usr/bin/python3.11)
==5813==    by 0x55BF93: ??? (in /usr/bin/python3.11)
==5813==    by 0x55B6FB: PyObject_CallMethod (in /usr/bin/python3.11)
==5813==    by 0x4FAB2A: ??? (in /usr/bin/python3.11)
==5813==    by 0x628925: ??? (in /usr/bin/python3.11)
==5813==    by 0x62863A: Py_InitializeFromConfig (in /usr/bin/python3.11)
==5813== 
==5813== 1 bytes in 1 blocks are still reachable in loss record 2 of 174
==5813==    at 0x48407B4: malloc (vg_replace_malloc.c:381)
==5813==    by 0x50601E: PyMem_Malloc (in /usr/bin/python3.11)
==5813==    by 0x55A8FF: PyModule_ExecDef (in /usr/bin/python3.11)
==5813==    by 0x63BFCB: ??? (in /usr/bin/python3.11)
==5813==    by 0x5458A2: ??? (in /usr/bin/python3.11)
==5813==    by 0x5343AF: _PyEval_EvalFrameDefault (in /usr/bin/python3.11)
==5813==    by 0x55C930: _PyFunction_Vectorcall (in /usr/bin/python3.11)
==5813==    by 0x54618E: ??? (in /usr/bin/python3.11)
==5813==    by 0x58351A: PyObject_CallMethodObjArgs (in /usr/bin/python3.11)
==5813==    by 0x451A10: ??? (in /usr/bin/python3.11)
==5813==    by 0x530A22: _PyEval_EvalFrameDefault (in /usr/bin/python3.11)
==5813==    by 0x52360A: PyEval_EvalCode (in /usr/bin/python3.11)
==5813== 
==5813== 10 bytes in 1 blocks are still reachable in loss record 3 of 174
==5813==    at 0x48407B4: malloc (vg_replace_malloc.c:381)
==5813==    by 0x4A3B8E9: strdup (strdup.c:42)
==5813==    by 0x59F91D7: ??? (in /usr/lib/x86_64-linux-gnu/libtinfo.so.6.4)
==5813==    by 0x59F99A7: _nc_first_db (in /usr/lib/x86_64-linux-gnu/libtinfo.so.6.4)
==5813==    by 0x5A04FA6: _nc_read_entry2 (in /usr/lib/x86_64-linux-gnu/libtinfo.so.6.4)
==5813==    by 0x59FC018: ??? (in /usr/lib/x86_64-linux-gnu/libtinfo.so.6.4)
==5813==    by 0x59FC3D5: _nc_setupterm (in /usr/lib/x86_64-linux-gnu/libtinfo.so.6.4)
==5813==    by 0x5978983: ??? (in /usr/lib/python3.11/lib-dynload/_curses.cpython-311-x86_64-linux-gnu.so)
==5813==    by 0x53ACF6: ??? (in /usr/bin/python3.11)
==5813==    by 0x53AC2B: PyObject_Vectorcall (in /usr/bin/python3.11)
==5813==    by 0x52B93F: _PyEval_EvalFrameDefault (in /usr/bin/python3.11)
==5813==    by 0x51F066: _PyObject_FastCallDictTstate (in /usr/bin/python3.11)
==5813== 
==5813== 15 bytes in 1 blocks are still reachable in loss record 4 of 174
==5813==    at 0x48407B4: malloc (vg_replace_malloc.c:381)
==5813==    by 0x4A3B8E9: strdup (strdup.c:42)
==5813==    by 0x59FC435: _nc_setupterm (in /usr/lib/x86_64-linux-gnu/libtinfo.so.6.4)
==5813==    by 0x5978983: ??? (in /usr/lib/python3.11/lib-dynload/_curses.cpython-311-x86_64-linux-gnu.so)
==5813==    by 0x53ACF6: ??? (in /usr/bin/python3.11)
==5813==    by 0x53AC2B: PyObject_Vectorcall (in /usr/bin/python3.11)
==5813==    by 0x52B93F: _PyEval_EvalFrameDefault (in /usr/bin/python3.11)
==5813==    by 0x51F066: _PyObject_FastCallDictTstate (in /usr/bin/python3.11)
==5813==    by 0x565972: ??? (in /usr/bin/python3.11)
==5813==    by 0x517E54: _PyObject_MakeTpCall (in /usr/bin/python3.11)
==5813==    by 0x52B93F: _PyEval_EvalFrameDefault (in /usr/bin/python3.11)
==5813==    by 0x52360A: PyEval_EvalCode (in /usr/bin/python3.11)
==5813== 
==5813== 16 bytes in 1 blocks are still reachable in loss record 5 of 174
==5813==    at 0x48407B4: malloc (vg_replace_malloc.c:381)
==5813==    by 0x4F7446: _PyWideStringList_Copy (in /usr/bin/python3.11)
==5813==    by 0x62C002: ??? (in /usr/bin/python3.11)
==5813==    by 0x6287FE: ??? (in /usr/bin/python3.11)
==5813==    by 0x62863A: Py_InitializeFromConfig (in /usr/bin/python3.11)
==5813==    by 0x6278E8: ??? (in /usr/bin/python3.11)
==5813==    by 0x62772F: ??? (in /usr/bin/python3.11)
==5813==    by 0x6275C6: Py_BytesMain (in /usr/bin/python3.11)
==5813==    by 0x49C4249: (below main) (libc_start_call_main.h:58)
==5813== 
==5813== 20 bytes in 1 blocks are still reachable in loss record 6 of 174
==5813==    at 0x48407B4: malloc (vg_replace_malloc.c:381)
==5813==    by 0x4F72C6: _PyMem_RawWcsdup (in /usr/bin/python3.11)
==5813==    by 0x64174F: ??? (in /usr/bin/python3.11)
==5813==    by 0x64F735: Py_RunMain (in /usr/bin/python3.11)
==5813==    by 0x6275C6: Py_BytesMain (in /usr/bin/python3.11)
==5813==    by 0x49C4249: (below main) (libc_start_call_main.h:58)
==5813== 
==5813== 20 bytes in 1 blocks are still reachable in loss record 7 of 174
==5813==    at 0x48407B4: malloc (vg_replace_malloc.c:381)
==5813==    by 0x4F72C6: _PyMem_RawWcsdup (in /usr/bin/python3.11)
==5813==    by 0x641781: ??? (in /usr/bin/python3.11)
==5813==    by 0x64F735: Py_RunMain (in /usr/bin/python3.11)
==5813==    by 0x6275C6: Py_BytesMain (in /usr/bin/python3.11)
==5813==    by 0x49C4249: (below main) (libc_start_call_main.h:58)
==5813== 
==5813== 22 bytes in 1 blocks are still reachable in loss record 8 of 174
==5813==    at 0x48407B4: malloc (vg_replace_malloc.c:381)
==5813==    by 0x59F9DF4: _nc_home_terminfo (in /usr/lib/x86_64-linux-gnu/libtinfo.so.6.4)
==5813==    by 0x59F9991: _nc_first_db (in /usr/lib/x86_64-linux-gnu/libtinfo.so.6.4)
==5813==    by 0x5A04FA6: _nc_read_entry2 (in /usr/lib/x86_64-linux-gnu/libtinfo.so.6.4)
==5813==    by 0x59FC018: ??? (in /usr/lib/x86_64-linux-gnu/libtinfo.so.6.4)
==5813==    by 0x59FC3D5: _nc_setupterm (in /usr/lib/x86_64-linux-gnu/libtinfo.so.6.4)
==5813==    by 0x5978983: ??? (in /usr/lib/python3.11/lib-dynload/_curses.cpython-311-x86_64-linux-gnu.so)
==5813==    by 0x53ACF6: ??? (in /usr/bin/python3.11)
==5813==    by 0x53AC2B: PyObject_Vectorcall (in /usr/bin/python3.11)
==5813==    by 0x52B93F: _PyEval_EvalFrameDefault (in /usr/bin/python3.11)
==5813==    by 0x51F066: _PyObject_FastCallDictTstate (in /usr/bin/python3.11)
==5813==    by 0x565972: ??? (in /usr/bin/python3.11)
==5813== 
==5813== 24 bytes in 1 blocks are still reachable in loss record 9 of 174
==5813==    at 0x48407B4: malloc (vg_replace_malloc.c:381)
==5813==    by 0x4A9FD49: tsearch (tsearch.c:337)
==5813==    by 0x59FE1F0: ??? (in /usr/lib/x86_64-linux-gnu/libtinfo.so.6.4)
==5813==    by 0x59FE2C6: tparm (in /usr/lib/x86_64-linux-gnu/libtinfo.so.6.4)
==5813==    by 0x5979782: ??? (in /usr/lib/python3.11/lib-dynload/_curses.cpython-311-x86_64-linux-gnu.so)
==5813==    by 0x54DDD7: ??? (in /usr/bin/python3.11)
==5813==    by 0x5343AF: _PyEval_EvalFrameDefault (in /usr/bin/python3.11)
==5813==    by 0x5855A3: ??? (in /usr/bin/python3.11)
==5813==    by 0x585173: ??? (in /usr/bin/python3.11)
==5813==    by 0x562711: PyObject_CallOneArg (in /usr/bin/python3.11)
==5813==    by 0x5D9AE6: ??? (in /usr/bin/python3.11)
==5813==    by 0x51E489: PyObject_GetAttr (in /usr/bin/python3.11)
==5813== 
==5813== 24 bytes in 1 blocks are still reachable in loss record 10 of 174
==5813==    at 0x48407B4: malloc (vg_replace_malloc.c:381)
==5813==    by 0x4A9FCD5: tsearch (tsearch.c:337)
==5813==    by 0x59FE1F0: ??? (in /usr/lib/x86_64-linux-gnu/libtinfo.so.6.4)
==5813==    by 0x59FE2C6: tparm (in /usr/lib/x86_64-linux-gnu/libtinfo.so.6.4)
==5813==    by 0x5979782: ??? (in /usr/lib/python3.11/lib-dynload/_curses.cpython-311-x86_64-linux-gnu.so)
==5813==    by 0x54DDD7: ??? (in /usr/bin/python3.11)
==5813==    by 0x5343AF: _PyEval_EvalFrameDefault (in /usr/bin/python3.11)
==5813==    by 0x5855A3: ??? (in /usr/bin/python3.11)
==5813==    by 0x585173: ??? (in /usr/bin/python3.11)
==5813==    by 0x562711: PyObject_CallOneArg (in /usr/bin/python3.11)
==5813==    by 0x5D9AE6: ??? (in /usr/bin/python3.11)
==5813==    by 0x51E489: PyObject_GetAttr (in /usr/bin/python3.11)
==5813== 
==5813== 32 bytes in 1 blocks are still reachable in loss record 11 of 174
==5813==    at 0x48407B4: malloc (vg_replace_malloc.c:381)
==5813==    by 0x4F6E39: PyThread_allocate_lock (in /usr/bin/python3.11)
==5813==    by 0x6715A7: ??? (in /usr/bin/python3.11)
==5813==    by 0x517E15: _PyObject_MakeTpCall (in /usr/bin/python3.11)
==5813==    by 0x52B93F: _PyEval_EvalFrameDefault (in /usr/bin/python3.11)
==5813==    by 0x51F066: _PyObject_FastCallDictTstate (in /usr/bin/python3.11)
==5813==    by 0x565972: ??? (in /usr/bin/python3.11)
==5813==    by 0x517E54: _PyObject_MakeTpCall (in /usr/bin/python3.11)
==5813==    by 0x52B93F: _PyEval_EvalFrameDefault (in /usr/bin/python3.11)
==5813==    by 0x53B0E3: ??? (in /usr/bin/python3.11)
==5813==    by 0x53ACF6: ??? (in /usr/bin/python3.11)
==5813==    by 0x53AC2B: PyObject_Vectorcall (in /usr/bin/python3.11)
==5813== 
==5813== 46 bytes in 1 blocks are still reachable in loss record 12 of 174
==5813==    at 0x484582F: realloc (vg_replace_malloc.c:1437)
==5813==    by 0x59F9A42: _nc_doalloc (in /usr/lib/x86_64-linux-gnu/libtinfo.so.6.4)
==5813==    by 0x5A0465F: _nc_read_termtype (in /usr/lib/x86_64-linux-gnu/libtinfo.so.6.4)
==5813==    by 0x5A04B1A: _nc_read_file_entry (in /usr/lib/x86_64-linux-gnu/libtinfo.so.6.4)
==5813==    by 0x5A04E7C: ??? (in /usr/lib/x86_64-linux-gnu/libtinfo.so.6.4)
==5813==    by 0x5A04FCB: _nc_read_entry2 (in /usr/lib/x86_64-linux-gnu/libtinfo.so.6.4)
==5813==    by 0x59FC018: ??? (in /usr/lib/x86_64-linux-gnu/libtinfo.so.6.4)
==5813==    by 0x59FC3D5: _nc_setupterm (in /usr/lib/x86_64-linux-gnu/libtinfo.so.6.4)
==5813==    by 0x5978983: ??? (in /usr/lib/python3.11/lib-dynload/_curses.cpython-311-x86_64-linux-gnu.so)
==5813==    by 0x53ACF6: ??? (in /usr/bin/python3.11)
==5813==    by 0x53AC2B: PyObject_Vectorcall (in /usr/bin/python3.11)
==5813==    by 0x52B93F: _PyEval_EvalFrameDefault (in /usr/bin/python3.11)
==5813== 
==5813== 46 bytes in 1 blocks are still reachable in loss record 13 of 174
==5813==    at 0x48407B4: malloc (vg_replace_malloc.c:381)
==5813==    by 0x59F70BE: ??? (in /usr/lib/x86_64-linux-gnu/libtinfo.so.6.4)
==5813==    by 0x59FC404: _nc_setupterm (in /usr/lib/x86_64-linux-gnu/libtinfo.so.6.4)
==5813==    by 0x5978983: ??? (in /usr/lib/python3.11/lib-dynload/_curses.cpython-311-x86_64-linux-gnu.so)
==5813==    by 0x53ACF6: ??? (in /usr/bin/python3.11)
==5813==    by 0x53AC2B: PyObject_Vectorcall (in /usr/bin/python3.11)
==5813==    by 0x52B93F: _PyEval_EvalFrameDefault (in /usr/bin/python3.11)
==5813==    by 0x51F066: _PyObject_FastCallDictTstate (in /usr/bin/python3.11)
==5813==    by 0x565972: ??? (in /usr/bin/python3.11)
==5813==    by 0x517E54: _PyObject_MakeTpCall (in /usr/bin/python3.11)
==5813==    by 0x52B93F: _PyEval_EvalFrameDefault (in /usr/bin/python3.11)
==5813==    by 0x52360A: PyEval_EvalCode (in /usr/bin/python3.11)
==5813== 
==5813== 48 bytes in 1 blocks are still reachable in loss record 14 of 174
==5813==    at 0x48455EF: calloc (vg_replace_malloc.c:1328)
==5813==    by 0x59F95CB: _nc_first_db (in /usr/lib/x86_64-linux-gnu/libtinfo.so.6.4)
==5813==    by 0x5A04FA6: _nc_read_entry2 (in /usr/lib/x86_64-linux-gnu/libtinfo.so.6.4)
==5813==    by 0x59FC018: ??? (in /usr/lib/x86_64-linux-gnu/libtinfo.so.6.4)
==5813==    by 0x59FC3D5: _nc_setupterm (in /usr/lib/x86_64-linux-gnu/libtinfo.so.6.4)
==5813==    by 0x5978983: ??? (in /usr/lib/python3.11/lib-dynload/_curses.cpython-311-x86_64-linux-gnu.so)
==5813==    by 0x53ACF6: ??? (in /usr/bin/python3.11)
==5813==    by 0x53AC2B: PyObject_Vectorcall (in /usr/bin/python3.11)
==5813==    by 0x52B93F: _PyEval_EvalFrameDefault (in /usr/bin/python3.11)
==5813==    by 0x51F066: _PyObject_FastCallDictTstate (in /usr/bin/python3.11)
==5813==    by 0x565972: ??? (in /usr/bin/python3.11)
==5813==    by 0x517E54: _PyObject_MakeTpCall (in /usr/bin/python3.11)
==5813== 
==5813== 68 bytes in 1 blocks are still reachable in loss record 15 of 174
==5813==    at 0x48407B4: malloc (vg_replace_malloc.c:381)
==5813==    by 0x4F72C6: _PyMem_RawWcsdup (in /usr/bin/python3.11)
==5813==    by 0x6417E5: ??? (in /usr/bin/python3.11)
==5813==    by 0x64F735: Py_RunMain (in /usr/bin/python3.11)
==5813==    by 0x6275C6: Py_BytesMain (in /usr/bin/python3.11)
==5813==    by 0x49C4249: (below main) (libc_start_call_main.h:58)
==5813== 
==5813== 68 bytes in 1 blocks are still reachable in loss record 16 of 174
==5813==    at 0x48407B4: malloc (vg_replace_malloc.c:381)
==5813==    by 0x4F72C6: _PyMem_RawWcsdup (in /usr/bin/python3.11)
==5813==    by 0x641825: ??? (in /usr/bin/python3.11)
==5813==    by 0x64F735: Py_RunMain (in /usr/bin/python3.11)
==5813==    by 0x6275C6: Py_BytesMain (in /usr/bin/python3.11)
==5813==    by 0x49C4249: (below main) (libc_start_call_main.h:58)
==5813== 
==5813== 72 bytes in 1 blocks are still reachable in loss record 17 of 174
==5813==    at 0x484582F: realloc (vg_replace_malloc.c:1437)
==5813==    by 0x59F9A42: _nc_doalloc (in /usr/lib/x86_64-linux-gnu/libtinfo.so.6.4)
==5813==    by 0x59FE8F8: tparm (in /usr/lib/x86_64-linux-gnu/libtinfo.so.6.4)
==5813==    by 0x5979782: ??? (in /usr/lib/python3.11/lib-dynload/_curses.cpython-311-x86_64-linux-gnu.so)
==5813==    by 0x54DDD7: ??? (in /usr/bin/python3.11)
==5813==    by 0x5343AF: _PyEval_EvalFrameDefault (in /usr/bin/python3.11)
==5813==    by 0x5855A3: ??? (in /usr/bin/python3.11)
==5813==    by 0x585173: ??? (in /usr/bin/python3.11)
==5813==    by 0x562711: PyObject_CallOneArg (in /usr/bin/python3.11)
==5813==    by 0x5D9AE6: ??? (in /usr/bin/python3.11)
==5813==    by 0x51E489: PyObject_GetAttr (in /usr/bin/python3.11)
==5813==    by 0x52BF94: _PyEval_EvalFrameDefault (in /usr/bin/python3.11)
==5813== 
==5813== 78 bytes in 1 blocks are still reachable in loss record 18 of 174
==5813==    at 0x48407B4: malloc (vg_replace_malloc.c:381)
==5813==    by 0x59F71FD: ??? (in /usr/lib/x86_64-linux-gnu/libtinfo.so.6.4)
==5813==    by 0x59FC404: _nc_setupterm (in /usr/lib/x86_64-linux-gnu/libtinfo.so.6.4)
==5813==    by 0x5978983: ??? (in /usr/lib/python3.11/lib-dynload/_curses.cpython-311-x86_64-linux-gnu.so)
==5813==    by 0x53ACF6: ??? (in /usr/bin/python3.11)
==5813==    by 0x53AC2B: PyObject_Vectorcall (in /usr/bin/python3.11)
==5813==    by 0x52B93F: _PyEval_EvalFrameDefault (in /usr/bin/python3.11)
==5813==    by 0x51F066: _PyObject_FastCallDictTstate (in /usr/bin/python3.11)
==5813==    by 0x565972: ??? (in /usr/bin/python3.11)
==5813==    by 0x517E54: _PyObject_MakeTpCall (in /usr/bin/python3.11)
==5813==    by 0x52B93F: _PyEval_EvalFrameDefault (in /usr/bin/python3.11)
==5813==    by 0x52360A: PyEval_EvalCode (in /usr/bin/python3.11)
==5813== 
==5813== 80 bytes in 1 blocks are still reachable in loss record 19 of 174
==5813==    at 0x48407B4: malloc (vg_replace_malloc.c:381)
==5813==    by 0x4F72C6: _PyMem_RawWcsdup (in /usr/bin/python3.11)
==5813==    by 0x6417B3: ??? (in /usr/bin/python3.11)
==5813==    by 0x64F735: Py_RunMain (in /usr/bin/python3.11)
==5813==    by 0x6275C6: Py_BytesMain (in /usr/bin/python3.11)
==5813==    by 0x49C4249: (below main) (libc_start_call_main.h:58)
==5813== 
==5813== 91 bytes in 1 blocks are still reachable in loss record 20 of 174
==5813==    at 0x48407B4: malloc (vg_replace_malloc.c:381)
==5813==    by 0x59F9530: _nc_first_db (in /usr/lib/x86_64-linux-gnu/libtinfo.so.6.4)
==5813==    by 0x5A04FA6: _nc_read_entry2 (in /usr/lib/x86_64-linux-gnu/libtinfo.so.6.4)
==5813==    by 0x59FC018: ??? (in /usr/lib/x86_64-linux-gnu/libtinfo.so.6.4)
==5813==    by 0x59FC3D5: _nc_setupterm (in /usr/lib/x86_64-linux-gnu/libtinfo.so.6.4)
==5813==    by 0x5978983: ??? (in /usr/lib/python3.11/lib-dynload/_curses.cpython-311-x86_64-linux-gnu.so)
==5813==    by 0x53ACF6: ??? (in /usr/bin/python3.11)
==5813==    by 0x53AC2B: PyObject_Vectorcall (in /usr/bin/python3.11)
==5813==    by 0x52B93F: _PyEval_EvalFrameDefault (in /usr/bin/python3.11)
==5813==    by 0x51F066: _PyObject_FastCallDictTstate (in /usr/bin/python3.11)
==5813==    by 0x565972: ??? (in /usr/bin/python3.11)
==5813==    by 0x517E54: _PyObject_MakeTpCall (in /usr/bin/python3.11)
==5813== 
==5813== 127 bytes in 2 blocks are still reachable in loss record 21 of 174
==5813==    at 0x48407B4: malloc (vg_replace_malloc.c:381)
==5813==    by 0x4A3B8E9: strdup (strdup.c:42)
==5813==    by 0x59FE1D5: ??? (in /usr/lib/x86_64-linux-gnu/libtinfo.so.6.4)
==5813==    by 0x59FE2C6: tparm (in /usr/lib/x86_64-linux-gnu/libtinfo.so.6.4)
==5813==    by 0x5979782: ??? (in /usr/lib/python3.11/lib-dynload/_curses.cpython-311-x86_64-linux-gnu.so)
==5813==    by 0x54DDD7: ??? (in /usr/bin/python3.11)
==5813==    by 0x5343AF: _PyEval_EvalFrameDefault (in /usr/bin/python3.11)
==5813==    by 0x5855A3: ??? (in /usr/bin/python3.11)
==5813==    by 0x585173: ??? (in /usr/bin/python3.11)
==5813==    by 0x562711: PyObject_CallOneArg (in /usr/bin/python3.11)
==5813==    by 0x5D9AE6: ??? (in /usr/bin/python3.11)
==5813==    by 0x51E489: PyObject_GetAttr (in /usr/bin/python3.11)
==5813== 
==5813== 129 bytes in 1 blocks are still reachable in loss record 22 of 174
==5813==    at 0x484582F: realloc (vg_replace_malloc.c:1437)
==5813==    by 0x59F9A42: _nc_doalloc (in /usr/lib/x86_64-linux-gnu/libtinfo.so.6.4)
==5813==    by 0x59FDDC0: _nc_tparm_analyze (in /usr/lib/x86_64-linux-gnu/libtinfo.so.6.4)
==5813==    by 0x59FE0E2: ??? (in /usr/lib/x86_64-linux-gnu/libtinfo.so.6.4)
==5813==    by 0x59FE2C6: tparm (in /usr/lib/x86_64-linux-gnu/libtinfo.so.6.4)
==5813==    by 0x5979782: ??? (in /usr/lib/python3.11/lib-dynload/_curses.cpython-311-x86_64-linux-gnu.so)
==5813==    by 0x54DDD7: ??? (in /usr/bin/python3.11)
==5813==    by 0x5343AF: _PyEval_EvalFrameDefault (in /usr/bin/python3.11)
==5813==    by 0x5855A3: ??? (in /usr/bin/python3.11)
==5813==    by 0x585173: ??? (in /usr/bin/python3.11)
==5813==    by 0x562711: PyObject_CallOneArg (in /usr/bin/python3.11)
==5813==    by 0x5D9AE6: ??? (in /usr/bin/python3.11)
==5813== 
==5813== 156 bytes in 1 blocks are still reachable in loss record 23 of 174
==5813==    at 0x484582F: realloc (vg_replace_malloc.c:1437)
==5813==    by 0x59F9A42: _nc_doalloc (in /usr/lib/x86_64-linux-gnu/libtinfo.so.6.4)
==5813==    by 0x5A0467D: _nc_read_termtype (in /usr/lib/x86_64-linux-gnu/libtinfo.so.6.4)
==5813==    by 0x5A04B1A: _nc_read_file_entry (in /usr/lib/x86_64-linux-gnu/libtinfo.so.6.4)
==5813==    by 0x5A04E7C: ??? (in /usr/lib/x86_64-linux-gnu/libtinfo.so.6.4)
==5813==    by 0x5A04FCB: _nc_read_entry2 (in /usr/lib/x86_64-linux-gnu/libtinfo.so.6.4)
==5813==    by 0x59FC018: ??? (in /usr/lib/x86_64-linux-gnu/libtinfo.so.6.4)
==5813==    by 0x59FC3D5: _nc_setupterm (in /usr/lib/x86_64-linux-gnu/libtinfo.so.6.4)
==5813==    by 0x5978983: ??? (in /usr/lib/python3.11/lib-dynload/_curses.cpython-311-x86_64-linux-gnu.so)
==5813==    by 0x53ACF6: ??? (in /usr/bin/python3.11)
==5813==    by 0x53AC2B: PyObject_Vectorcall (in /usr/bin/python3.11)
==5813==    by 0x52B93F: _PyEval_EvalFrameDefault (in /usr/bin/python3.11)
==5813== 
==5813== 172 bytes in 2 blocks are still reachable in loss record 24 of 174
==5813==    at 0x48407B4: malloc (vg_replace_malloc.c:381)
==5813==    by 0x4F72C6: _PyMem_RawWcsdup (in /usr/bin/python3.11)
==5813==    by 0x4F7468: _PyWideStringList_Copy (in /usr/bin/python3.11)
==5813==    by 0x62C002: ??? (in /usr/bin/python3.11)
==5813==    by 0x6287FE: ??? (in /usr/bin/python3.11)
==5813==    by 0x62863A: Py_InitializeFromConfig (in /usr/bin/python3.11)
==5813==    by 0x6278E8: ??? (in /usr/bin/python3.11)
==5813==    by 0x62772F: ??? (in /usr/bin/python3.11)
==5813==    by 0x6275C6: Py_BytesMain (in /usr/bin/python3.11)
==5813==    by 0x49C4249: (below main) (libc_start_call_main.h:58)
==5813== 
==5813== 217 bytes in 6 blocks are still reachable in loss record 25 of 174
==5813==    at 0x48407B4: malloc (vg_replace_malloc.c:381)
==5813==    by 0x402369A: malloc (rtld-malloc.h:56)
==5813==    by 0x402369A: strdup (strdup.c:42)
==5813==    by 0x4013284: _dl_load_cache_lookup (dl-cache.c:525)
==5813==    by 0x4008012: _dl_map_object (dl-load.c:2139)
==5813==    by 0x4002280: openaux (dl-deps.c:64)
==5813==    by 0x4AEBFC9: _dl_catch_exception (dl-error-skeleton.c:208)
==5813==    by 0x40025E9: _dl_map_object_deps (dl-deps.c:232)
==5813==    by 0x400B8EC: dl_open_worker_begin (dl-open.c:592)
==5813==    by 0x4AEBFC9: _dl_catch_exception (dl-error-skeleton.c:208)
==5813==    by 0x400B045: dl_open_worker (dl-open.c:782)
==5813==    by 0x4AEBFC9: _dl_catch_exception (dl-error-skeleton.c:208)
==5813==    by 0x400B437: _dl_open (dl-open.c:884)
==5813== 
==5813== 217 bytes in 6 blocks are still reachable in loss record 26 of 174
==5813==    at 0x48407B4: malloc (vg_replace_malloc.c:381)
==5813==    by 0x400ADC8: malloc (rtld-malloc.h:56)
==5813==    by 0x400ADC8: _dl_new_object (dl-object.c:199)
==5813==    by 0x400651E: _dl_map_object_from_fd (dl-load.c:1063)
==5813==    by 0x4007EF4: _dl_map_object (dl-load.c:2272)
==5813==    by 0x4002280: openaux (dl-deps.c:64)
==5813==    by 0x4AEBFC9: _dl_catch_exception (dl-error-skeleton.c:208)
==5813==    by 0x40025E9: _dl_map_object_deps (dl-deps.c:232)
==5813==    by 0x400B8EC: dl_open_worker_begin (dl-open.c:592)
==5813==    by 0x4AEBFC9: _dl_catch_exception (dl-error-skeleton.c:208)
==5813==    by 0x400B045: dl_open_worker (dl-open.c:782)
==5813==    by 0x4AEBFC9: _dl_catch_exception (dl-error-skeleton.c:208)
==5813==    by 0x400B437: _dl_open (dl-open.c:884)
==5813== 
==5813== 304 bytes in 1 blocks are still reachable in loss record 27 of 174
==5813==    at 0x48407B4: malloc (vg_replace_malloc.c:381)
==5813==    by 0x6418AB: ??? (in /usr/bin/python3.11)
==5813==    by 0x64F735: Py_RunMain (in /usr/bin/python3.11)
==5813==    by 0x6275C6: Py_BytesMain (in /usr/bin/python3.11)
==5813==    by 0x49C4249: (below main) (libc_start_call_main.h:58)
==5813== 
==5813== 336 bytes in 2 blocks are still reachable in loss record 28 of 174
==5813==    at 0x48455EF: calloc (vg_replace_malloc.c:1328)
==5813==    by 0x59FE14E: ??? (in /usr/lib/x86_64-linux-gnu/libtinfo.so.6.4)
==5813==    by 0x59FE2C6: tparm (in /usr/lib/x86_64-linux-gnu/libtinfo.so.6.4)
==5813==    by 0x5979782: ??? (in /usr/lib/python3.11/lib-dynload/_curses.cpython-311-x86_64-linux-gnu.so)
==5813==    by 0x54DDD7: ??? (in /usr/bin/python3.11)
==5813==    by 0x5343AF: _PyEval_EvalFrameDefault (in /usr/bin/python3.11)
==5813==    by 0x5855A3: ??? (in /usr/bin/python3.11)
==5813==    by 0x585173: ??? (in /usr/bin/python3.11)
==5813==    by 0x562711: PyObject_CallOneArg (in /usr/bin/python3.11)
==5813==    by 0x5D9AE6: ??? (in /usr/bin/python3.11)
==5813==    by 0x51E489: PyObject_GetAttr (in /usr/bin/python3.11)
==5813==    by 0x52BF94: _PyEval_EvalFrameDefault (in /usr/bin/python3.11)
==5813== 
==5813== 518 bytes in 1 blocks are still reachable in loss record 29 of 174
==5813==    at 0x48407B4: malloc (vg_replace_malloc.c:381)
==5813==    by 0x4FBDF9: ??? (in /usr/bin/python3.11)
==5813==    by 0x56AA3D: PyType_FromModuleAndSpec (in /usr/bin/python3.11)
==5813==    by 0x63C024: ??? (in /usr/bin/python3.11)
==5813==    by 0x55A93E: PyModule_ExecDef (in /usr/bin/python3.11)
==5813==    by 0x63BFCB: ??? (in /usr/bin/python3.11)
==5813==    by 0x5458A2: ??? (in /usr/bin/python3.11)
==5813==    by 0x5343AF: _PyEval_EvalFrameDefault (in /usr/bin/python3.11)
==5813==    by 0x55C930: _PyFunction_Vectorcall (in /usr/bin/python3.11)
==5813==    by 0x55BF93: ??? (in /usr/bin/python3.11)
==5813==    by 0x55B6FB: PyObject_CallMethod (in /usr/bin/python3.11)
==5813==    by 0x4FAB2A: ??? (in /usr/bin/python3.11)
==5813== 
==5813== 528 bytes in 1 blocks are still reachable in loss record 30 of 174
==5813==    at 0x48407B4: malloc (vg_replace_malloc.c:381)
==5813==    by 0x527DAA: PyBytes_FromStringAndSize (in /usr/bin/python3.11)
==5813==    by 0x5244A3: ??? (in /usr/bin/python3.11)
==5813==    by 0x52479C: ??? (in /usr/bin/python3.11)
==5813==    by 0x524C79: ??? (in /usr/bin/python3.11)
==5813==    by 0x5246F6: ??? (in /usr/bin/python3.11)
==5813==    by 0x524D02: ??? (in /usr/bin/python3.11)
==5813==    by 0x5246F6: ??? (in /usr/bin/python3.11)
==5813==    by 0x6336E3: ??? (in /usr/bin/python3.11)
==5813==    by 0x5B3297: ??? (in /usr/bin/python3.11)
==5813==    by 0x52C176: _PyEval_EvalFrameDefault (in /usr/bin/python3.11)
==5813==    by 0x55C930: _PyFunction_Vectorcall (in /usr/bin/python3.11)
==5813== 
==5813== 566 bytes in 1 blocks are still reachable in loss record 31 of 174
==5813==    at 0x48407B4: malloc (vg_replace_malloc.c:381)
==5813==    by 0x52AFA1: ??? (in /usr/bin/python3.11)
==5813==    by 0x524A93: ??? (in /usr/bin/python3.11)
==5813==    by 0x524BE9: ??? (in /usr/bin/python3.11)
==5813==    by 0x5246F6: ??? (in /usr/bin/python3.11)
==5813==    by 0x524CDD: ??? (in /usr/bin/python3.11)
==5813==    by 0x5246F6: ??? (in /usr/bin/python3.11)
==5813==    by 0x524D02: ??? (in /usr/bin/python3.11)
==5813==    by 0x5246F6: ??? (in /usr/bin/python3.11)
==5813==    by 0x6336E3: ??? (in /usr/bin/python3.11)
==5813==    by 0x5B3297: ??? (in /usr/bin/python3.11)
==5813==    by 0x52C176: _PyEval_EvalFrameDefault (in /usr/bin/python3.11)
==5813== 
==5813== 568 bytes in 1 blocks are still reachable in loss record 32 of 174
==5813==    at 0x48407B4: malloc (vg_replace_malloc.c:381)
==5813==    by 0x500157: ??? (in /usr/bin/python3.11)
==5813==    by 0x508A47: ??? (in /usr/bin/python3.11)
==5813==    by 0x501D1F: ??? (in /usr/bin/python3.11)
==5813==    by 0x500F66: PyType_Ready (in /usr/bin/python3.11)
==5813==    by 0x5B415A6: PyInit__ctypes (in /usr/lib/python3.11/lib-dynload/_ctypes.cpython-311-x86_64-linux-gnu.so)
==5813==    by 0x6539FA: ??? (in /usr/bin/python3.11)
==5813==    by 0x54DDD7: ??? (in /usr/bin/python3.11)
==5813==    by 0x5343AF: _PyEval_EvalFrameDefault (in /usr/bin/python3.11)
==5813==    by 0x55C930: _PyFunction_Vectorcall (in /usr/bin/python3.11)
==5813==    by 0x54618E: ??? (in /usr/bin/python3.11)
==5813==    by 0x58351A: PyObject_CallMethodObjArgs (in /usr/bin/python3.11)
==5813== 
==5813== 568 bytes in 1 blocks are still reachable in loss record 33 of 174
==5813==    at 0x48407B4: malloc (vg_replace_malloc.c:381)
==5813==    by 0x527DAA: PyBytes_FromStringAndSize (in /usr/bin/python3.11)
==5813==    by 0x5244A3: ??? (in /usr/bin/python3.11)
==5813==    by 0x52479C: ??? (in /usr/bin/python3.11)
==5813==    by 0x524C0D: ??? (in /usr/bin/python3.11)
==5813==    by 0x5246F6: ??? (in /usr/bin/python3.11)
==5813==    by 0x524D02: ??? (in /usr/bin/python3.11)
==5813==    by 0x5246F6: ??? (in /usr/bin/python3.11)
==5813==    by 0x6336E3: ??? (in /usr/bin/python3.11)
==5813==    by 0x5B3297: ??? (in /usr/bin/python3.11)
==5813==    by 0x52C176: _PyEval_EvalFrameDefault (in /usr/bin/python3.11)
==5813==    by 0x55C930: _PyFunction_Vectorcall (in /usr/bin/python3.11)
==5813== 
==5813== 568 bytes in 1 blocks are still reachable in loss record 34 of 174
==5813==    at 0x48407B4: malloc (vg_replace_malloc.c:381)
==5813==    by 0x500157: ??? (in /usr/bin/python3.11)
==5813==    by 0x508A47: ??? (in /usr/bin/python3.11)
==5813==    by 0x501D1F: ??? (in /usr/bin/python3.11)
==5813==    by 0x518D23: ??? (in /usr/bin/python3.11)
==5813==    by 0x5B3984E: ??? (in /usr/lib/python3.11/lib-dynload/_ctypes.cpython-311-x86_64-linux-gnu.so)
==5813==    by 0x517E15: _PyObject_MakeTpCall (in /usr/bin/python3.11)
==5813==    by 0x58F864: _PyObject_CallFunction_SizeT (in /usr/bin/python3.11)
==5813==    by 0x5B39718: ??? (in /usr/lib/python3.11/lib-dynload/_ctypes.cpython-311-x86_64-linux-gnu.so)
==5813==    by 0x52CBB6: _PyEval_EvalFrameDefault (in /usr/bin/python3.11)
==5813==    by 0x53B0E3: ??? (in /usr/bin/python3.11)
==5813==    by 0x53ACF6: ??? (in /usr/bin/python3.11)
==5813== 
==5813== 568 bytes in 1 blocks are still reachable in loss record 35 of 174
==5813==    at 0x48407B4: malloc (vg_replace_malloc.c:381)
==5813==    by 0x500157: ??? (in /usr/bin/python3.11)
==5813==    by 0x508A47: ??? (in /usr/bin/python3.11)
==5813==    by 0x5B3978D: ??? (in /usr/lib/python3.11/lib-dynload/_ctypes.cpython-311-x86_64-linux-gnu.so)
==5813==    by 0x52CBB6: _PyEval_EvalFrameDefault (in /usr/bin/python3.11)
==5813==    by 0x53B0E3: ??? (in /usr/bin/python3.11)
==5813==    by 0x53ACF6: ??? (in /usr/bin/python3.11)
==5813==    by 0x53AC2B: PyObject_Vectorcall (in /usr/bin/python3.11)
==5813==    by 0x52B93F: _PyEval_EvalFrameDefault (in /usr/bin/python3.11)
==5813==    by 0x52360A: PyEval_EvalCode (in /usr/bin/python3.11)
==5813==    by 0x58EC4D: ??? (in /usr/bin/python3.11)
==5813==    by 0x53ACF6: ??? (in /usr/bin/python3.11)
==5813== 
==5813== 568 bytes in 1 blocks are still reachable in loss record 36 of 174
==5813==    at 0x48407B4: malloc (vg_replace_malloc.c:381)
==5813==    by 0x500157: ??? (in /usr/bin/python3.11)
==5813==    by 0x508A47: ??? (in /usr/bin/python3.11)
==5813==    by 0x5F68E7: ??? (in /usr/bin/python3.11)
==5813==    by 0x56A493: PyObject_Call (in /usr/bin/python3.11)
==5813==    by 0x52F8A1: _PyEval_EvalFrameDefault (in /usr/bin/python3.11)
==5813==    by 0x5C4107: ??? (in /usr/bin/python3.11)
==5813==    by 0x5C3EFE: ??? (in /usr/bin/python3.11)
==5813==    by 0x52C359: _PyEval_EvalFrameDefault (in /usr/bin/python3.11)
==5813==    by 0x53B0E3: ??? (in /usr/bin/python3.11)
==5813==    by 0x53ACF6: ??? (in /usr/bin/python3.11)
==5813==    by 0x53AC2B: PyObject_Vectorcall (in /usr/bin/python3.11)
==5813== 
==5813== 570 bytes in 1 blocks are still reachable in loss record 37 of 174
==5813==    at 0x48407B4: malloc (vg_replace_malloc.c:381)
==5813==    by 0x52AFA1: ??? (in /usr/bin/python3.11)
==5813==    by 0x524A93: ??? (in /usr/bin/python3.11)
==5813==    by 0x524BE9: ??? (in /usr/bin/python3.11)
==5813==    by 0x5246F6: ??? (in /usr/bin/python3.11)
==5813==    by 0x524C55: ??? (in /usr/bin/python3.11)
==5813==    by 0x5246F6: ??? (in /usr/bin/python3.11)
==5813==    by 0x524D02: ??? (in /usr/bin/python3.11)
==5813==    by 0x5246F6: ??? (in /usr/bin/python3.11)
==5813==    by 0x6336E3: ??? (in /usr/bin/python3.11)
==5813==    by 0x5B3297: ??? (in /usr/bin/python3.11)
==5813==    by 0x52C176: _PyEval_EvalFrameDefault (in /usr/bin/python3.11)
==5813== 
==5813== 615 bytes in 1 blocks are still reachable in loss record 38 of 174
==5813==    at 0x48407B4: malloc (vg_replace_malloc.c:381)
==5813==    by 0x527DAA: PyBytes_FromStringAndSize (in /usr/bin/python3.11)
==5813==    by 0x5244A3: ??? (in /usr/bin/python3.11)
==5813==    by 0x52479C: ??? (in /usr/bin/python3.11)
==5813==    by 0x524CBD: ??? (in /usr/bin/python3.11)
==5813==    by 0x5246F6: ??? (in /usr/bin/python3.11)
==5813==    by 0x524D02: ??? (in /usr/bin/python3.11)
==5813==    by 0x5246F6: ??? (in /usr/bin/python3.11)
==5813==    by 0x6336E3: ??? (in /usr/bin/python3.11)
==5813==    by 0x5B3297: ??? (in /usr/bin/python3.11)
==5813==    by 0x52C176: _PyEval_EvalFrameDefault (in /usr/bin/python3.11)
==5813==    by 0x55C930: _PyFunction_Vectorcall (in /usr/bin/python3.11)
==5813== 
==5813== 629 bytes in 1 blocks are still reachable in loss record 39 of 174
==5813==    at 0x48407B4: malloc (vg_replace_malloc.c:381)
==5813==    by 0x527DAA: PyBytes_FromStringAndSize (in /usr/bin/python3.11)
==5813==    by 0x5244A3: ??? (in /usr/bin/python3.11)
==5813==    by 0x52479C: ??? (in /usr/bin/python3.11)
==5813==    by 0x524D02: ??? (in /usr/bin/python3.11)
==5813==    by 0x5246F6: ??? (in /usr/bin/python3.11)
==5813==    by 0x524D02: ??? (in /usr/bin/python3.11)
==5813==    by 0x5246F6: ??? (in /usr/bin/python3.11)
==5813==    by 0x6336E3: ??? (in /usr/bin/python3.11)
==5813==    by 0x5B3297: ??? (in /usr/bin/python3.11)
==5813==    by 0x52C176: _PyEval_EvalFrameDefault (in /usr/bin/python3.11)
==5813==    by 0x55C930: _PyFunction_Vectorcall (in /usr/bin/python3.11)
==5813== 
==5813== 640 bytes in 1 blocks are still reachable in loss record 40 of 174
==5813==    at 0x48455EF: calloc (vg_replace_malloc.c:1328)
==5813==    by 0x5A04959: _nc_read_termtype (in /usr/lib/x86_64-linux-gnu/libtinfo.so.6.4)
==5813==    by 0x5A04B1A: _nc_read_file_entry (in /usr/lib/x86_64-linux-gnu/libtinfo.so.6.4)
==5813==    by 0x5A04E7C: ??? (in /usr/lib/x86_64-linux-gnu/libtinfo.so.6.4)
==5813==    by 0x5A04FCB: _nc_read_entry2 (in /usr/lib/x86_64-linux-gnu/libtinfo.so.6.4)
==5813==    by 0x59FC018: ??? (in /usr/lib/x86_64-linux-gnu/libtinfo.so.6.4)
==5813==    by 0x59FC3D5: _nc_setupterm (in /usr/lib/x86_64-linux-gnu/libtinfo.so.6.4)
==5813==    by 0x5978983: ??? (in /usr/lib/python3.11/lib-dynload/_curses.cpython-311-x86_64-linux-gnu.so)
==5813==    by 0x53ACF6: ??? (in /usr/bin/python3.11)
==5813==    by 0x53AC2B: PyObject_Vectorcall (in /usr/bin/python3.11)
==5813==    by 0x52B93F: _PyEval_EvalFrameDefault (in /usr/bin/python3.11)
==5813==    by 0x51F066: _PyObject_FastCallDictTstate (in /usr/bin/python3.11)
==5813== 
==5813== 640 bytes in 1 blocks are still reachable in loss record 41 of 174
==5813==    at 0x48407B4: malloc (vg_replace_malloc.c:381)
==5813==    by 0x59F7346: ??? (in /usr/lib/x86_64-linux-gnu/libtinfo.so.6.4)
==5813==    by 0x59FC404: _nc_setupterm (in /usr/lib/x86_64-linux-gnu/libtinfo.so.6.4)
==5813==    by 0x5978983: ??? (in /usr/lib/python3.11/lib-dynload/_curses.cpython-311-x86_64-linux-gnu.so)
==5813==    by 0x53ACF6: ??? (in /usr/bin/python3.11)
==5813==    by 0x53AC2B: PyObject_Vectorcall (in /usr/bin/python3.11)
==5813==    by 0x52B93F: _PyEval_EvalFrameDefault (in /usr/bin/python3.11)
==5813==    by 0x51F066: _PyObject_FastCallDictTstate (in /usr/bin/python3.11)
==5813==    by 0x565972: ??? (in /usr/bin/python3.11)
==5813==    by 0x517E54: _PyObject_MakeTpCall (in /usr/bin/python3.11)
==5813==    by 0x52B93F: _PyEval_EvalFrameDefault (in /usr/bin/python3.11)
==5813==    by 0x52360A: PyEval_EvalCode (in /usr/bin/python3.11)
==5813== 
==5813== 657 bytes in 1 blocks are still reachable in loss record 42 of 174
==5813==    at 0x48407B4: malloc (vg_replace_malloc.c:381)
==5813==    by 0x519E29: ??? (in /usr/bin/python3.11)
==5813==    by 0x517E15: _PyObject_MakeTpCall (in /usr/bin/python3.11)
==5813==    by 0x51F269: _PyObject_FastCallDictTstate (in /usr/bin/python3.11)
==5813==    by 0x53B1BB: ??? (in /usr/bin/python3.11)
==5813==    by 0x53ACF6: ??? (in /usr/bin/python3.11)
==5813==    by 0x53AC2B: PyObject_Vectorcall (in /usr/bin/python3.11)
==5813==    by 0x52B93F: _PyEval_EvalFrameDefault (in /usr/bin/python3.11)
==5813==    by 0x52360A: PyEval_EvalCode (in /usr/bin/python3.11)
==5813==    by 0x58EC4D: ??? (in /usr/bin/python3.11)
==5813==    by 0x53ACF6: ??? (in /usr/bin/python3.11)
==5813==    by 0x53AC2B: PyObject_Vectorcall (in /usr/bin/python3.11)
==5813== 
==5813== 744 bytes in 1 blocks are still reachable in loss record 43 of 174
==5813==    at 0x48407B4: malloc (vg_replace_malloc.c:381)
==5813==    by 0x52AFA1: ??? (in /usr/bin/python3.11)
==5813==    by 0x524A93: ??? (in /usr/bin/python3.11)
==5813==    by 0x524BE9: ??? (in /usr/bin/python3.11)
==5813==    by 0x5246F6: ??? (in /usr/bin/python3.11)
==5813==    by 0x524D02: ??? (in /usr/bin/python3.11)
==5813==    by 0x5246F6: ??? (in /usr/bin/python3.11)
==5813==    by 0x524D02: ??? (in /usr/bin/python3.11)
==5813==    by 0x5246F6: ??? (in /usr/bin/python3.11)
==5813==    by 0x6336E3: ??? (in /usr/bin/python3.11)
==5813==    by 0x5B3297: ??? (in /usr/bin/python3.11)
==5813==    by 0x52C176: _PyEval_EvalFrameDefault (in /usr/bin/python3.11)
==5813== 
==5813== 751 bytes in 1 blocks are still reachable in loss record 44 of 174
==5813==    at 0x48407B4: malloc (vg_replace_malloc.c:381)
==5813==    by 0x52AFA1: ??? (in /usr/bin/python3.11)
==5813==    by 0x524A93: ??? (in /usr/bin/python3.11)
==5813==    by 0x524D02: ??? (in /usr/bin/python3.11)
==5813==    by 0x5246F6: ??? (in /usr/bin/python3.11)
==5813==    by 0x6336E3: ??? (in /usr/bin/python3.11)
==5813==    by 0x5B3297: ??? (in /usr/bin/python3.11)
==5813==    by 0x52C176: _PyEval_EvalFrameDefault (in /usr/bin/python3.11)
==5813==    by 0x55C930: _PyFunction_Vectorcall (in /usr/bin/python3.11)
==5813==    by 0x54618E: ??? (in /usr/bin/python3.11)
==5813==    by 0x58351A: PyObject_CallMethodObjArgs (in /usr/bin/python3.11)
==5813==    by 0x451A10: ??? (in /usr/bin/python3.11)
==5813== 
==5813== 755 bytes in 1 blocks are still reachable in loss record 45 of 174
==5813==    at 0x48407B4: malloc (vg_replace_malloc.c:381)
==5813==    by 0x527DAA: PyBytes_FromStringAndSize (in /usr/bin/python3.11)
==5813==    by 0x5244A3: ??? (in /usr/bin/python3.11)
==5813==    by 0x52479C: ??? (in /usr/bin/python3.11)
==5813==    by 0x524C31: ??? (in /usr/bin/python3.11)
==5813==    by 0x5246F6: ??? (in /usr/bin/python3.11)
==5813==    by 0x524D02: ??? (in /usr/bin/python3.11)
==5813==    by 0x5246F6: ??? (in /usr/bin/python3.11)
==5813==    by 0x6336E3: ??? (in /usr/bin/python3.11)
==5813==    by 0x5B3297: ??? (in /usr/bin/python3.11)
==5813==    by 0x52C176: _PyEval_EvalFrameDefault (in /usr/bin/python3.11)
==5813==    by 0x55C930: _PyFunction_Vectorcall (in /usr/bin/python3.11)
==5813== 
==5813== 760 bytes in 1 blocks are still reachable in loss record 46 of 174
==5813==    at 0x48455EF: calloc (vg_replace_malloc.c:1328)
==5813==    by 0x59FC37F: _nc_setupterm (in /usr/lib/x86_64-linux-gnu/libtinfo.so.6.4)
==5813==    by 0x5978983: ??? (in /usr/lib/python3.11/lib-dynload/_curses.cpython-311-x86_64-linux-gnu.so)
==5813==    by 0x53ACF6: ??? (in /usr/bin/python3.11)
==5813==    by 0x53AC2B: PyObject_Vectorcall (in /usr/bin/python3.11)
==5813==    by 0x52B93F: _PyEval_EvalFrameDefault (in /usr/bin/python3.11)
==5813==    by 0x51F066: _PyObject_FastCallDictTstate (in /usr/bin/python3.11)
==5813==    by 0x565972: ??? (in /usr/bin/python3.11)
==5813==    by 0x517E54: _PyObject_MakeTpCall (in /usr/bin/python3.11)
==5813==    by 0x52B93F: _PyEval_EvalFrameDefault (in /usr/bin/python3.11)
==5813==    by 0x52360A: PyEval_EvalCode (in /usr/bin/python3.11)
==5813==    by 0x58EC4D: ??? (in /usr/bin/python3.11)
==5813== 
==5813== 768 bytes in 1 blocks are still reachable in loss record 47 of 174
==5813==    at 0x48407B4: malloc (vg_replace_malloc.c:381)
==5813==    by 0x500157: ??? (in /usr/bin/python3.11)
==5813==    by 0x508A47: ??? (in /usr/bin/python3.11)
==5813==    by 0x50122B: ??? (in /usr/bin/python3.11)
==5813==    by 0x500F66: PyType_Ready (in /usr/bin/python3.11)
==5813==    by 0x4F9425: ??? (in /usr/bin/python3.11)
==5813==    by 0x628925: ??? (in /usr/bin/python3.11)
==5813==    by 0x62863A: Py_InitializeFromConfig (in /usr/bin/python3.11)
==5813==    by 0x6278E8: ??? (in /usr/bin/python3.11)
==5813==    by 0x62772F: ??? (in /usr/bin/python3.11)
==5813==    by 0x6275C6: Py_BytesMain (in /usr/bin/python3.11)
==5813==    by 0x49C4249: (below main) (libc_start_call_main.h:58)
==5813== 
==5813== 768 bytes in 1 blocks are still reachable in loss record 48 of 174
==5813==    at 0x48407B4: malloc (vg_replace_malloc.c:381)
==5813==    by 0x500157: ??? (in /usr/bin/python3.11)
==5813==    by 0x508A47: ??? (in /usr/bin/python3.11)
==5813==    by 0x502CE6: ??? (in /usr/bin/python3.11)
==5813==    by 0x500F66: PyType_Ready (in /usr/bin/python3.11)
==5813==    by 0x4F9425: ??? (in /usr/bin/python3.11)
==5813==    by 0x628925: ??? (in /usr/bin/python3.11)
==5813==    by 0x62863A: Py_InitializeFromConfig (in /usr/bin/python3.11)
==5813==    by 0x6278E8: ??? (in /usr/bin/python3.11)
==5813==    by 0x62772F: ??? (in /usr/bin/python3.11)
==5813==    by 0x6275C6: Py_BytesMain (in /usr/bin/python3.11)
==5813==    by 0x49C4249: (below main) (libc_start_call_main.h:58)
==5813== 
==5813== 768 bytes in 1 blocks are still reachable in loss record 49 of 174
==5813==    at 0x48407B4: malloc (vg_replace_malloc.c:381)
==5813==    by 0x500157: ??? (in /usr/bin/python3.11)
==5813==    by 0x508A47: ??? (in /usr/bin/python3.11)
==5813==    by 0x50CCC1: PyDict_SetItemString (in /usr/bin/python3.11)
==5813==    by 0x63C0DA: ??? (in /usr/bin/python3.11)
==5813==    by 0x55A93E: PyModule_ExecDef (in /usr/bin/python3.11)
==5813==    by 0x63BFCB: ??? (in /usr/bin/python3.11)
==5813==    by 0x5458A2: ??? (in /usr/bin/python3.11)
==5813==    by 0x5343AF: _PyEval_EvalFrameDefault (in /usr/bin/python3.11)
==5813==    by 0x55C930: _PyFunction_Vectorcall (in /usr/bin/python3.11)
==5813==    by 0x55BF93: ??? (in /usr/bin/python3.11)
==5813==    by 0x55B6FB: PyObject_CallMethod (in /usr/bin/python3.11)
==5813== 
==5813== 768 bytes in 1 blocks are still reachable in loss record 50 of 174
==5813==    at 0x48407B4: malloc (vg_replace_malloc.c:381)
==5813==    by 0x500157: ??? (in /usr/bin/python3.11)
==5813==    by 0x4FDADD: PyDict_SetDefault (in /usr/bin/python3.11)
==5813==    by 0x501EDE: ??? (in /usr/bin/python3.11)
==5813==    by 0x500F66: PyType_Ready (in /usr/bin/python3.11)
==5813==    by 0x56AA18: PyType_FromModuleAndSpec (in /usr/bin/python3.11)
==5813==    by 0x66DB78: ??? (in /usr/bin/python3.11)
==5813==    by 0x55A93E: PyModule_ExecDef (in /usr/bin/python3.11)
==5813==    by 0x63BFCB: ??? (in /usr/bin/python3.11)
==5813==    by 0x5458A2: ??? (in /usr/bin/python3.11)
==5813==    by 0x5343AF: _PyEval_EvalFrameDefault (in /usr/bin/python3.11)
==5813==    by 0x55C930: _PyFunction_Vectorcall (in /usr/bin/python3.11)
==5813== 
==5813== 768 bytes in 1 blocks are still reachable in loss record 51 of 174
==5813==    at 0x48407B4: malloc (vg_replace_malloc.c:381)
==5813==    by 0x500157: ??? (in /usr/bin/python3.11)
==5813==    by 0x4FDADD: PyDict_SetDefault (in /usr/bin/python3.11)
==5813==    by 0x502EE4: ??? (in /usr/bin/python3.11)
==5813==    by 0x500F66: PyType_Ready (in /usr/bin/python3.11)
==5813==    by 0x51C5FB: ??? (in /usr/bin/python3.11)
==5813==    by 0x5184FE: ??? (in /usr/bin/python3.11)
==5813==    by 0x517E15: _PyObject_MakeTpCall (in /usr/bin/python3.11)
==5813==    by 0x51F269: _PyObject_FastCallDictTstate (in /usr/bin/python3.11)
==5813==    by 0x53B1BB: ??? (in /usr/bin/python3.11)
==5813==    by 0x53ACF6: ??? (in /usr/bin/python3.11)
==5813==    by 0x53AC2B: PyObject_Vectorcall (in /usr/bin/python3.11)
==5813== 
==5813== 768 bytes in 1 blocks are still reachable in loss record 52 of 174
==5813==    at 0x48407B4: malloc (vg_replace_malloc.c:381)
==5813==    by 0x500157: ??? (in /usr/bin/python3.11)
==5813==    by 0x4FDADD: PyDict_SetDefault (in /usr/bin/python3.11)
==5813==    by 0x502EE4: ??? (in /usr/bin/python3.11)
==5813==    by 0x500F66: PyType_Ready (in /usr/bin/python3.11)
==5813==    by 0x56AD81: PyModule_AddType (in /usr/bin/python3.11)
==5813==    by 0x475DD2: PyInit__datetime (in /usr/bin/python3.11)
==5813==    by 0x440F0D: ??? (in /usr/bin/python3.11)
==5813==    by 0x56A6C8: ??? (in /usr/bin/python3.11)
==5813==    by 0x5458A2: ??? (in /usr/bin/python3.11)
==5813==    by 0x5343AF: _PyEval_EvalFrameDefault (in /usr/bin/python3.11)
==5813==    by 0x55C930: _PyFunction_Vectorcall (in /usr/bin/python3.11)
==5813== 
==5813== 768 bytes in 1 blocks are still reachable in loss record 53 of 174
==5813==    at 0x48407B4: malloc (vg_replace_malloc.c:381)
==5813==    by 0x500157: ??? (in /usr/bin/python3.11)
==5813==    by 0x508A47: ??? (in /usr/bin/python3.11)
==5813==    by 0x50122B: ??? (in /usr/bin/python3.11)
==5813==    by 0x500F66: PyType_Ready (in /usr/bin/python3.11)
==5813==    by 0x56AD81: PyModule_AddType (in /usr/bin/python3.11)
==5813==    by 0x475DD2: PyInit__datetime (in /usr/bin/python3.11)
==5813==    by 0x440F0D: ??? (in /usr/bin/python3.11)
==5813==    by 0x56A6C8: ??? (in /usr/bin/python3.11)
==5813==    by 0x5458A2: ??? (in /usr/bin/python3.11)
==5813==    by 0x5343AF: _PyEval_EvalFrameDefault (in /usr/bin/python3.11)
==5813==    by 0x55C930: _PyFunction_Vectorcall (in /usr/bin/python3.11)
==5813== 
==5813== 768 bytes in 1 blocks are still reachable in loss record 54 of 174
==5813==    at 0x48407B4: malloc (vg_replace_malloc.c:381)
==5813==    by 0x4FEA8A: ??? (in /usr/bin/python3.11)
==5813==    by 0x502B3D: ??? (in /usr/bin/python3.11)
==5813==    by 0x518D23: ??? (in /usr/bin/python3.11)
==5813==    by 0x5B48BB: ??? (in /usr/bin/python3.11)
==5813==    by 0x547AC5: ??? (in /usr/bin/python3.11)
==5813==    by 0x56A493: PyObject_Call (in /usr/bin/python3.11)
==5813==    by 0x5343AF: _PyEval_EvalFrameDefault (in /usr/bin/python3.11)
==5813==    by 0x51F066: _PyObject_FastCallDictTstate (in /usr/bin/python3.11)
==5813==    by 0x5B443B: ??? (in /usr/bin/python3.11)
==5813==    by 0x5184E5: ??? (in /usr/bin/python3.11)
==5813==    by 0x517E15: _PyObject_MakeTpCall (in /usr/bin/python3.11)
==5813== 
==5813== 768 bytes in 1 blocks are still reachable in loss record 55 of 174
==5813==    at 0x48407B4: malloc (vg_replace_malloc.c:381)
==5813==    by 0x4FEA8A: ??? (in /usr/bin/python3.11)
==5813==    by 0x502B3D: ??? (in /usr/bin/python3.11)
==5813==    by 0x518D23: ??? (in /usr/bin/python3.11)
==5813==    by 0x5B3984E: ??? (in /usr/lib/python3.11/lib-dynload/_ctypes.cpython-311-x86_64-linux-gnu.so)
==5813==    by 0x517E15: _PyObject_MakeTpCall (in /usr/bin/python3.11)
==5813==    by 0x58F864: _PyObject_CallFunction_SizeT (in /usr/bin/python3.11)
==5813==    by 0x5B39718: ??? (in /usr/lib/python3.11/lib-dynload/_ctypes.cpython-311-x86_64-linux-gnu.so)
==5813==    by 0x52CBB6: _PyEval_EvalFrameDefault (in /usr/bin/python3.11)
==5813==    by 0x53B0E3: ??? (in /usr/bin/python3.11)
==5813==    by 0x53ACF6: ??? (in /usr/bin/python3.11)
==5813==    by 0x53AC2B: PyObject_Vectorcall (in /usr/bin/python3.11)
==5813== 
==5813== 768 bytes in 1 blocks are still reachable in loss record 56 of 174
==5813==    at 0x48407B4: malloc (vg_replace_malloc.c:381)
==5813==    by 0x4FEA8A: ??? (in /usr/bin/python3.11)
==5813==    by 0x502B3D: ??? (in /usr/bin/python3.11)
==5813==    by 0x518D23: ??? (in /usr/bin/python3.11)
==5813==    by 0x5B3F0F0: ??? (in /usr/lib/python3.11/lib-dynload/_ctypes.cpython-311-x86_64-linux-gnu.so)
==5813==    by 0x517E15: _PyObject_MakeTpCall (in /usr/bin/python3.11)
==5813==    by 0x5126A4: PyObject_CallFunction (in /usr/bin/python3.11)
==5813==    by 0x5B3ED58: ??? (in /usr/lib/python3.11/lib-dynload/_ctypes.cpython-311-x86_64-linux-gnu.so)
==5813==    by 0x5458A2: ??? (in /usr/bin/python3.11)
==5813==    by 0x53AC2B: PyObject_Vectorcall (in /usr/bin/python3.11)
==5813==    by 0x52B93F: _PyEval_EvalFrameDefault (in /usr/bin/python3.11)
==5813==    by 0x53B0E3: ??? (in /usr/bin/python3.11)
==5813== 
==5813== 784 bytes in 1 blocks are still reachable in loss record 57 of 174
==5813==    at 0x48407B4: malloc (vg_replace_malloc.c:381)
==5813==    by 0x50601E: PyMem_Malloc (in /usr/bin/python3.11)
==5813==    by 0x57FB7C: ??? (in /usr/bin/python3.11)
==5813==    by 0x530AAF: _PyEval_EvalFrameDefault (in /usr/bin/python3.11)
==5813==    by 0x52360A: PyEval_EvalCode (in /usr/bin/python3.11)
==5813==    by 0x58EC4D: ??? (in /usr/bin/python3.11)
==5813==    by 0x53ACF6: ??? (in /usr/bin/python3.11)
==5813==    by 0x5343AF: _PyEval_EvalFrameDefault (in /usr/bin/python3.11)
==5813==    by 0x55C930: _PyFunction_Vectorcall (in /usr/bin/python3.11)
==5813==    by 0x54618E: ??? (in /usr/bin/python3.11)
==5813==    by 0x58351A: PyObject_CallMethodObjArgs (in /usr/bin/python3.11)
==5813==    by 0x451A10: ??? (in /usr/bin/python3.11)
==5813== 
==5813== 808 bytes in 1 blocks are still reachable in loss record 58 of 174
==5813==    at 0x48407B4: malloc (vg_replace_malloc.c:381)
==5813==    by 0x527DAA: PyBytes_FromStringAndSize (in /usr/bin/python3.11)
==5813==    by 0x5244A3: ??? (in /usr/bin/python3.11)
==5813==    by 0x52479C: ??? (in /usr/bin/python3.11)
==5813==    by 0x524D02: ??? (in /usr/bin/python3.11)
==5813==    by 0x5246F6: ??? (in /usr/bin/python3.11)
==5813==    by 0x6336E3: ??? (in /usr/bin/python3.11)
==5813==    by 0x5B3297: ??? (in /usr/bin/python3.11)
==5813==    by 0x52C176: _PyEval_EvalFrameDefault (in /usr/bin/python3.11)
==5813==    by 0x55C930: _PyFunction_Vectorcall (in /usr/bin/python3.11)
==5813==    by 0x54618E: ??? (in /usr/bin/python3.11)
==5813==    by 0x58351A: PyObject_CallMethodObjArgs (in /usr/bin/python3.11)
==5813== 
==5813== 848 bytes in 1 blocks are still reachable in loss record 59 of 174
==5813==    at 0x48407B4: malloc (vg_replace_malloc.c:381)
==5813==    by 0x53A431: _PyCode_New (in /usr/bin/python3.11)
==5813==    by 0x524892: ??? (in /usr/bin/python3.11)
==5813==    by 0x524C79: ??? (in /usr/bin/python3.11)
==5813==    by 0x5246F6: ??? (in /usr/bin/python3.11)
==5813==    by 0x524C9D: ??? (in /usr/bin/python3.11)
==5813==    by 0x5246F6: ??? (in /usr/bin/python3.11)
==5813==    by 0x524D02: ??? (in /usr/bin/python3.11)
==5813==    by 0x5246F6: ??? (in /usr/bin/python3.11)
==5813==    by 0x6336E3: ??? (in /usr/bin/python3.11)
==5813==    by 0x5B3297: ??? (in /usr/bin/python3.11)
==5813==    by 0x52C176: _PyEval_EvalFrameDefault (in /usr/bin/python3.11)
==5813== 
==5813== 859 bytes in 1 blocks are still reachable in loss record 60 of 174
==5813==    at 0x48407B4: malloc (vg_replace_malloc.c:381)
==5813==    by 0x519E29: ??? (in /usr/bin/python3.11)
==5813==    by 0x5B48BB: ??? (in /usr/bin/python3.11)
==5813==    by 0x547AC5: ??? (in /usr/bin/python3.11)
==5813==    by 0x56A493: PyObject_Call (in /usr/bin/python3.11)
==5813==    by 0x5343AF: _PyEval_EvalFrameDefault (in /usr/bin/python3.11)
==5813==    by 0x51F066: _PyObject_FastCallDictTstate (in /usr/bin/python3.11)
==5813==    by 0x5B443B: ??? (in /usr/bin/python3.11)
==5813==    by 0x517E15: _PyObject_MakeTpCall (in /usr/bin/python3.11)
==5813==    by 0x53B1BB: ??? (in /usr/bin/python3.11)
==5813==    by 0x53ACF6: ??? (in /usr/bin/python3.11)
==5813==    by 0x53AC2B: PyObject_Vectorcall (in /usr/bin/python3.11)
==5813== 
==5813== 896 bytes in 1 blocks are still reachable in loss record 61 of 174
==5813==    at 0x48407B4: malloc (vg_replace_malloc.c:381)
==5813==    by 0x53A431: _PyCode_New (in /usr/bin/python3.11)
==5813==    by 0x524892: ??? (in /usr/bin/python3.11)
==5813==    by 0x524C55: ??? (in /usr/bin/python3.11)
==5813==    by 0x5246F6: ??? (in /usr/bin/python3.11)
==5813==    by 0x524D02: ??? (in /usr/bin/python3.11)
==5813==    by 0x5246F6: ??? (in /usr/bin/python3.11)
==5813==    by 0x6336E3: ??? (in /usr/bin/python3.11)
==5813==    by 0x5B3297: ??? (in /usr/bin/python3.11)
==5813==    by 0x52C176: _PyEval_EvalFrameDefault (in /usr/bin/python3.11)
==5813==    by 0x55C930: _PyFunction_Vectorcall (in /usr/bin/python3.11)
==5813==    by 0x54618E: ??? (in /usr/bin/python3.11)
==5813== 
==5813== 960 bytes in 1 blocks are still reachable in loss record 62 of 174
==5813==    at 0x48407B4: malloc (vg_replace_malloc.c:381)
==5813==    by 0x50825A: PyType_GenericAlloc (in /usr/bin/python3.11)
==5813==    by 0x56A741: PyType_FromModuleAndSpec (in /usr/bin/python3.11)
==5813==    by 0x64CBA6: ??? (in /usr/bin/python3.11)
==5813==    by 0x55A93E: PyModule_ExecDef (in /usr/bin/python3.11)
==5813==    by 0x63BFCB: ??? (in /usr/bin/python3.11)
==5813==    by 0x5458A2: ??? (in /usr/bin/python3.11)
==5813==    by 0x5343AF: _PyEval_EvalFrameDefault (in /usr/bin/python3.11)
==5813==    by 0x55C930: _PyFunction_Vectorcall (in /usr/bin/python3.11)
==5813==    by 0x54618E: ??? (in /usr/bin/python3.11)
==5813==    by 0x58351A: PyObject_CallMethodObjArgs (in /usr/bin/python3.11)
==5813==    by 0x451A10: ??? (in /usr/bin/python3.11)
==5813== 
==5813== 960 bytes in 1 blocks are still reachable in loss record 63 of 174
==5813==    at 0x48407B4: malloc (vg_replace_malloc.c:381)
==5813==    by 0x50825A: PyType_GenericAlloc (in /usr/bin/python3.11)
==5813==    by 0x51968E: ??? (in /usr/bin/python3.11)
==5813==    by 0x517E15: _PyObject_MakeTpCall (in /usr/bin/python3.11)
==5813==    by 0x51F269: _PyObject_FastCallDictTstate (in /usr/bin/python3.11)
==5813==    by 0x53B1BB: ??? (in /usr/bin/python3.11)
==5813==    by 0x53ACF6: ??? (in /usr/bin/python3.11)
==5813==    by 0x53AC2B: PyObject_Vectorcall (in /usr/bin/python3.11)
==5813==    by 0x52B93F: _PyEval_EvalFrameDefault (in /usr/bin/python3.11)
==5813==    by 0x52360A: PyEval_EvalCode (in /usr/bin/python3.11)
==5813==    by 0x58EC4D: ??? (in /usr/bin/python3.11)
==5813==    by 0x52ECC4: _PyEval_EvalFrameDefault (in /usr/bin/python3.11)
==5813== 
==5813== 960 bytes in 1 blocks are still reachable in loss record 64 of 174
==5813==    at 0x48407B4: malloc (vg_replace_malloc.c:381)
==5813==    by 0x50825A: PyType_GenericAlloc (in /usr/bin/python3.11)
==5813==    by 0x56A741: PyType_FromModuleAndSpec (in /usr/bin/python3.11)
==5813==    by 0x651CC3: ??? (in /usr/bin/python3.11)
==5813==    by 0x55A93E: PyModule_ExecDef (in /usr/bin/python3.11)
==5813==    by 0x63BFCB: ??? (in /usr/bin/python3.11)
==5813==    by 0x5458A2: ??? (in /usr/bin/python3.11)
==5813==    by 0x5343AF: _PyEval_EvalFrameDefault (in /usr/bin/python3.11)
==5813==    by 0x55C930: _PyFunction_Vectorcall (in /usr/bin/python3.11)
==5813==    by 0x54618E: ??? (in /usr/bin/python3.11)
==5813==    by 0x58351A: PyObject_CallMethodObjArgs (in /usr/bin/python3.11)
==5813==    by 0x451A10: ??? (in /usr/bin/python3.11)
==5813== 
==5813== 960 bytes in 1 blocks are still reachable in loss record 65 of 174
==5813==    at 0x48407B4: malloc (vg_replace_malloc.c:381)
==5813==    by 0x50825A: PyType_GenericAlloc (in /usr/bin/python3.11)
==5813==    by 0x56A741: PyType_FromModuleAndSpec (in /usr/bin/python3.11)
==5813==    by 0x6524F6: ??? (in /usr/bin/python3.11)
==5813==    by 0x55A93E: PyModule_ExecDef (in /usr/bin/python3.11)
==5813==    by 0x63BFCB: ??? (in /usr/bin/python3.11)
==5813==    by 0x5458A2: ??? (in /usr/bin/python3.11)
==5813==    by 0x5343AF: _PyEval_EvalFrameDefault (in /usr/bin/python3.11)
==5813==    by 0x55C930: _PyFunction_Vectorcall (in /usr/bin/python3.11)
==5813==    by 0x54618E: ??? (in /usr/bin/python3.11)
==5813==    by 0x58351A: PyObject_CallMethodObjArgs (in /usr/bin/python3.11)
==5813==    by 0x451A10: ??? (in /usr/bin/python3.11)
==5813== 
==5813== 960 bytes in 1 blocks are still reachable in loss record 66 of 174
==5813==    at 0x48407B4: malloc (vg_replace_malloc.c:381)
==5813==    by 0x50825A: PyType_GenericAlloc (in /usr/bin/python3.11)
==5813==    by 0x51968E: ??? (in /usr/bin/python3.11)
==5813==    by 0x517E15: _PyObject_MakeTpCall (in /usr/bin/python3.11)
==5813==    by 0x52E996: _PyEval_EvalFrameDefault (in /usr/bin/python3.11)
==5813==    by 0x52360A: PyEval_EvalCode (in /usr/bin/python3.11)
==5813==    by 0x58EC4D: ??? (in /usr/bin/python3.11)
==5813==    by 0x53ACF6: ??? (in /usr/bin/python3.11)
==5813==    by 0x5343AF: _PyEval_EvalFrameDefault (in /usr/bin/python3.11)
==5813==    by 0x55C930: _PyFunction_Vectorcall (in /usr/bin/python3.11)
==5813==    by 0x54618E: ??? (in /usr/bin/python3.11)
==5813==    by 0x58351A: PyObject_CallMethodObjArgs (in /usr/bin/python3.11)
==5813== 
==5813== 960 bytes in 1 blocks are still reachable in loss record 67 of 174
==5813==    at 0x48407B4: malloc (vg_replace_malloc.c:381)
==5813==    by 0x50825A: PyType_GenericAlloc (in /usr/bin/python3.11)
==5813==    by 0x5185D1: ??? (in /usr/bin/python3.11)
==5813==    by 0x517E15: _PyObject_MakeTpCall (in /usr/bin/python3.11)
==5813==    by 0x5125C2: PyObject_CallFunction (in /usr/bin/python3.11)
==5813==    by 0x631A49: PyErr_NewException (in /usr/bin/python3.11)
==5813==    by 0x597AA00: PyInit__curses (in /usr/lib/python3.11/lib-dynload/_curses.cpython-311-x86_64-linux-gnu.so)
==5813==    by 0x6539FA: ??? (in /usr/bin/python3.11)
==5813==    by 0x54DDD7: ??? (in /usr/bin/python3.11)
==5813==    by 0x5343AF: _PyEval_EvalFrameDefault (in /usr/bin/python3.11)
==5813==    by 0x55C930: _PyFunction_Vectorcall (in /usr/bin/python3.11)
==5813==    by 0x54618E: ??? (in /usr/bin/python3.11)
==5813== 
==5813== 960 bytes in 1 blocks are still reachable in loss record 68 of 174
==5813==    at 0x48407B4: malloc (vg_replace_malloc.c:381)
==5813==    by 0x50825A: PyType_GenericAlloc (in /usr/bin/python3.11)
==5813==    by 0x5185D1: ??? (in /usr/bin/python3.11)
==5813==    by 0x517E15: _PyObject_MakeTpCall (in /usr/bin/python3.11)
==5813==    by 0x5125C2: PyObject_CallFunction (in /usr/bin/python3.11)
==5813==    by 0x631A49: PyErr_NewException (in /usr/bin/python3.11)
==5813==    by 0x66DDC4: PyInit__socket (in /usr/bin/python3.11)
==5813==    by 0x440F0D: ??? (in /usr/bin/python3.11)
==5813==    by 0x56A6C8: ??? (in /usr/bin/python3.11)
==5813==    by 0x5458A2: ??? (in /usr/bin/python3.11)
==5813==    by 0x5343AF: _PyEval_EvalFrameDefault (in /usr/bin/python3.11)
==5813==    by 0x55C930: _PyFunction_Vectorcall (in /usr/bin/python3.11)
==5813== 
==5813== 960 bytes in 1 blocks are still reachable in loss record 69 of 174
==5813==    at 0x48407B4: malloc (vg_replace_malloc.c:381)
==5813==    by 0x50825A: PyType_GenericAlloc (in /usr/bin/python3.11)
==5813==    by 0x5185D1: ??? (in /usr/bin/python3.11)
==5813==    by 0x517E15: _PyObject_MakeTpCall (in /usr/bin/python3.11)
==5813==    by 0x5125C2: PyObject_CallFunction (in /usr/bin/python3.11)
==5813==    by 0x631A49: PyErr_NewException (in /usr/bin/python3.11)
==5813==    by 0x66DDFB: PyInit__socket (in /usr/bin/python3.11)
==5813==    by 0x440F0D: ??? (in /usr/bin/python3.11)
==5813==    by 0x56A6C8: ??? (in /usr/bin/python3.11)
==5813==    by 0x5458A2: ??? (in /usr/bin/python3.11)
==5813==    by 0x5343AF: _PyEval_EvalFrameDefault (in /usr/bin/python3.11)
==5813==    by 0x55C930: _PyFunction_Vectorcall (in /usr/bin/python3.11)
==5813== 
==5813== 960 bytes in 1 blocks are still reachable in loss record 70 of 174
==5813==    at 0x48407B4: malloc (vg_replace_malloc.c:381)
==5813==    by 0x50825A: PyType_GenericAlloc (in /usr/bin/python3.11)
==5813==    by 0x51968E: ??? (in /usr/bin/python3.11)
==5813==    by 0x517E15: _PyObject_MakeTpCall (in /usr/bin/python3.11)
==5813==    by 0x52E996: _PyEval_EvalFrameDefault (in /usr/bin/python3.11)
==5813==    by 0x55C930: _PyFunction_Vectorcall (in /usr/bin/python3.11)
==5813==    by 0x512B13: ??? (in /usr/bin/python3.11)
==5813==    by 0x55C0BE: ??? (in /usr/bin/python3.11)
==5813==    by 0x55B6FB: PyObject_CallMethod (in /usr/bin/python3.11)
==5813==    by 0x65A9ED8: PyInit__decimal (in /usr/lib/python3.11/lib-dynload/_decimal.cpython-311-x86_64-linux-gnu.so)
==5813==    by 0x6539FA: ??? (in /usr/bin/python3.11)
==5813==    by 0x54DDD7: ??? (in /usr/bin/python3.11)
==5813== 
==5813== 960 bytes in 1 blocks are still reachable in loss record 71 of 174
==5813==    at 0x48407B4: malloc (vg_replace_malloc.c:381)
==5813==    by 0x50825A: PyType_GenericAlloc (in /usr/bin/python3.11)
==5813==    by 0x5185D1: ??? (in /usr/bin/python3.11)
==5813==    by 0x5B48BB: ??? (in /usr/bin/python3.11)
==5813==    by 0x547AC5: ??? (in /usr/bin/python3.11)
==5813==    by 0x56A493: PyObject_Call (in /usr/bin/python3.11)
==5813==    by 0x5343AF: _PyEval_EvalFrameDefault (in /usr/bin/python3.11)
==5813==    by 0x51F066: _PyObject_FastCallDictTstate (in /usr/bin/python3.11)
==5813==    by 0x5B443B: ??? (in /usr/bin/python3.11)
==5813==    by 0x5184E5: ??? (in /usr/bin/python3.11)
==5813==    by 0x517E15: _PyObject_MakeTpCall (in /usr/bin/python3.11)
==5813==    by 0x5125C2: PyObject_CallFunction (in /usr/bin/python3.11)
==5813== 
==5813== 960 bytes in 1 blocks are still reachable in loss record 72 of 174
==5813==    at 0x48407B4: malloc (vg_replace_malloc.c:381)
==5813==    by 0x50825A: PyType_GenericAlloc (in /usr/bin/python3.11)
==5813==    by 0x5185D1: ??? (in /usr/bin/python3.11)
==5813==    by 0x517E15: _PyObject_MakeTpCall (in /usr/bin/python3.11)
==5813==    by 0x5125C2: PyObject_CallFunction (in /usr/bin/python3.11)
==5813==    by 0x631A49: PyErr_NewException (in /usr/bin/python3.11)
==5813==    by 0x65AA04D: PyInit__decimal (in /usr/lib/python3.11/lib-dynload/_decimal.cpython-311-x86_64-linux-gnu.so)
==5813==    by 0x6539FA: ??? (in /usr/bin/python3.11)
==5813==    by 0x54DDD7: ??? (in /usr/bin/python3.11)
==5813==    by 0x5343AF: _PyEval_EvalFrameDefault (in /usr/bin/python3.11)
==5813==    by 0x55C930: _PyFunction_Vectorcall (in /usr/bin/python3.11)
==5813==    by 0x54618E: ??? (in /usr/bin/python3.11)
==5813== 
==5813== 960 bytes in 1 blocks are still reachable in loss record 73 of 174
==5813==    at 0x48407B4: malloc (vg_replace_malloc.c:381)
==5813==    by 0x50825A: PyType_GenericAlloc (in /usr/bin/python3.11)
==5813==    by 0x5185D1: ??? (in /usr/bin/python3.11)
==5813==    by 0x517E15: _PyObject_MakeTpCall (in /usr/bin/python3.11)
==5813==    by 0x5125C2: PyObject_CallFunction (in /usr/bin/python3.11)
==5813==    by 0x631A49: PyErr_NewException (in /usr/bin/python3.11)
==5813==    by 0x5B4148B: PyInit__ctypes (in /usr/lib/python3.11/lib-dynload/_ctypes.cpython-311-x86_64-linux-gnu.so)
==5813==    by 0x6539FA: ??? (in /usr/bin/python3.11)
==5813==    by 0x54DDD7: ??? (in /usr/bin/python3.11)
==5813==    by 0x5343AF: _PyEval_EvalFrameDefault (in /usr/bin/python3.11)
==5813==    by 0x55C930: _PyFunction_Vectorcall (in /usr/bin/python3.11)
==5813==    by 0x54618E: ??? (in /usr/bin/python3.11)
==5813== 
==5813== 960 bytes in 1 blocks are still reachable in loss record 74 of 174
==5813==    at 0x48407B4: malloc (vg_replace_malloc.c:381)
==5813==    by 0x50825A: PyType_GenericAlloc (in /usr/bin/python3.11)
==5813==    by 0x5185D1: ??? (in /usr/bin/python3.11)
==5813==    by 0x5B3984E: ??? (in /usr/lib/python3.11/lib-dynload/_ctypes.cpython-311-x86_64-linux-gnu.so)
==5813==    by 0x517E15: _PyObject_MakeTpCall (in /usr/bin/python3.11)
==5813==    by 0x58F864: _PyObject_CallFunction_SizeT (in /usr/bin/python3.11)
==5813==    by 0x5B39718: ??? (in /usr/lib/python3.11/lib-dynload/_ctypes.cpython-311-x86_64-linux-gnu.so)
==5813==    by 0x52CBB6: _PyEval_EvalFrameDefault (in /usr/bin/python3.11)
==5813==    by 0x53B0E3: ??? (in /usr/bin/python3.11)
==5813==    by 0x53ACF6: ??? (in /usr/bin/python3.11)
==5813==    by 0x53AC2B: PyObject_Vectorcall (in /usr/bin/python3.11)
==5813==    by 0x52B93F: _PyEval_EvalFrameDefault (in /usr/bin/python3.11)
==5813== 
==5813== 960 bytes in 1 blocks are still reachable in loss record 75 of 174
==5813==    at 0x48407B4: malloc (vg_replace_malloc.c:381)
==5813==    by 0x50825A: PyType_GenericAlloc (in /usr/bin/python3.11)
==5813==    by 0x5185D1: ??? (in /usr/bin/python3.11)
==5813==    by 0x5B3F0F0: ??? (in /usr/lib/python3.11/lib-dynload/_ctypes.cpython-311-x86_64-linux-gnu.so)
==5813==    by 0x517E15: _PyObject_MakeTpCall (in /usr/bin/python3.11)
==5813==    by 0x5126A4: PyObject_CallFunction (in /usr/bin/python3.11)
==5813==    by 0x5B3ED58: ??? (in /usr/lib/python3.11/lib-dynload/_ctypes.cpython-311-x86_64-linux-gnu.so)
==5813==    by 0x5458A2: ??? (in /usr/bin/python3.11)
==5813==    by 0x53AC2B: PyObject_Vectorcall (in /usr/bin/python3.11)
==5813==    by 0x52B93F: _PyEval_EvalFrameDefault (in /usr/bin/python3.11)
==5813==    by 0x53B0E3: ??? (in /usr/bin/python3.11)
==5813==    by 0x53ACF6: ??? (in /usr/bin/python3.11)
==5813== 
==5813== 984 bytes in 1 blocks are still reachable in loss record 76 of 174
==5813==    at 0x48407B4: malloc (vg_replace_malloc.c:381)
==5813==    by 0x5A0481E: _nc_read_termtype (in /usr/lib/x86_64-linux-gnu/libtinfo.so.6.4)
==5813==    by 0x5A04B1A: _nc_read_file_entry (in /usr/lib/x86_64-linux-gnu/libtinfo.so.6.4)
==5813==    by 0x5A04E7C: ??? (in /usr/lib/x86_64-linux-gnu/libtinfo.so.6.4)
==5813==    by 0x5A04FCB: _nc_read_entry2 (in /usr/lib/x86_64-linux-gnu/libtinfo.so.6.4)
==5813==    by 0x59FC018: ??? (in /usr/lib/x86_64-linux-gnu/libtinfo.so.6.4)
==5813==    by 0x59FC3D5: _nc_setupterm (in /usr/lib/x86_64-linux-gnu/libtinfo.so.6.4)
==5813==    by 0x5978983: ??? (in /usr/lib/python3.11/lib-dynload/_curses.cpython-311-x86_64-linux-gnu.so)
==5813==    by 0x53ACF6: ??? (in /usr/bin/python3.11)
==5813==    by 0x53AC2B: PyObject_Vectorcall (in /usr/bin/python3.11)
==5813==    by 0x52B93F: _PyEval_EvalFrameDefault (in /usr/bin/python3.11)
==5813==    by 0x51F066: _PyObject_FastCallDictTstate (in /usr/bin/python3.11)
==5813== 
==5813== 985 bytes in 1 blocks are still reachable in loss record 77 of 174
==5813==    at 0x48455EF: calloc (vg_replace_malloc.c:1328)
==5813==    by 0x59F74F9: ??? (in /usr/lib/x86_64-linux-gnu/libtinfo.so.6.4)
==5813==    by 0x59FC404: _nc_setupterm (in /usr/lib/x86_64-linux-gnu/libtinfo.so.6.4)
==5813==    by 0x5978983: ??? (in /usr/lib/python3.11/lib-dynload/_curses.cpython-311-x86_64-linux-gnu.so)
==5813==    by 0x53ACF6: ??? (in /usr/bin/python3.11)
==5813==    by 0x53AC2B: PyObject_Vectorcall (in /usr/bin/python3.11)
==5813==    by 0x52B93F: _PyEval_EvalFrameDefault (in /usr/bin/python3.11)
==5813==    by 0x51F066: _PyObject_FastCallDictTstate (in /usr/bin/python3.11)
==5813==    by 0x565972: ??? (in /usr/bin/python3.11)
==5813==    by 0x517E54: _PyObject_MakeTpCall (in /usr/bin/python3.11)
==5813==    by 0x52B93F: _PyEval_EvalFrameDefault (in /usr/bin/python3.11)
==5813==    by 0x52360A: PyEval_EvalCode (in /usr/bin/python3.11)
==5813== 
==5813== 992 bytes in 1 blocks are still reachable in loss record 78 of 174
==5813==    at 0x48407B4: malloc (vg_replace_malloc.c:381)
==5813==    by 0x53A431: _PyCode_New (in /usr/bin/python3.11)
==5813==    by 0x524892: ??? (in /usr/bin/python3.11)
==5813==    by 0x524CBD: ??? (in /usr/bin/python3.11)
==5813==    by 0x5246F6: ??? (in /usr/bin/python3.11)
==5813==    by 0x524D02: ??? (in /usr/bin/python3.11)
==5813==    by 0x5246F6: ??? (in /usr/bin/python3.11)
==5813==    by 0x6336E3: ??? (in /usr/bin/python3.11)
==5813==    by 0x5B3297: ??? (in /usr/bin/python3.11)
==5813==    by 0x52C176: _PyEval_EvalFrameDefault (in /usr/bin/python3.11)
==5813==    by 0x55C930: _PyFunction_Vectorcall (in /usr/bin/python3.11)
==5813==    by 0x54618E: ??? (in /usr/bin/python3.11)
==5813== 
==5813== 1,000 bytes in 1 blocks are still reachable in loss record 79 of 174
==5813==    at 0x48407B4: malloc (vg_replace_malloc.c:381)
==5813==    by 0x50825A: PyType_GenericAlloc (in /usr/bin/python3.11)
==5813==    by 0x56A741: PyType_FromModuleAndSpec (in /usr/bin/python3.11)
==5813==    by 0x63C024: ??? (in /usr/bin/python3.11)
==5813==    by 0x55A93E: PyModule_ExecDef (in /usr/bin/python3.11)
==5813==    by 0x63BFCB: ??? (in /usr/bin/python3.11)
==5813==    by 0x5458A2: ??? (in /usr/bin/python3.11)
==5813==    by 0x5343AF: _PyEval_EvalFrameDefault (in /usr/bin/python3.11)
==5813==    by 0x55C930: _PyFunction_Vectorcall (in /usr/bin/python3.11)
==5813==    by 0x55BF93: ??? (in /usr/bin/python3.11)
==5813==    by 0x55B6FB: PyObject_CallMethod (in /usr/bin/python3.11)
==5813==    by 0x4FAB2A: ??? (in /usr/bin/python3.11)
==5813== 
==5813== 1,000 bytes in 1 blocks are still reachable in loss record 80 of 174
==5813==    at 0x48407B4: malloc (vg_replace_malloc.c:381)
==5813==    by 0x50825A: PyType_GenericAlloc (in /usr/bin/python3.11)
==5813==    by 0x56A741: PyType_FromModuleAndSpec (in /usr/bin/python3.11)
==5813==    by 0x63C054: ??? (in /usr/bin/python3.11)
==5813==    by 0x55A93E: PyModule_ExecDef (in /usr/bin/python3.11)
==5813==    by 0x63BFCB: ??? (in /usr/bin/python3.11)
==5813==    by 0x5458A2: ??? (in /usr/bin/python3.11)
==5813==    by 0x5343AF: _PyEval_EvalFrameDefault (in /usr/bin/python3.11)
==5813==    by 0x55C930: _PyFunction_Vectorcall (in /usr/bin/python3.11)
==5813==    by 0x55BF93: ??? (in /usr/bin/python3.11)
==5813==    by 0x55B6FB: PyObject_CallMethod (in /usr/bin/python3.11)
==5813==    by 0x4FAB2A: ??? (in /usr/bin/python3.11)
==5813== 
==5813== 1,000 bytes in 1 blocks are still reachable in loss record 81 of 174
==5813==    at 0x48407B4: malloc (vg_replace_malloc.c:381)
==5813==    by 0x50825A: PyType_GenericAlloc (in /usr/bin/python3.11)
==5813==    by 0x56A741: PyType_FromModuleAndSpec (in /usr/bin/python3.11)
==5813==    by 0x63C088: ??? (in /usr/bin/python3.11)
==5813==    by 0x55A93E: PyModule_ExecDef (in /usr/bin/python3.11)
==5813==    by 0x63BFCB: ??? (in /usr/bin/python3.11)
==5813==    by 0x5458A2: ??? (in /usr/bin/python3.11)
==5813==    by 0x5343AF: _PyEval_EvalFrameDefault (in /usr/bin/python3.11)
==5813==    by 0x55C930: _PyFunction_Vectorcall (in /usr/bin/python3.11)
==5813==    by 0x55BF93: ??? (in /usr/bin/python3.11)
==5813==    by 0x55B6FB: PyObject_CallMethod (in /usr/bin/python3.11)
==5813==    by 0x4FAB2A: ??? (in /usr/bin/python3.11)
==5813== 
==5813== 1,000 bytes in 1 blocks are still reachable in loss record 82 of 174
==5813==    at 0x48407B4: malloc (vg_replace_malloc.c:381)
==5813==    by 0x50825A: PyType_GenericAlloc (in /usr/bin/python3.11)
==5813==    by 0x56A741: PyType_FromModuleAndSpec (in /usr/bin/python3.11)
==5813==    by 0x63C0A5: ??? (in /usr/bin/python3.11)
==5813==    by 0x55A93E: PyModule_ExecDef (in /usr/bin/python3.11)
==5813==    by 0x63BFCB: ??? (in /usr/bin/python3.11)
==5813==    by 0x5458A2: ??? (in /usr/bin/python3.11)
==5813==    by 0x5343AF: _PyEval_EvalFrameDefault (in /usr/bin/python3.11)
==5813==    by 0x55C930: _PyFunction_Vectorcall (in /usr/bin/python3.11)
==5813==    by 0x55BF93: ??? (in /usr/bin/python3.11)
==5813==    by 0x55B6FB: PyObject_CallMethod (in /usr/bin/python3.11)
==5813==    by 0x4FAB2A: ??? (in /usr/bin/python3.11)
==5813== 
==5813== 1,000 bytes in 1 blocks are still reachable in loss record 83 of 174
==5813==    at 0x48407B4: malloc (vg_replace_malloc.c:381)
==5813==    by 0x50825A: PyType_GenericAlloc (in /usr/bin/python3.11)
==5813==    by 0x56A741: PyType_FromModuleAndSpec (in /usr/bin/python3.11)
==5813==    by 0x651C65: ??? (in /usr/bin/python3.11)
==5813==    by 0x55A93E: PyModule_ExecDef (in /usr/bin/python3.11)
==5813==    by 0x63BFCB: ??? (in /usr/bin/python3.11)
==5813==    by 0x5458A2: ??? (in /usr/bin/python3.11)
==5813==    by 0x5343AF: _PyEval_EvalFrameDefault (in /usr/bin/python3.11)
==5813==    by 0x55C930: _PyFunction_Vectorcall (in /usr/bin/python3.11)
==5813==    by 0x54618E: ??? (in /usr/bin/python3.11)
==5813==    by 0x58351A: PyObject_CallMethodObjArgs (in /usr/bin/python3.11)
==5813==    by 0x451A10: ??? (in /usr/bin/python3.11)
==5813== 
==5813== 1,000 bytes in 1 blocks are still reachable in loss record 84 of 174
==5813==    at 0x48407B4: malloc (vg_replace_malloc.c:381)
==5813==    by 0x50825A: PyType_GenericAlloc (in /usr/bin/python3.11)
==5813==    by 0x56A741: PyType_FromModuleAndSpec (in /usr/bin/python3.11)
==5813==    by 0x651C94: ??? (in /usr/bin/python3.11)
==5813==    by 0x55A93E: PyModule_ExecDef (in /usr/bin/python3.11)
==5813==    by 0x63BFCB: ??? (in /usr/bin/python3.11)
==5813==    by 0x5458A2: ??? (in /usr/bin/python3.11)
==5813==    by 0x5343AF: _PyEval_EvalFrameDefault (in /usr/bin/python3.11)
==5813==    by 0x55C930: _PyFunction_Vectorcall (in /usr/bin/python3.11)
==5813==    by 0x54618E: ??? (in /usr/bin/python3.11)
==5813==    by 0x58351A: PyObject_CallMethodObjArgs (in /usr/bin/python3.11)
==5813==    by 0x451A10: ??? (in /usr/bin/python3.11)
==5813== 
==5813== 1,000 bytes in 1 blocks are still reachable in loss record 85 of 174
==5813==    at 0x48407B4: malloc (vg_replace_malloc.c:381)
==5813==    by 0x50825A: PyType_GenericAlloc (in /usr/bin/python3.11)
==5813==    by 0x56A741: PyType_FromModuleAndSpec (in /usr/bin/python3.11)
==5813==    by 0x6524D9: ??? (in /usr/bin/python3.11)
==5813==    by 0x55A93E: PyModule_ExecDef (in /usr/bin/python3.11)
==5813==    by 0x63BFCB: ??? (in /usr/bin/python3.11)
==5813==    by 0x5458A2: ??? (in /usr/bin/python3.11)
==5813==    by 0x5343AF: _PyEval_EvalFrameDefault (in /usr/bin/python3.11)
==5813==    by 0x55C930: _PyFunction_Vectorcall (in /usr/bin/python3.11)
==5813==    by 0x54618E: ??? (in /usr/bin/python3.11)
==5813==    by 0x58351A: PyObject_CallMethodObjArgs (in /usr/bin/python3.11)
==5813==    by 0x451A10: ??? (in /usr/bin/python3.11)
==5813== 
==5813== 1,000 bytes in 1 blocks are still reachable in loss record 86 of 174
==5813==    at 0x48407B4: malloc (vg_replace_malloc.c:381)
==5813==    by 0x50825A: PyType_GenericAlloc (in /usr/bin/python3.11)
==5813==    by 0x56A741: PyType_FromModuleAndSpec (in /usr/bin/python3.11)
==5813==    by 0x66DBB0: ??? (in /usr/bin/python3.11)
==5813==    by 0x55A93E: PyModule_ExecDef (in /usr/bin/python3.11)
==5813==    by 0x63BFCB: ??? (in /usr/bin/python3.11)
==5813==    by 0x5458A2: ??? (in /usr/bin/python3.11)
==5813==    by 0x5343AF: _PyEval_EvalFrameDefault (in /usr/bin/python3.11)
==5813==    by 0x55C930: _PyFunction_Vectorcall (in /usr/bin/python3.11)
==5813==    by 0x54618E: ??? (in /usr/bin/python3.11)
==5813==    by 0x58351A: PyObject_CallMethodObjArgs (in /usr/bin/python3.11)
==5813==    by 0x451A10: ??? (in /usr/bin/python3.11)
==5813== 
==5813== 1,024 bytes in 1 blocks are still reachable in loss record 87 of 174
==5813==    at 0x48407B4: malloc (vg_replace_malloc.c:381)
==5813==    by 0x5147B0: ??? (in /usr/bin/python3.11)
==5813==    by 0x513A2D: ??? (in /usr/bin/python3.11)
==5813==    by 0x512D07: ??? (in /usr/bin/python3.11)
==5813==    by 0x66F9D4: ??? (in /usr/bin/python3.11)
==5813==    by 0x5B9440: PyNumber_Or (in /usr/bin/python3.11)
==5813==    by 0x52CBB6: _PyEval_EvalFrameDefault (in /usr/bin/python3.11)
==5813==    by 0x53B0E3: ??? (in /usr/bin/python3.11)
==5813==    by 0x53ACF6: ??? (in /usr/bin/python3.11)
==5813==    by 0x53AC2B: PyObject_Vectorcall (in /usr/bin/python3.11)
==5813==    by 0x52B93F: _PyEval_EvalFrameDefault (in /usr/bin/python3.11)
==5813==    by 0x52360A: PyEval_EvalCode (in /usr/bin/python3.11)
==5813== 
==5813== 1,040 bytes in 1 blocks are still reachable in loss record 88 of 174
==5813==    at 0x48407B4: malloc (vg_replace_malloc.c:381)
==5813==    by 0x50825A: PyType_GenericAlloc (in /usr/bin/python3.11)
==5813==    by 0x56A741: PyType_FromModuleAndSpec (in /usr/bin/python3.11)
==5813==    by 0x6524A0: ??? (in /usr/bin/python3.11)
==5813==    by 0x55A93E: PyModule_ExecDef (in /usr/bin/python3.11)
==5813==    by 0x63BFCB: ??? (in /usr/bin/python3.11)
==5813==    by 0x5458A2: ??? (in /usr/bin/python3.11)
==5813==    by 0x5343AF: _PyEval_EvalFrameDefault (in /usr/bin/python3.11)
==5813==    by 0x55C930: _PyFunction_Vectorcall (in /usr/bin/python3.11)
==5813==    by 0x54618E: ??? (in /usr/bin/python3.11)
==5813==    by 0x58351A: PyObject_CallMethodObjArgs (in /usr/bin/python3.11)
==5813==    by 0x451A10: ??? (in /usr/bin/python3.11)
==5813== 
==5813== 1,089 bytes in 1 blocks are still reachable in loss record 89 of 174
==5813==    at 0x48407B4: malloc (vg_replace_malloc.c:381)
==5813==    by 0x4FBDF9: ??? (in /usr/bin/python3.11)
==5813==    by 0x502CC6: ??? (in /usr/bin/python3.11)
==5813==    by 0x500F66: PyType_Ready (in /usr/bin/python3.11)
==5813==    by 0x56AD81: PyModule_AddType (in /usr/bin/python3.11)
==5813==    by 0x676FB0: PyInit__pickle (in /usr/bin/python3.11)
==5813==    by 0x440F0D: ??? (in /usr/bin/python3.11)
==5813==    by 0x56A6C8: ??? (in /usr/bin/python3.11)
==5813==    by 0x5458A2: ??? (in /usr/bin/python3.11)
==5813==    by 0x5343AF: _PyEval_EvalFrameDefault (in /usr/bin/python3.11)
==5813==    by 0x55C930: _PyFunction_Vectorcall (in /usr/bin/python3.11)
==5813==    by 0x54618E: ??? (in /usr/bin/python3.11)
==5813== 
==5813== 1,104 bytes in 1 blocks are still reachable in loss record 90 of 174
==5813==    at 0x48407B4: malloc (vg_replace_malloc.c:381)
==5813==    by 0x500157: ??? (in /usr/bin/python3.11)
==5813==    by 0x508A47: ??? (in /usr/bin/python3.11)
==5813==    by 0x501D1F: ??? (in /usr/bin/python3.11)
==5813==    by 0x518D23: ??? (in /usr/bin/python3.11)
==5813==    by 0x5B3D037: ??? (in /usr/lib/python3.11/lib-dynload/_ctypes.cpython-311-x86_64-linux-gnu.so)
==5813==    by 0x517E15: _PyObject_MakeTpCall (in /usr/bin/python3.11)
==5813==    by 0x53B1BB: ??? (in /usr/bin/python3.11)
==5813==    by 0x53ACF6: ??? (in /usr/bin/python3.11)
==5813==    by 0x53AC2B: PyObject_Vectorcall (in /usr/bin/python3.11)
==5813==    by 0x52B93F: _PyEval_EvalFrameDefault (in /usr/bin/python3.11)
==5813==    by 0x52360A: PyEval_EvalCode (in /usr/bin/python3.11)
==5813== 
==5813== 1,104 bytes in 1 blocks are still reachable in loss record 91 of 174
==5813==    at 0x48407B4: malloc (vg_replace_malloc.c:381)
==5813==    by 0x500157: ??? (in /usr/bin/python3.11)
==5813==    by 0x508A47: ??? (in /usr/bin/python3.11)
==5813==    by 0x5F68E7: ??? (in /usr/bin/python3.11)
==5813==    by 0x56A493: PyObject_Call (in /usr/bin/python3.11)
==5813==    by 0x52F8A1: _PyEval_EvalFrameDefault (in /usr/bin/python3.11)
==5813==    by 0x5C4107: ??? (in /usr/bin/python3.11)
==5813==    by 0x5C3EFE: ??? (in /usr/bin/python3.11)
==5813==    by 0x52C359: _PyEval_EvalFrameDefault (in /usr/bin/python3.11)
==5813==    by 0x52360A: PyEval_EvalCode (in /usr/bin/python3.11)
==5813==    by 0x58EC4D: ??? (in /usr/bin/python3.11)
==5813==    by 0x53ACF6: ??? (in /usr/bin/python3.11)
==5813== 
==5813== 1,108 bytes in 15 blocks are still reachable in loss record 92 of 174
==5813==    at 0x48407B4: malloc (vg_replace_malloc.c:381)
==5813==    by 0x402369A: malloc (rtld-malloc.h:56)
==5813==    by 0x402369A: strdup (strdup.c:42)
==5813==    by 0x4007E6D: _dl_map_object (dl-load.c:2205)
==5813==    by 0x400B884: dl_open_worker_begin (dl-open.c:534)
==5813==    by 0x4AEBFC9: _dl_catch_exception (dl-error-skeleton.c:208)
==5813==    by 0x400B045: dl_open_worker (dl-open.c:782)
==5813==    by 0x4AEBFC9: _dl_catch_exception (dl-error-skeleton.c:208)
==5813==    by 0x400B437: _dl_open (dl-open.c:884)
==5813==    by 0x4A22437: dlopen_doit (dlopen.c:56)
==5813==    by 0x4AEBFC9: _dl_catch_exception (dl-error-skeleton.c:208)
==5813==    by 0x4AEC07E: _dl_catch_error (dl-error-skeleton.c:227)
==5813==    by 0x4A21F26: _dlerror_run (dlerror.c:138)
==5813== 
==5813== 1,108 bytes in 15 blocks are still reachable in loss record 93 of 174
==5813==    at 0x48407B4: malloc (vg_replace_malloc.c:381)
==5813==    by 0x400ADC8: malloc (rtld-malloc.h:56)
==5813==    by 0x400ADC8: _dl_new_object (dl-object.c:199)
==5813==    by 0x400651E: _dl_map_object_from_fd (dl-load.c:1063)
==5813==    by 0x4007EF4: _dl_map_object (dl-load.c:2272)
==5813==    by 0x400B884: dl_open_worker_begin (dl-open.c:534)
==5813==    by 0x4AEBFC9: _dl_catch_exception (dl-error-skeleton.c:208)
==5813==    by 0x400B045: dl_open_worker (dl-open.c:782)
==5813==    by 0x4AEBFC9: _dl_catch_exception (dl-error-skeleton.c:208)
==5813==    by 0x400B437: _dl_open (dl-open.c:884)
==5813==    by 0x4A22437: dlopen_doit (dlopen.c:56)
==5813==    by 0x4AEBFC9: _dl_catch_exception (dl-error-skeleton.c:208)
==5813==    by 0x4AEC07E: _dl_catch_error (dl-error-skeleton.c:227)
==5813== 
==5813== 1,120 bytes in 1 blocks are still reachable in loss record 94 of 174
==5813==    at 0x48407B4: malloc (vg_replace_malloc.c:381)
==5813==    by 0x50825A: PyType_GenericAlloc (in /usr/bin/python3.11)
==5813==    by 0x56A741: PyType_FromModuleAndSpec (in /usr/bin/python3.11)
==5813==    by 0x56AF0D: _PyStructSequence_NewType (in /usr/bin/python3.11)
==5813==    by 0x63C0EC: ??? (in /usr/bin/python3.11)
==5813==    by 0x55A93E: PyModule_ExecDef (in /usr/bin/python3.11)
==5813==    by 0x63BFCB: ??? (in /usr/bin/python3.11)
==5813==    by 0x5458A2: ??? (in /usr/bin/python3.11)
==5813==    by 0x5343AF: _PyEval_EvalFrameDefault (in /usr/bin/python3.11)
==5813==    by 0x55C930: _PyFunction_Vectorcall (in /usr/bin/python3.11)
==5813==    by 0x55BF93: ??? (in /usr/bin/python3.11)
==5813==    by 0x55B6FB: PyObject_CallMethod (in /usr/bin/python3.11)
==5813== 
==5813== 1,120 bytes in 1 blocks are still reachable in loss record 95 of 174
==5813==    at 0x48407B4: malloc (vg_replace_malloc.c:381)
==5813==    by 0x50825A: PyType_GenericAlloc (in /usr/bin/python3.11)
==5813==    by 0x56A741: PyType_FromModuleAndSpec (in /usr/bin/python3.11)
==5813==    by 0x66DB78: ??? (in /usr/bin/python3.11)
==5813==    by 0x55A93E: PyModule_ExecDef (in /usr/bin/python3.11)
==5813==    by 0x63BFCB: ??? (in /usr/bin/python3.11)
==5813==    by 0x5458A2: ??? (in /usr/bin/python3.11)
==5813==    by 0x5343AF: _PyEval_EvalFrameDefault (in /usr/bin/python3.11)
==5813==    by 0x55C930: _PyFunction_Vectorcall (in /usr/bin/python3.11)
==5813==    by 0x54618E: ??? (in /usr/bin/python3.11)
==5813==    by 0x58351A: PyObject_CallMethodObjArgs (in /usr/bin/python3.11)
==5813==    by 0x451A10: ??? (in /usr/bin/python3.11)
==5813== 
==5813== 1,120 bytes in 1 blocks are still reachable in loss record 96 of 174
==5813==    at 0x48407B4: malloc (vg_replace_malloc.c:381)
==5813==    by 0x50825A: PyType_GenericAlloc (in /usr/bin/python3.11)
==5813==    by 0x56A741: PyType_FromModuleAndSpec (in /usr/bin/python3.11)
==5813==    by 0x66DB94: ??? (in /usr/bin/python3.11)
==5813==    by 0x55A93E: PyModule_ExecDef (in /usr/bin/python3.11)
==5813==    by 0x63BFCB: ??? (in /usr/bin/python3.11)
==5813==    by 0x5458A2: ??? (in /usr/bin/python3.11)
==5813==    by 0x5343AF: _PyEval_EvalFrameDefault (in /usr/bin/python3.11)
==5813==    by 0x55C930: _PyFunction_Vectorcall (in /usr/bin/python3.11)
==5813==    by 0x54618E: ??? (in /usr/bin/python3.11)
==5813==    by 0x58351A: PyObject_CallMethodObjArgs (in /usr/bin/python3.11)
==5813==    by 0x451A10: ??? (in /usr/bin/python3.11)
==5813== 
==5813== 1,173 bytes in 1 blocks are still reachable in loss record 97 of 174
==5813==    at 0x48407B4: malloc (vg_replace_malloc.c:381)
==5813==    by 0x52AFA1: ??? (in /usr/bin/python3.11)
==5813==    by 0x524A93: ??? (in /usr/bin/python3.11)
==5813==    by 0x524BE9: ??? (in /usr/bin/python3.11)
==5813==    by 0x5246F6: ??? (in /usr/bin/python3.11)
==5813==    by 0x6336E3: ??? (in /usr/bin/python3.11)
==5813==    by 0x5B3297: ??? (in /usr/bin/python3.11)
==5813==    by 0x52C176: _PyEval_EvalFrameDefault (in /usr/bin/python3.11)
==5813==    by 0x55C930: _PyFunction_Vectorcall (in /usr/bin/python3.11)
==5813==    by 0x54618E: ??? (in /usr/bin/python3.11)
==5813==    by 0x58351A: PyObject_CallMethodObjArgs (in /usr/bin/python3.11)
==5813==    by 0x451A10: ??? (in /usr/bin/python3.11)
==5813== 
==5813== 1,177 bytes in 2 blocks are still reachable in loss record 98 of 174
==5813==    at 0x48407B4: malloc (vg_replace_malloc.c:381)
==5813==    by 0x4FBDF9: ??? (in /usr/bin/python3.11)
==5813==    by 0x543E9B: _PyObject_GenericGetAttrWithDict (in /usr/bin/python3.11)
==5813==    by 0x51E473: PyObject_GetAttr (in /usr/bin/python3.11)
==5813==    by 0x52BF94: _PyEval_EvalFrameDefault (in /usr/bin/python3.11)
==5813==    by 0x53B0E3: ??? (in /usr/bin/python3.11)
==5813==    by 0x53ACF6: ??? (in /usr/bin/python3.11)
==5813==    by 0x53AC2B: PyObject_Vectorcall (in /usr/bin/python3.11)
==5813==    by 0x52B93F: _PyEval_EvalFrameDefault (in /usr/bin/python3.11)
==5813==    by 0x52360A: PyEval_EvalCode (in /usr/bin/python3.11)
==5813==    by 0x58EC4D: ??? (in /usr/bin/python3.11)
==5813==    by 0x53ACF6: ??? (in /usr/bin/python3.11)
==5813== 
==5813== 1,200 bytes in 1 blocks are still reachable in loss record 99 of 174
==5813==    at 0x48407B4: malloc (vg_replace_malloc.c:381)
==5813==    by 0x50825A: PyType_GenericAlloc (in /usr/bin/python3.11)
==5813==    by 0x56A741: PyType_FromModuleAndSpec (in /usr/bin/python3.11)
==5813==    by 0x652470: ??? (in /usr/bin/python3.11)
==5813==    by 0x55A93E: PyModule_ExecDef (in /usr/bin/python3.11)
==5813==    by 0x63BFCB: ??? (in /usr/bin/python3.11)
==5813==    by 0x5458A2: ??? (in /usr/bin/python3.11)
==5813==    by 0x5343AF: _PyEval_EvalFrameDefault (in /usr/bin/python3.11)
==5813==    by 0x55C930: _PyFunction_Vectorcall (in /usr/bin/python3.11)
==5813==    by 0x54618E: ??? (in /usr/bin/python3.11)
==5813==    by 0x58351A: PyObject_CallMethodObjArgs (in /usr/bin/python3.11)
==5813==    by 0x451A10: ??? (in /usr/bin/python3.11)
==5813== 
==5813== 1,332 bytes in 2 blocks are still reachable in loss record 100 of 174
==5813==    at 0x48407B4: malloc (vg_replace_malloc.c:381)
==5813==    by 0x4FBDF9: ??? (in /usr/bin/python3.11)
==5813==    by 0x502CC6: ??? (in /usr/bin/python3.11)
==5813==    by 0x500F66: PyType_Ready (in /usr/bin/python3.11)
==5813==    by 0x56AD81: PyModule_AddType (in /usr/bin/python3.11)
==5813==    by 0x652131: ??? (in /usr/bin/python3.11)
==5813==    by 0x55A93E: PyModule_ExecDef (in /usr/bin/python3.11)
==5813==    by 0x63BFCB: ??? (in /usr/bin/python3.11)
==5813==    by 0x5458A2: ??? (in /usr/bin/python3.11)
==5813==    by 0x5343AF: _PyEval_EvalFrameDefault (in /usr/bin/python3.11)
==5813==    by 0x55C930: _PyFunction_Vectorcall (in /usr/bin/python3.11)
==5813==    by 0x54618E: ??? (in /usr/bin/python3.11)
==5813== 
==5813== 1,363 bytes in 2 blocks are still reachable in loss record 101 of 174
==5813==    at 0x48407B4: malloc (vg_replace_malloc.c:381)
==5813==    by 0x4FBDF9: ??? (in /usr/bin/python3.11)
==5813==    by 0x502CC6: ??? (in /usr/bin/python3.11)
==5813==    by 0x500F66: PyType_Ready (in /usr/bin/python3.11)
==5813==    by 0x4F9425: ??? (in /usr/bin/python3.11)
==5813==    by 0x628925: ??? (in /usr/bin/python3.11)
==5813==    by 0x62863A: Py_InitializeFromConfig (in /usr/bin/python3.11)
==5813==    by 0x6278E8: ??? (in /usr/bin/python3.11)
==5813==    by 0x62772F: ??? (in /usr/bin/python3.11)
==5813==    by 0x6275C6: Py_BytesMain (in /usr/bin/python3.11)
==5813==    by 0x49C4249: (below main) (libc_start_call_main.h:58)
==5813== 
==5813== 1,416 bytes in 1 blocks are still reachable in loss record 102 of 174
==5813==    at 0x48407B4: malloc (vg_replace_malloc.c:381)
==5813==    by 0x4FBDF9: ??? (in /usr/bin/python3.11)
==5813==    by 0x502CC6: ??? (in /usr/bin/python3.11)
==5813==    by 0x500F66: PyType_Ready (in /usr/bin/python3.11)
==5813==    by 0x56AD81: PyModule_AddType (in /usr/bin/python3.11)
==5813==    by 0x676F9B: PyInit__pickle (in /usr/bin/python3.11)
==5813==    by 0x440F0D: ??? (in /usr/bin/python3.11)
==5813==    by 0x56A6C8: ??? (in /usr/bin/python3.11)
==5813==    by 0x5458A2: ??? (in /usr/bin/python3.11)
==5813==    by 0x5343AF: _PyEval_EvalFrameDefault (in /usr/bin/python3.11)
==5813==    by 0x55C930: _PyFunction_Vectorcall (in /usr/bin/python3.11)
==5813==    by 0x54618E: ??? (in /usr/bin/python3.11)
==5813== 
==5813== 1,489 bytes in 1 blocks are still reachable in loss record 103 of 174
==5813==    at 0x48407B4: malloc (vg_replace_malloc.c:381)
==5813==    by 0x519E29: ??? (in /usr/bin/python3.11)
==5813==    by 0x517E15: _PyObject_MakeTpCall (in /usr/bin/python3.11)
==5813==    by 0x51F269: _PyObject_FastCallDictTstate (in /usr/bin/python3.11)
==5813==    by 0x53B1BB: ??? (in /usr/bin/python3.11)
==5813==    by 0x53ACF6: ??? (in /usr/bin/python3.11)
==5813==    by 0x53AC2B: PyObject_Vectorcall (in /usr/bin/python3.11)
==5813==    by 0x52B93F: _PyEval_EvalFrameDefault (in /usr/bin/python3.11)
==5813==    by 0x52360A: PyEval_EvalCode (in /usr/bin/python3.11)
==5813==    by 0x632C84: ??? (in /usr/bin/python3.11)
==5813==    by 0x6321EE: PyImport_ImportFrozenModuleObject (in /usr/bin/python3.11)
==5813==    by 0x6320BD: PyImport_ImportFrozenModule (in /usr/bin/python3.11)
==5813== 
==5813== 1,496 bytes in 1 blocks are still reachable in loss record 104 of 174
==5813==    at 0x48407B4: malloc (vg_replace_malloc.c:381)
==5813==    by 0x53A431: _PyCode_New (in /usr/bin/python3.11)
==5813==    by 0x524892: ??? (in /usr/bin/python3.11)
==5813==    by 0x524C31: ??? (in /usr/bin/python3.11)
==5813==    by 0x5246F6: ??? (in /usr/bin/python3.11)
==5813==    by 0x524D02: ??? (in /usr/bin/python3.11)
==5813==    by 0x5246F6: ??? (in /usr/bin/python3.11)
==5813==    by 0x6336E3: ??? (in /usr/bin/python3.11)
==5813==    by 0x5B3297: ??? (in /usr/bin/python3.11)
==5813==    by 0x52C176: _PyEval_EvalFrameDefault (in /usr/bin/python3.11)
==5813==    by 0x55C930: _PyFunction_Vectorcall (in /usr/bin/python3.11)
==5813==    by 0x54618E: ??? (in /usr/bin/python3.11)
==5813== 
==5813== 1,520 bytes in 1 blocks are still reachable in loss record 105 of 174
==5813==    at 0x48407B4: malloc (vg_replace_malloc.c:381)
==5813==    by 0x500157: ??? (in /usr/bin/python3.11)
==5813==    by 0x508A47: ??? (in /usr/bin/python3.11)
==5813==    by 0x52DD5D: _PyEval_EvalFrameDefault (in /usr/bin/python3.11)
==5813==    by 0x52360A: PyEval_EvalCode (in /usr/bin/python3.11)
==5813==    by 0x632C84: ??? (in /usr/bin/python3.11)
==5813==    by 0x6321EE: PyImport_ImportFrozenModuleObject (in /usr/bin/python3.11)
==5813==    by 0x6320BD: PyImport_ImportFrozenModule (in /usr/bin/python3.11)
==5813==    by 0x4FAA28: ??? (in /usr/bin/python3.11)
==5813==    by 0x628925: ??? (in /usr/bin/python3.11)
==5813==    by 0x62863A: Py_InitializeFromConfig (in /usr/bin/python3.11)
==5813==    by 0x6278E8: ??? (in /usr/bin/python3.11)
==5813== 
==5813== 1,520 bytes in 1 blocks are still reachable in loss record 106 of 174
==5813==    at 0x48407B4: malloc (vg_replace_malloc.c:381)
==5813==    by 0x500157: ??? (in /usr/bin/python3.11)
==5813==    by 0x508A47: ??? (in /usr/bin/python3.11)
==5813==    by 0x50E052: _PyObject_GenericSetAttrWithDict (in /usr/bin/python3.11)
==5813==    by 0x50D8CE: ??? (in /usr/bin/python3.11)
==5813==    by 0x559BD9: PyModule_FromDefAndSpec2 (in /usr/bin/python3.11)
==5813==    by 0x56A6C8: ??? (in /usr/bin/python3.11)
==5813==    by 0x5458A2: ??? (in /usr/bin/python3.11)
==5813==    by 0x5343AF: _PyEval_EvalFrameDefault (in /usr/bin/python3.11)
==5813==    by 0x55C930: _PyFunction_Vectorcall (in /usr/bin/python3.11)
==5813==    by 0x54618E: ??? (in /usr/bin/python3.11)
==5813==    by 0x58351A: PyObject_CallMethodObjArgs (in /usr/bin/python3.11)
==5813== 
==5813== 1,520 bytes in 1 blocks are still reachable in loss record 107 of 174
==5813==    at 0x48407B4: malloc (vg_replace_malloc.c:381)
==5813==    by 0x500157: ??? (in /usr/bin/python3.11)
==5813==    by 0x508A47: ??? (in /usr/bin/python3.11)
==5813==    by 0x502CE6: ??? (in /usr/bin/python3.11)
==5813==    by 0x500F66: PyType_Ready (in /usr/bin/python3.11)
==5813==    by 0x56AD81: PyModule_AddType (in /usr/bin/python3.11)
==5813==    by 0x652312: ??? (in /usr/bin/python3.11)
==5813==    by 0x55A93E: PyModule_ExecDef (in /usr/bin/python3.11)
==5813==    by 0x63BFCB: ??? (in /usr/bin/python3.11)
==5813==    by 0x5458A2: ??? (in /usr/bin/python3.11)
==5813==    by 0x5343AF: _PyEval_EvalFrameDefault (in /usr/bin/python3.11)
==5813==    by 0x55C930: _PyFunction_Vectorcall (in /usr/bin/python3.11)
==5813== 
==5813== 1,520 bytes in 1 blocks are still reachable in loss record 108 of 174
==5813==    at 0x48407B4: malloc (vg_replace_malloc.c:381)
==5813==    by 0x500157: ??? (in /usr/bin/python3.11)
==5813==    by 0x4FDADD: PyDict_SetDefault (in /usr/bin/python3.11)
==5813==    by 0x502EE4: ??? (in /usr/bin/python3.11)
==5813==    by 0x500F66: PyType_Ready (in /usr/bin/python3.11)
==5813==    by 0x597A919: PyInit__curses (in /usr/lib/python3.11/lib-dynload/_curses.cpython-311-x86_64-linux-gnu.so)
==5813==    by 0x6539FA: ??? (in /usr/bin/python3.11)
==5813==    by 0x54DDD7: ??? (in /usr/bin/python3.11)
==5813==    by 0x5343AF: _PyEval_EvalFrameDefault (in /usr/bin/python3.11)
==5813==    by 0x55C930: _PyFunction_Vectorcall (in /usr/bin/python3.11)
==5813==    by 0x54618E: ??? (in /usr/bin/python3.11)
==5813==    by 0x58351A: PyObject_CallMethodObjArgs (in /usr/bin/python3.11)
==5813== 
==5813== 1,520 bytes in 1 blocks are still reachable in loss record 109 of 174
==5813==    at 0x48407B4: malloc (vg_replace_malloc.c:381)
==5813==    by 0x500157: ??? (in /usr/bin/python3.11)
==5813==    by 0x4FDADD: PyDict_SetDefault (in /usr/bin/python3.11)
==5813==    by 0x502EE4: ??? (in /usr/bin/python3.11)
==5813==    by 0x500F66: PyType_Ready (in /usr/bin/python3.11)
==5813==    by 0x65A9D79: PyInit__decimal (in /usr/lib/python3.11/lib-dynload/_decimal.cpython-311-x86_64-linux-gnu.so)
==5813==    by 0x6539FA: ??? (in /usr/bin/python3.11)
==5813==    by 0x54DDD7: ??? (in /usr/bin/python3.11)
==5813==    by 0x5343AF: _PyEval_EvalFrameDefault (in /usr/bin/python3.11)
==5813==    by 0x55C930: _PyFunction_Vectorcall (in /usr/bin/python3.11)
==5813==    by 0x54618E: ??? (in /usr/bin/python3.11)
==5813==    by 0x58351A: PyObject_CallMethodObjArgs (in /usr/bin/python3.11)
==5813== 
==5813== 1,520 bytes in 1 blocks are still reachable in loss record 110 of 174
==5813==    at 0x48407B4: malloc (vg_replace_malloc.c:381)
==5813==    by 0x500157: ??? (in /usr/bin/python3.11)
==5813==    by 0x508A47: ??? (in /usr/bin/python3.11)
==5813==    by 0x55AF41: PyModule_AddObjectRef (in /usr/bin/python3.11)
==5813==    by 0x5B419D6: PyInit__ctypes (in /usr/lib/python3.11/lib-dynload/_ctypes.cpython-311-x86_64-linux-gnu.so)
==5813==    by 0x6539FA: ??? (in /usr/bin/python3.11)
==5813==    by 0x54DDD7: ??? (in /usr/bin/python3.11)
==5813==    by 0x5343AF: _PyEval_EvalFrameDefault (in /usr/bin/python3.11)
==5813==    by 0x55C930: _PyFunction_Vectorcall (in /usr/bin/python3.11)
==5813==    by 0x54618E: ??? (in /usr/bin/python3.11)
==5813==    by 0x58351A: PyObject_CallMethodObjArgs (in /usr/bin/python3.11)
==5813==    by 0x451A10: ??? (in /usr/bin/python3.11)
==5813== 
==5813== 1,536 bytes in 1 blocks are still reachable in loss record 111 of 174
==5813==    at 0x484582F: realloc (vg_replace_malloc.c:1437)
==5813==    by 0x4FB50C: ??? (in /usr/bin/python3.11)
==5813==    by 0x52AF69: ??? (in /usr/bin/python3.11)
==5813==    by 0x52440A: ??? (in /usr/bin/python3.11)
==5813==    by 0x524D02: ??? (in /usr/bin/python3.11)
==5813==    by 0x524C0D: ??? (in /usr/bin/python3.11)
==5813==    by 0x5246F6: ??? (in /usr/bin/python3.11)
==5813==    by 0x6336E3: ??? (in /usr/bin/python3.11)
==5813==    by 0x5B3297: ??? (in /usr/bin/python3.11)
==5813==    by 0x52C176: _PyEval_EvalFrameDefault (in /usr/bin/python3.11)
==5813==    by 0x55C930: _PyFunction_Vectorcall (in /usr/bin/python3.11)
==5813==    by 0x54618E: ??? (in /usr/bin/python3.11)
==5813== 
==5813== 1,536 bytes in 2 blocks are still reachable in loss record 112 of 174
==5813==    at 0x48407B4: malloc (vg_replace_malloc.c:381)
==5813==    by 0x500157: ??? (in /usr/bin/python3.11)
==5813==    by 0x4FDADD: PyDict_SetDefault (in /usr/bin/python3.11)
==5813==    by 0x501EDE: ??? (in /usr/bin/python3.11)
==5813==    by 0x500F66: PyType_Ready (in /usr/bin/python3.11)
==5813==    by 0x4F9425: ??? (in /usr/bin/python3.11)
==5813==    by 0x628925: ??? (in /usr/bin/python3.11)
==5813==    by 0x62863A: Py_InitializeFromConfig (in /usr/bin/python3.11)
==5813==    by 0x6278E8: ??? (in /usr/bin/python3.11)
==5813==    by 0x62772F: ??? (in /usr/bin/python3.11)
==5813==    by 0x6275C6: Py_BytesMain (in /usr/bin/python3.11)
==5813==    by 0x49C4249: (below main) (libc_start_call_main.h:58)
==5813== 
==5813== 1,536 bytes in 2 blocks are still reachable in loss record 113 of 174
==5813==    at 0x48407B4: malloc (vg_replace_malloc.c:381)
==5813==    by 0x4FEA8A: ??? (in /usr/bin/python3.11)
==5813==    by 0x502B3D: ??? (in /usr/bin/python3.11)
==5813==    by 0x518D23: ??? (in /usr/bin/python3.11)
==5813==    by 0x517E15: _PyObject_MakeTpCall (in /usr/bin/python3.11)
==5813==    by 0x51F269: _PyObject_FastCallDictTstate (in /usr/bin/python3.11)
==5813==    by 0x53B1BB: ??? (in /usr/bin/python3.11)
==5813==    by 0x53ACF6: ??? (in /usr/bin/python3.11)
==5813==    by 0x53AC2B: PyObject_Vectorcall (in /usr/bin/python3.11)
==5813==    by 0x52B93F: _PyEval_EvalFrameDefault (in /usr/bin/python3.11)
==5813==    by 0x52360A: PyEval_EvalCode (in /usr/bin/python3.11)
==5813==    by 0x632C84: ??? (in /usr/bin/python3.11)
==5813== 
==5813== 1,536 bytes in 2 blocks are still reachable in loss record 114 of 174
==5813==    at 0x48407B4: malloc (vg_replace_malloc.c:381)
==5813==    by 0x51729D: PyDict_Copy (in /usr/bin/python3.11)
==5813==    by 0x518517: ??? (in /usr/bin/python3.11)
==5813==    by 0x5B48BB: ??? (in /usr/bin/python3.11)
==5813==    by 0x547AC5: ??? (in /usr/bin/python3.11)
==5813==    by 0x56A493: PyObject_Call (in /usr/bin/python3.11)
==5813==    by 0x5343AF: _PyEval_EvalFrameDefault (in /usr/bin/python3.11)
==5813==    by 0x51F066: _PyObject_FastCallDictTstate (in /usr/bin/python3.11)
==5813==    by 0x5B443B: ??? (in /usr/bin/python3.11)
==5813==    by 0x517E15: _PyObject_MakeTpCall (in /usr/bin/python3.11)
==5813==    by 0x53B1BB: ??? (in /usr/bin/python3.11)
==5813==    by 0x53ACF6: ??? (in /usr/bin/python3.11)
==5813== 
==5813== 1,536 bytes in 2 blocks are still reachable in loss record 115 of 174
==5813==    at 0x48407B4: malloc (vg_replace_malloc.c:381)
==5813==    by 0x4FEA8A: ??? (in /usr/bin/python3.11)
==5813==    by 0x502B3D: ??? (in /usr/bin/python3.11)
==5813==    by 0x518D23: ??? (in /usr/bin/python3.11)
==5813==    by 0x5B3D557: ??? (in /usr/lib/python3.11/lib-dynload/_ctypes.cpython-311-x86_64-linux-gnu.so)
==5813==    by 0x517E15: _PyObject_MakeTpCall (in /usr/bin/python3.11)
==5813==    by 0x53B1BB: ??? (in /usr/bin/python3.11)
==5813==    by 0x53ACF6: ??? (in /usr/bin/python3.11)
==5813==    by 0x53AC2B: PyObject_Vectorcall (in /usr/bin/python3.11)
==5813==    by 0x52B93F: _PyEval_EvalFrameDefault (in /usr/bin/python3.11)
==5813==    by 0x52360A: PyEval_EvalCode (in /usr/bin/python3.11)
==5813==    by 0x58EC4D: ??? (in /usr/bin/python3.11)
==5813== 
==5813== 1,536 bytes in 2 blocks are still reachable in loss record 116 of 174
==5813==    at 0x48407B4: malloc (vg_replace_malloc.c:381)
==5813==    by 0x4FEA8A: ??? (in /usr/bin/python3.11)
==5813==    by 0x502B3D: ??? (in /usr/bin/python3.11)
==5813==    by 0x518D23: ??? (in /usr/bin/python3.11)
==5813==    by 0x5B48BB: ??? (in /usr/bin/python3.11)
==5813==    by 0x547AC5: ??? (in /usr/bin/python3.11)
==5813==    by 0x517EB2: _PyObject_MakeTpCall (in /usr/bin/python3.11)
==5813==    by 0x52B93F: _PyEval_EvalFrameDefault (in /usr/bin/python3.11)
==5813==    by 0x52360A: PyEval_EvalCode (in /usr/bin/python3.11)
==5813==    by 0x58EC4D: ??? (in /usr/bin/python3.11)
==5813==    by 0x53ACF6: ??? (in /usr/bin/python3.11)
==5813==    by 0x5343AF: _PyEval_EvalFrameDefault (in /usr/bin/python3.11)
==5813== 
==5813== 1,664 bytes in 1 blocks are still reachable in loss record 117 of 174
==5813==    at 0x48407B4: malloc (vg_replace_malloc.c:381)
==5813==    by 0x5A03F1A: _nc_read_termtype (in /usr/lib/x86_64-linux-gnu/libtinfo.so.6.4)
==5813==    by 0x5A04B1A: _nc_read_file_entry (in /usr/lib/x86_64-linux-gnu/libtinfo.so.6.4)
==5813==    by 0x5A04E7C: ??? (in /usr/lib/x86_64-linux-gnu/libtinfo.so.6.4)
==5813==    by 0x5A04FCB: _nc_read_entry2 (in /usr/lib/x86_64-linux-gnu/libtinfo.so.6.4)
==5813==    by 0x59FC018: ??? (in /usr/lib/x86_64-linux-gnu/libtinfo.so.6.4)
==5813==    by 0x59FC3D5: _nc_setupterm (in /usr/lib/x86_64-linux-gnu/libtinfo.so.6.4)
==5813==    by 0x5978983: ??? (in /usr/lib/python3.11/lib-dynload/_curses.cpython-311-x86_64-linux-gnu.so)
==5813==    by 0x53ACF6: ??? (in /usr/bin/python3.11)
==5813==    by 0x53AC2B: PyObject_Vectorcall (in /usr/bin/python3.11)
==5813==    by 0x52B93F: _PyEval_EvalFrameDefault (in /usr/bin/python3.11)
==5813==    by 0x51F066: _PyObject_FastCallDictTstate (in /usr/bin/python3.11)
==5813== 
==5813== 1,816 bytes in 2 blocks are still reachable in loss record 118 of 174
==5813==    at 0x48407B4: malloc (vg_replace_malloc.c:381)
==5813==    by 0x53A431: _PyCode_New (in /usr/bin/python3.11)
==5813==    by 0x524892: ??? (in /usr/bin/python3.11)
==5813==    by 0x524C79: ??? (in /usr/bin/python3.11)
==5813==    by 0x5246F6: ??? (in /usr/bin/python3.11)
==5813==    by 0x524D02: ??? (in /usr/bin/python3.11)
==5813==    by 0x5246F6: ??? (in /usr/bin/python3.11)
==5813==    by 0x6336E3: ??? (in /usr/bin/python3.11)
==5813==    by 0x5B3297: ??? (in /usr/bin/python3.11)
==5813==    by 0x52C176: _PyEval_EvalFrameDefault (in /usr/bin/python3.11)
==5813==    by 0x55C930: _PyFunction_Vectorcall (in /usr/bin/python3.11)
==5813==    by 0x54618E: ??? (in /usr/bin/python3.11)
==5813== 
==5813== 1,920 bytes in 2 blocks are still reachable in loss record 119 of 174
==5813==    at 0x48407B4: malloc (vg_replace_malloc.c:381)
==5813==    by 0x50825A: PyType_GenericAlloc (in /usr/bin/python3.11)
==5813==    by 0x5185D1: ??? (in /usr/bin/python3.11)
==5813==    by 0x517E15: _PyObject_MakeTpCall (in /usr/bin/python3.11)
==5813==    by 0x51F269: _PyObject_FastCallDictTstate (in /usr/bin/python3.11)
==5813==    by 0x53B1BB: ??? (in /usr/bin/python3.11)
==5813==    by 0x53ACF6: ??? (in /usr/bin/python3.11)
==5813==    by 0x53AC2B: PyObject_Vectorcall (in /usr/bin/python3.11)
==5813==    by 0x52B93F: _PyEval_EvalFrameDefault (in /usr/bin/python3.11)
==5813==    by 0x52360A: PyEval_EvalCode (in /usr/bin/python3.11)
==5813==    by 0x632C84: ??? (in /usr/bin/python3.11)
==5813==    by 0x6321EE: PyImport_ImportFrozenModuleObject (in /usr/bin/python3.11)
==5813== 
==5813== 1,920 bytes in 2 blocks are still reachable in loss record 120 of 174
==5813==    at 0x48407B4: malloc (vg_replace_malloc.c:381)
==5813==    by 0x50825A: PyType_GenericAlloc (in /usr/bin/python3.11)
==5813==    by 0x5185D1: ??? (in /usr/bin/python3.11)
==5813==    by 0x5B3D557: ??? (in /usr/lib/python3.11/lib-dynload/_ctypes.cpython-311-x86_64-linux-gnu.so)
==5813==    by 0x517E15: _PyObject_MakeTpCall (in /usr/bin/python3.11)
==5813==    by 0x53B1BB: ??? (in /usr/bin/python3.11)
==5813==    by 0x53ACF6: ??? (in /usr/bin/python3.11)
==5813==    by 0x53AC2B: PyObject_Vectorcall (in /usr/bin/python3.11)
==5813==    by 0x52B93F: _PyEval_EvalFrameDefault (in /usr/bin/python3.11)
==5813==    by 0x52360A: PyEval_EvalCode (in /usr/bin/python3.11)
==5813==    by 0x58EC4D: ??? (in /usr/bin/python3.11)
==5813==    by 0x53ACF6: ??? (in /usr/bin/python3.11)
==5813== 
==5813== 1,920 bytes in 2 blocks are still reachable in loss record 121 of 174
==5813==    at 0x48407B4: malloc (vg_replace_malloc.c:381)
==5813==    by 0x50825A: PyType_GenericAlloc (in /usr/bin/python3.11)
==5813==    by 0x5185D1: ??? (in /usr/bin/python3.11)
==5813==    by 0x5B48BB: ??? (in /usr/bin/python3.11)
==5813==    by 0x547AC5: ??? (in /usr/bin/python3.11)
==5813==    by 0x517EB2: _PyObject_MakeTpCall (in /usr/bin/python3.11)
==5813==    by 0x52B93F: _PyEval_EvalFrameDefault (in /usr/bin/python3.11)
==5813==    by 0x52360A: PyEval_EvalCode (in /usr/bin/python3.11)
==5813==    by 0x58EC4D: ??? (in /usr/bin/python3.11)
==5813==    by 0x53ACF6: ??? (in /usr/bin/python3.11)
==5813==    by 0x5343AF: _PyEval_EvalFrameDefault (in /usr/bin/python3.11)
==5813==    by 0x55C930: _PyFunction_Vectorcall (in /usr/bin/python3.11)
==5813== 
==5813== 2,048 bytes in 1 blocks are still reachable in loss record 122 of 174
==5813==    at 0x48407B4: malloc (vg_replace_malloc.c:381)
==5813==    by 0x5147B0: ??? (in /usr/bin/python3.11)
==5813==    by 0x5136F8: ??? (in /usr/bin/python3.11)
==5813==    by 0x5A9F9C: ??? (in /usr/bin/python3.11)
==5813==    by 0x53AC2B: PyObject_Vectorcall (in /usr/bin/python3.11)
==5813==    by 0x52B93F: _PyEval_EvalFrameDefault (in /usr/bin/python3.11)
==5813==    by 0x53B0E3: ??? (in /usr/bin/python3.11)
==5813==    by 0x53ACF6: ??? (in /usr/bin/python3.11)
==5813==    by 0x53AC2B: PyObject_Vectorcall (in /usr/bin/python3.11)
==5813==    by 0x52B93F: _PyEval_EvalFrameDefault (in /usr/bin/python3.11)
==5813==    by 0x52360A: PyEval_EvalCode (in /usr/bin/python3.11)
==5813==    by 0x58EC4D: ??? (in /usr/bin/python3.11)
==5813== 
==5813== 2,128 bytes in 3 blocks are still reachable in loss record 123 of 174
==5813==    at 0x48407B4: malloc (vg_replace_malloc.c:381)
==5813==    by 0x53A431: _PyCode_New (in /usr/bin/python3.11)
==5813==    by 0x524892: ??? (in /usr/bin/python3.11)
==5813==    by 0x524C0D: ??? (in /usr/bin/python3.11)
==5813==    by 0x5246F6: ??? (in /usr/bin/python3.11)
==5813==    by 0x524D02: ??? (in /usr/bin/python3.11)
==5813==    by 0x5246F6: ??? (in /usr/bin/python3.11)
==5813==    by 0x6336E3: ??? (in /usr/bin/python3.11)
==5813==    by 0x5B3297: ??? (in /usr/bin/python3.11)
==5813==    by 0x52C176: _PyEval_EvalFrameDefault (in /usr/bin/python3.11)
==5813==    by 0x55C930: _PyFunction_Vectorcall (in /usr/bin/python3.11)
==5813==    by 0x54618E: ??? (in /usr/bin/python3.11)
==5813== 
==5813== 2,181 bytes in 1 blocks are still reachable in loss record 124 of 174
==5813==    at 0x48407B4: malloc (vg_replace_malloc.c:381)
==5813==    by 0x4FBDF9: ??? (in /usr/bin/python3.11)
==5813==    by 0x502CC6: ??? (in /usr/bin/python3.11)
==5813==    by 0x500F66: PyType_Ready (in /usr/bin/python3.11)
==5813==    by 0x51C5FB: ??? (in /usr/bin/python3.11)
==5813==    by 0x5184FE: ??? (in /usr/bin/python3.11)
==5813==    by 0x517E15: _PyObject_MakeTpCall (in /usr/bin/python3.11)
==5813==    by 0x51F269: _PyObject_FastCallDictTstate (in /usr/bin/python3.11)
==5813==    by 0x53B1BB: ??? (in /usr/bin/python3.11)
==5813==    by 0x53ACF6: ??? (in /usr/bin/python3.11)
==5813==    by 0x53AC2B: PyObject_Vectorcall (in /usr/bin/python3.11)
==5813==    by 0x52B93F: _PyEval_EvalFrameDefault (in /usr/bin/python3.11)
==5813== 
==5813== 2,200 bytes in 1 blocks are still reachable in loss record 125 of 174
==5813==    at 0x48407B4: malloc (vg_replace_malloc.c:381)
==5813==    by 0x500157: ??? (in /usr/bin/python3.11)
==5813==    by 0x508A47: ??? (in /usr/bin/python3.11)
==5813==    by 0x501D1F: ??? (in /usr/bin/python3.11)
==5813==    by 0x518D23: ??? (in /usr/bin/python3.11)
==5813==    by 0x517E15: _PyObject_MakeTpCall (in /usr/bin/python3.11)
==5813==    by 0x5125C2: PyObject_CallFunction (in /usr/bin/python3.11)
==5813==    by 0x631A49: PyErr_NewException (in /usr/bin/python3.11)
==5813==    by 0x676FDF: PyInit__pickle (in /usr/bin/python3.11)
==5813==    by 0x440F0D: ??? (in /usr/bin/python3.11)
==5813==    by 0x56A6C8: ??? (in /usr/bin/python3.11)
==5813==    by 0x5458A2: ??? (in /usr/bin/python3.11)
==5813== 
==5813== 2,200 bytes in 1 blocks are still reachable in loss record 126 of 174
==5813==    at 0x48407B4: malloc (vg_replace_malloc.c:381)
==5813==    by 0x500157: ??? (in /usr/bin/python3.11)
==5813==    by 0x508A47: ??? (in /usr/bin/python3.11)
==5813==    by 0x501D1F: ??? (in /usr/bin/python3.11)
==5813==    by 0x518D23: ??? (in /usr/bin/python3.11)
==5813==    by 0x5B3E9A9: ??? (in /usr/lib/python3.11/lib-dynload/_ctypes.cpython-311-x86_64-linux-gnu.so)
==5813==    by 0x517E15: _PyObject_MakeTpCall (in /usr/bin/python3.11)
==5813==    by 0x53B1BB: ??? (in /usr/bin/python3.11)
==5813==    by 0x53ACF6: ??? (in /usr/bin/python3.11)
==5813==    by 0x53AC2B: PyObject_Vectorcall (in /usr/bin/python3.11)
==5813==    by 0x52B93F: _PyEval_EvalFrameDefault (in /usr/bin/python3.11)
==5813==    by 0x52360A: PyEval_EvalCode (in /usr/bin/python3.11)
==5813== 
==5813== 2,246 bytes in 1 blocks are still reachable in loss record 127 of 174
==5813==    at 0x48407B4: malloc (vg_replace_malloc.c:381)
==5813==    by 0x59F72E8: ??? (in /usr/lib/x86_64-linux-gnu/libtinfo.so.6.4)
==5813==    by 0x59FC404: _nc_setupterm (in /usr/lib/x86_64-linux-gnu/libtinfo.so.6.4)
==5813==    by 0x5978983: ??? (in /usr/lib/python3.11/lib-dynload/_curses.cpython-311-x86_64-linux-gnu.so)
==5813==    by 0x53ACF6: ??? (in /usr/bin/python3.11)
==5813==    by 0x53AC2B: PyObject_Vectorcall (in /usr/bin/python3.11)
==5813==    by 0x52B93F: _PyEval_EvalFrameDefault (in /usr/bin/python3.11)
==5813==    by 0x51F066: _PyObject_FastCallDictTstate (in /usr/bin/python3.11)
==5813==    by 0x565972: ??? (in /usr/bin/python3.11)
==5813==    by 0x517E54: _PyObject_MakeTpCall (in /usr/bin/python3.11)
==5813==    by 0x52B93F: _PyEval_EvalFrameDefault (in /usr/bin/python3.11)
==5813==    by 0x52360A: PyEval_EvalCode (in /usr/bin/python3.11)
==5813== 
==5813== 2,288 bytes in 2 blocks are still reachable in loss record 128 of 174
==5813==    at 0x48407B4: malloc (vg_replace_malloc.c:381)
==5813==    by 0x500157: ??? (in /usr/bin/python3.11)
==5813==    by 0x4FDADD: PyDict_SetDefault (in /usr/bin/python3.11)
==5813==    by 0x502968: ??? (in /usr/bin/python3.11)
==5813==    by 0x500F66: PyType_Ready (in /usr/bin/python3.11)
==5813==    by 0x56AD81: PyModule_AddType (in /usr/bin/python3.11)
==5813==    by 0x475DD2: PyInit__datetime (in /usr/bin/python3.11)
==5813==    by 0x440F0D: ??? (in /usr/bin/python3.11)
==5813==    by 0x56A6C8: ??? (in /usr/bin/python3.11)
==5813==    by 0x5458A2: ??? (in /usr/bin/python3.11)
==5813==    by 0x5343AF: _PyEval_EvalFrameDefault (in /usr/bin/python3.11)
==5813==    by 0x55C930: _PyFunction_Vectorcall (in /usr/bin/python3.11)
==5813== 
==5813== 2,304 bytes in 3 blocks are still reachable in loss record 129 of 174
==5813==    at 0x48407B4: malloc (vg_replace_malloc.c:381)
==5813==    by 0x500157: ??? (in /usr/bin/python3.11)
==5813==    by 0x508A47: ??? (in /usr/bin/python3.11)
==5813==    by 0x5B7619: ??? (in /usr/bin/python3.11)
==5813==    by 0x50E60A: _PyObject_GenericSetAttrWithDict (in /usr/bin/python3.11)
==5813==    by 0x58E86D: ??? (in /usr/bin/python3.11)
==5813==    by 0x50DE4A: PyObject_SetAttr (in /usr/bin/python3.11)
==5813==    by 0x5B5314: ??? (in /usr/bin/python3.11)
==5813==    by 0x52C176: _PyEval_EvalFrameDefault (in /usr/bin/python3.11)
==5813==    by 0x51F066: _PyObject_FastCallDictTstate (in /usr/bin/python3.11)
==5813==    by 0x5B443B: ??? (in /usr/bin/python3.11)
==5813==    by 0x517E15: _PyObject_MakeTpCall (in /usr/bin/python3.11)
==5813== 
==5813== 2,304 bytes in 3 blocks are still reachable in loss record 130 of 174
==5813==    at 0x48407B4: malloc (vg_replace_malloc.c:381)
==5813==    by 0x4FEA8A: ??? (in /usr/bin/python3.11)
==5813==    by 0x502B3D: ??? (in /usr/bin/python3.11)
==5813==    by 0x518D23: ??? (in /usr/bin/python3.11)
==5813==    by 0x5B3F0F0: ??? (in /usr/lib/python3.11/lib-dynload/_ctypes.cpython-311-x86_64-linux-gnu.so)
==5813==    by 0x517E15: _PyObject_MakeTpCall (in /usr/bin/python3.11)
==5813==    by 0x5126A4: PyObject_CallFunction (in /usr/bin/python3.11)
==5813==    by 0x5B3ED58: ??? (in /usr/lib/python3.11/lib-dynload/_ctypes.cpython-311-x86_64-linux-gnu.so)
==5813==    by 0x5458A2: ??? (in /usr/bin/python3.11)
==5813==    by 0x53AC2B: PyObject_Vectorcall (in /usr/bin/python3.11)
==5813==    by 0x52B93F: _PyEval_EvalFrameDefault (in /usr/bin/python3.11)
==5813==    by 0x52360A: PyEval_EvalCode (in /usr/bin/python3.11)
==5813== 
==5813== 2,304 bytes in 3 blocks are still reachable in loss record 131 of 174
==5813==    at 0x48407B4: malloc (vg_replace_malloc.c:381)
==5813==    by 0x4FEA8A: ??? (in /usr/bin/python3.11)
==5813==    by 0x502B3D: ??? (in /usr/bin/python3.11)
==5813==    by 0x518D23: ??? (in /usr/bin/python3.11)
==5813==    by 0x5B3E9A9: ??? (in /usr/lib/python3.11/lib-dynload/_ctypes.cpython-311-x86_64-linux-gnu.so)
==5813==    by 0x517E15: _PyObject_MakeTpCall (in /usr/bin/python3.11)
==5813==    by 0x53B1BB: ??? (in /usr/bin/python3.11)
==5813==    by 0x53ACF6: ??? (in /usr/bin/python3.11)
==5813==    by 0x53AC2B: PyObject_Vectorcall (in /usr/bin/python3.11)
==5813==    by 0x52B93F: _PyEval_EvalFrameDefault (in /usr/bin/python3.11)
==5813==    by 0x52360A: PyEval_EvalCode (in /usr/bin/python3.11)
==5813==    by 0x58EC4D: ??? (in /usr/bin/python3.11)
==5813== 
==5813== 2,304 bytes in 3 blocks are still reachable in loss record 132 of 174
==5813==    at 0x48407B4: malloc (vg_replace_malloc.c:381)
==5813==    by 0x4FEA8A: ??? (in /usr/bin/python3.11)
==5813==    by 0x502B3D: ??? (in /usr/bin/python3.11)
==5813==    by 0x518D23: ??? (in /usr/bin/python3.11)
==5813==    by 0x517E15: _PyObject_MakeTpCall (in /usr/bin/python3.11)
==5813==    by 0x53B1BB: ??? (in /usr/bin/python3.11)
==5813==    by 0x53ACF6: ??? (in /usr/bin/python3.11)
==5813==    by 0x53AC2B: PyObject_Vectorcall (in /usr/bin/python3.11)
==5813==    by 0x52B93F: _PyEval_EvalFrameDefault (in /usr/bin/python3.11)
==5813==    by 0x52360A: PyEval_EvalCode (in /usr/bin/python3.11)
==5813==    by 0x58EC4D: ??? (in /usr/bin/python3.11)
==5813==    by 0x53ACF6: ??? (in /usr/bin/python3.11)
==5813== 
==5813== 2,320 bytes in 2 blocks are still reachable in loss record 133 of 174
==5813==    at 0x48407B4: malloc (vg_replace_malloc.c:381)
==5813==    by 0x50825A: PyType_GenericAlloc (in /usr/bin/python3.11)
==5813==    by 0x51968E: ??? (in /usr/bin/python3.11)
==5813==    by 0x517E15: _PyObject_MakeTpCall (in /usr/bin/python3.11)
==5813==    by 0x51F185: _PyObject_FastCallDictTstate (in /usr/bin/python3.11)
==5813==    by 0x53B1BB: ??? (in /usr/bin/python3.11)
==5813==    by 0x53ACF6: ??? (in /usr/bin/python3.11)
==5813==    by 0x53AC2B: PyObject_Vectorcall (in /usr/bin/python3.11)
==5813==    by 0x52B93F: _PyEval_EvalFrameDefault (in /usr/bin/python3.11)
==5813==    by 0x52360A: PyEval_EvalCode (in /usr/bin/python3.11)
==5813==    by 0x58EC4D: ??? (in /usr/bin/python3.11)
==5813==    by 0x53ACF6: ??? (in /usr/bin/python3.11)
==5813== 
==5813== 2,688 bytes in 4 blocks are still reachable in loss record 134 of 174
==5813==    at 0x48407B4: malloc (vg_replace_malloc.c:381)
==5813==    by 0x53A431: _PyCode_New (in /usr/bin/python3.11)
==5813==    by 0x524892: ??? (in /usr/bin/python3.11)
==5813==    by 0x524C9D: ??? (in /usr/bin/python3.11)
==5813==    by 0x5246F6: ??? (in /usr/bin/python3.11)
==5813==    by 0x524D02: ??? (in /usr/bin/python3.11)
==5813==    by 0x5246F6: ??? (in /usr/bin/python3.11)
==5813==    by 0x6336E3: ??? (in /usr/bin/python3.11)
==5813==    by 0x5B3297: ??? (in /usr/bin/python3.11)
==5813==    by 0x52C176: _PyEval_EvalFrameDefault (in /usr/bin/python3.11)
==5813==    by 0x55C930: _PyFunction_Vectorcall (in /usr/bin/python3.11)
==5813==    by 0x54618E: ??? (in /usr/bin/python3.11)
==5813== 
==5813== 2,880 bytes in 3 blocks are still reachable in loss record 135 of 174
==5813==    at 0x48407B4: malloc (vg_replace_malloc.c:381)
==5813==    by 0x50825A: PyType_GenericAlloc (in /usr/bin/python3.11)
==5813==    by 0x5185D1: ??? (in /usr/bin/python3.11)
==5813==    by 0x5B3F0F0: ??? (in /usr/lib/python3.11/lib-dynload/_ctypes.cpython-311-x86_64-linux-gnu.so)
==5813==    by 0x517E15: _PyObject_MakeTpCall (in /usr/bin/python3.11)
==5813==    by 0x5126A4: PyObject_CallFunction (in /usr/bin/python3.11)
==5813==    by 0x5B3ED58: ??? (in /usr/lib/python3.11/lib-dynload/_ctypes.cpython-311-x86_64-linux-gnu.so)
==5813==    by 0x5458A2: ??? (in /usr/bin/python3.11)
==5813==    by 0x53AC2B: PyObject_Vectorcall (in /usr/bin/python3.11)
==5813==    by 0x52B93F: _PyEval_EvalFrameDefault (in /usr/bin/python3.11)
==5813==    by 0x52360A: PyEval_EvalCode (in /usr/bin/python3.11)
==5813==    by 0x58EC4D: ??? (in /usr/bin/python3.11)
==5813== 
==5813== 2,880 bytes in 3 blocks are still reachable in loss record 136 of 174
==5813==    at 0x48407B4: malloc (vg_replace_malloc.c:381)
==5813==    by 0x50825A: PyType_GenericAlloc (in /usr/bin/python3.11)
==5813==    by 0x5185D1: ??? (in /usr/bin/python3.11)
==5813==    by 0x5B3E9A9: ??? (in /usr/lib/python3.11/lib-dynload/_ctypes.cpython-311-x86_64-linux-gnu.so)
==5813==    by 0x517E15: _PyObject_MakeTpCall (in /usr/bin/python3.11)
==5813==    by 0x53B1BB: ??? (in /usr/bin/python3.11)
==5813==    by 0x53ACF6: ??? (in /usr/bin/python3.11)
==5813==    by 0x53AC2B: PyObject_Vectorcall (in /usr/bin/python3.11)
==5813==    by 0x52B93F: _PyEval_EvalFrameDefault (in /usr/bin/python3.11)
==5813==    by 0x52360A: PyEval_EvalCode (in /usr/bin/python3.11)
==5813==    by 0x58EC4D: ??? (in /usr/bin/python3.11)
==5813==    by 0x53ACF6: ??? (in /usr/bin/python3.11)
==5813== 
==5813== 2,880 bytes in 3 blocks are still reachable in loss record 137 of 174
==5813==    at 0x48407B4: malloc (vg_replace_malloc.c:381)
==5813==    by 0x50825A: PyType_GenericAlloc (in /usr/bin/python3.11)
==5813==    by 0x5185D1: ??? (in /usr/bin/python3.11)
==5813==    by 0x517E15: _PyObject_MakeTpCall (in /usr/bin/python3.11)
==5813==    by 0x53B1BB: ??? (in /usr/bin/python3.11)
==5813==    by 0x53ACF6: ??? (in /usr/bin/python3.11)
==5813==    by 0x53AC2B: PyObject_Vectorcall (in /usr/bin/python3.11)
==5813==    by 0x52B93F: _PyEval_EvalFrameDefault (in /usr/bin/python3.11)
==5813==    by 0x52360A: PyEval_EvalCode (in /usr/bin/python3.11)
==5813==    by 0x58EC4D: ??? (in /usr/bin/python3.11)
==5813==    by 0x53ACF6: ??? (in /usr/bin/python3.11)
==5813==    by 0x5343AF: _PyEval_EvalFrameDefault (in /usr/bin/python3.11)
==5813== 
==5813== 3,056 bytes in 3 blocks are still reachable in loss record 138 of 174
==5813==    at 0x48407B4: malloc (vg_replace_malloc.c:381)
==5813==    by 0x500157: ??? (in /usr/bin/python3.11)
==5813==    by 0x4FDADD: PyDict_SetDefault (in /usr/bin/python3.11)
==5813==    by 0x502EE4: ??? (in /usr/bin/python3.11)
==5813==    by 0x500F66: PyType_Ready (in /usr/bin/python3.11)
==5813==    by 0x4F9425: ??? (in /usr/bin/python3.11)
==5813==    by 0x628925: ??? (in /usr/bin/python3.11)
==5813==    by 0x62863A: Py_InitializeFromConfig (in /usr/bin/python3.11)
==5813==    by 0x6278E8: ??? (in /usr/bin/python3.11)
==5813==    by 0x62772F: ??? (in /usr/bin/python3.11)
==5813==    by 0x6275C6: Py_BytesMain (in /usr/bin/python3.11)
==5813==    by 0x49C4249: (below main) (libc_start_call_main.h:58)
==5813== 
==5813== 3,072 bytes in 4 blocks are still reachable in loss record 139 of 174
==5813==    at 0x48407B4: malloc (vg_replace_malloc.c:381)
==5813==    by 0x4FEA8A: ??? (in /usr/bin/python3.11)
==5813==    by 0x502B3D: ??? (in /usr/bin/python3.11)
==5813==    by 0x518D23: ??? (in /usr/bin/python3.11)
==5813==    by 0x5B48BB: ??? (in /usr/bin/python3.11)
==5813==    by 0x547AC5: ??? (in /usr/bin/python3.11)
==5813==    by 0x56A493: PyObject_Call (in /usr/bin/python3.11)
==5813==    by 0x5343AF: _PyEval_EvalFrameDefault (in /usr/bin/python3.11)
==5813==    by 0x51F066: _PyObject_FastCallDictTstate (in /usr/bin/python3.11)
==5813==    by 0x5B443B: ??? (in /usr/bin/python3.11)
==5813==    by 0x517E15: _PyObject_MakeTpCall (in /usr/bin/python3.11)
==5813==    by 0x53B1BB: ??? (in /usr/bin/python3.11)
==5813== 
==5813== 3,264 bytes in 1 blocks are still reachable in loss record 140 of 174
==5813==    at 0x48407B4: malloc (vg_replace_malloc.c:381)
==5813==    by 0x500157: ??? (in /usr/bin/python3.11)
==5813==    by 0x4FDADD: PyDict_SetDefault (in /usr/bin/python3.11)
==5813==    by 0x502EE4: ??? (in /usr/bin/python3.11)
==5813==    by 0x500F66: PyType_Ready (in /usr/bin/python3.11)
==5813==    by 0x65A9D69: PyInit__decimal (in /usr/lib/python3.11/lib-dynload/_decimal.cpython-311-x86_64-linux-gnu.so)
==5813==    by 0x6539FA: ??? (in /usr/bin/python3.11)
==5813==    by 0x54DDD7: ??? (in /usr/bin/python3.11)
==5813==    by 0x5343AF: _PyEval_EvalFrameDefault (in /usr/bin/python3.11)
==5813==    by 0x55C930: _PyFunction_Vectorcall (in /usr/bin/python3.11)
==5813==    by 0x54618E: ??? (in /usr/bin/python3.11)
==5813==    by 0x58351A: PyObject_CallMethodObjArgs (in /usr/bin/python3.11)
==5813== 
==5813== 3,796 bytes in 3 blocks are still reachable in loss record 141 of 174
==5813==    at 0x48407B4: malloc (vg_replace_malloc.c:381)
==5813==    by 0x519E29: ??? (in /usr/bin/python3.11)
==5813==    by 0x517E15: _PyObject_MakeTpCall (in /usr/bin/python3.11)
==5813==    by 0x51F185: _PyObject_FastCallDictTstate (in /usr/bin/python3.11)
==5813==    by 0x53B1BB: ??? (in /usr/bin/python3.11)
==5813==    by 0x53ACF6: ??? (in /usr/bin/python3.11)
==5813==    by 0x53AC2B: PyObject_Vectorcall (in /usr/bin/python3.11)
==5813==    by 0x52B93F: _PyEval_EvalFrameDefault (in /usr/bin/python3.11)
==5813==    by 0x52360A: PyEval_EvalCode (in /usr/bin/python3.11)
==5813==    by 0x58EC4D: ??? (in /usr/bin/python3.11)
==5813==    by 0x53ACF6: ??? (in /usr/bin/python3.11)
==5813==    by 0x5343AF: _PyEval_EvalFrameDefault (in /usr/bin/python3.11)
==5813== 
==5813== 3,840 bytes in 4 blocks are still reachable in loss record 142 of 174
==5813==    at 0x48407B4: malloc (vg_replace_malloc.c:381)
==5813==    by 0x50825A: PyType_GenericAlloc (in /usr/bin/python3.11)
==5813==    by 0x5185D1: ??? (in /usr/bin/python3.11)
==5813==    by 0x5B48BB: ??? (in /usr/bin/python3.11)
==5813==    by 0x547AC5: ??? (in /usr/bin/python3.11)
==5813==    by 0x56A493: PyObject_Call (in /usr/bin/python3.11)
==5813==    by 0x5343AF: _PyEval_EvalFrameDefault (in /usr/bin/python3.11)
==5813==    by 0x51F066: _PyObject_FastCallDictTstate (in /usr/bin/python3.11)
==5813==    by 0x5B443B: ??? (in /usr/bin/python3.11)
==5813==    by 0x517E15: _PyObject_MakeTpCall (in /usr/bin/python3.11)
==5813==    by 0x53B1BB: ??? (in /usr/bin/python3.11)
==5813==    by 0x53ACF6: ??? (in /usr/bin/python3.11)
==5813== 
==5813== 3,840 bytes in 4 blocks are still reachable in loss record 143 of 174
==5813==    at 0x48407B4: malloc (vg_replace_malloc.c:381)
==5813==    by 0x50825A: PyType_GenericAlloc (in /usr/bin/python3.11)
==5813==    by 0x5187C7: ??? (in /usr/bin/python3.11)
==5813==    by 0x517E15: _PyObject_MakeTpCall (in /usr/bin/python3.11)
==5813==    by 0x5125C2: PyObject_CallFunction (in /usr/bin/python3.11)
==5813==    by 0x631A49: PyErr_NewException (in /usr/bin/python3.11)
==5813==    by 0x65AA212: PyInit__decimal (in /usr/lib/python3.11/lib-dynload/_decimal.cpython-311-x86_64-linux-gnu.so)
==5813==    by 0x6539FA: ??? (in /usr/bin/python3.11)
==5813==    by 0x54DDD7: ??? (in /usr/bin/python3.11)
==5813==    by 0x5343AF: _PyEval_EvalFrameDefault (in /usr/bin/python3.11)
==5813==    by 0x55C930: _PyFunction_Vectorcall (in /usr/bin/python3.11)
==5813==    by 0x54618E: ??? (in /usr/bin/python3.11)
==5813== 
==5813== 3,840 bytes in 4 blocks are still reachable in loss record 144 of 174
==5813==    at 0x48407B4: malloc (vg_replace_malloc.c:381)
==5813==    by 0x50825A: PyType_GenericAlloc (in /usr/bin/python3.11)
==5813==    by 0x5185D1: ??? (in /usr/bin/python3.11)
==5813==    by 0x517E15: _PyObject_MakeTpCall (in /usr/bin/python3.11)
==5813==    by 0x51F185: _PyObject_FastCallDictTstate (in /usr/bin/python3.11)
==5813==    by 0x53B1BB: ??? (in /usr/bin/python3.11)
==5813==    by 0x53ACF6: ??? (in /usr/bin/python3.11)
==5813==    by 0x53AC2B: PyObject_Vectorcall (in /usr/bin/python3.11)
==5813==    by 0x52B93F: _PyEval_EvalFrameDefault (in /usr/bin/python3.11)
==5813==    by 0x52360A: PyEval_EvalCode (in /usr/bin/python3.11)
==5813==    by 0x58EC4D: ??? (in /usr/bin/python3.11)
==5813==    by 0x53ACF6: ??? (in /usr/bin/python3.11)
==5813== 
==5813== 3,936 bytes in 1 blocks are still reachable in loss record 145 of 174
==5813==    at 0x484582F: realloc (vg_replace_malloc.c:1437)
==5813==    by 0x59F9A42: _nc_doalloc (in /usr/lib/x86_64-linux-gnu/libtinfo.so.6.4)
==5813==    by 0x5A0469B: _nc_read_termtype (in /usr/lib/x86_64-linux-gnu/libtinfo.so.6.4)
==5813==    by 0x5A04B1A: _nc_read_file_entry (in /usr/lib/x86_64-linux-gnu/libtinfo.so.6.4)
==5813==    by 0x5A04E7C: ??? (in /usr/lib/x86_64-linux-gnu/libtinfo.so.6.4)
==5813==    by 0x5A04FCB: _nc_read_entry2 (in /usr/lib/x86_64-linux-gnu/libtinfo.so.6.4)
==5813==    by 0x59FC018: ??? (in /usr/lib/x86_64-linux-gnu/libtinfo.so.6.4)
==5813==    by 0x59FC3D5: _nc_setupterm (in /usr/lib/x86_64-linux-gnu/libtinfo.so.6.4)
==5813==    by 0x5978983: ??? (in /usr/lib/python3.11/lib-dynload/_curses.cpython-311-x86_64-linux-gnu.so)
==5813==    by 0x53ACF6: ??? (in /usr/bin/python3.11)
==5813==    by 0x53AC2B: PyObject_Vectorcall (in /usr/bin/python3.11)
==5813==    by 0x52B93F: _PyEval_EvalFrameDefault (in /usr/bin/python3.11)
==5813== 
==5813== 3,936 bytes in 1 blocks are still reachable in loss record 146 of 174
==5813==    at 0x48407B4: malloc (vg_replace_malloc.c:381)
==5813==    by 0x59F70DE: ??? (in /usr/lib/x86_64-linux-gnu/libtinfo.so.6.4)
==5813==    by 0x59FC404: _nc_setupterm (in /usr/lib/x86_64-linux-gnu/libtinfo.so.6.4)
==5813==    by 0x5978983: ??? (in /usr/lib/python3.11/lib-dynload/_curses.cpython-311-x86_64-linux-gnu.so)
==5813==    by 0x53ACF6: ??? (in /usr/bin/python3.11)
==5813==    by 0x53AC2B: PyObject_Vectorcall (in /usr/bin/python3.11)
==5813==    by 0x52B93F: _PyEval_EvalFrameDefault (in /usr/bin/python3.11)
==5813==    by 0x51F066: _PyObject_FastCallDictTstate (in /usr/bin/python3.11)
==5813==    by 0x565972: ??? (in /usr/bin/python3.11)
==5813==    by 0x517E54: _PyObject_MakeTpCall (in /usr/bin/python3.11)
==5813==    by 0x52B93F: _PyEval_EvalFrameDefault (in /usr/bin/python3.11)
==5813==    by 0x52360A: PyEval_EvalCode (in /usr/bin/python3.11)
==5813== 
==5813== 4,560 bytes in 3 blocks are still reachable in loss record 147 of 174
==5813==    at 0x48407B4: malloc (vg_replace_malloc.c:381)
==5813==    by 0x500157: ??? (in /usr/bin/python3.11)
==5813==    by 0x508A47: ??? (in /usr/bin/python3.11)
==5813==    by 0x52DD5D: _PyEval_EvalFrameDefault (in /usr/bin/python3.11)
==5813==    by 0x52360A: PyEval_EvalCode (in /usr/bin/python3.11)
==5813==    by 0x58EC4D: ??? (in /usr/bin/python3.11)
==5813==    by 0x52ECC4: _PyEval_EvalFrameDefault (in /usr/bin/python3.11)
==5813==    by 0x55C930: _PyFunction_Vectorcall (in /usr/bin/python3.11)
==5813==    by 0x54618E: ??? (in /usr/bin/python3.11)
==5813==    by 0x58351A: PyObject_CallMethodObjArgs (in /usr/bin/python3.11)
==5813==    by 0x451A10: ??? (in /usr/bin/python3.11)
==5813==    by 0x530A22: _PyEval_EvalFrameDefault (in /usr/bin/python3.11)
==5813== 
==5813== 4,624 bytes in 1 blocks are still reachable in loss record 148 of 174
==5813==    at 0x48407B4: malloc (vg_replace_malloc.c:381)
==5813==    by 0x500157: ??? (in /usr/bin/python3.11)
==5813==    by 0x508A47: ??? (in /usr/bin/python3.11)
==5813==    by 0x501D1F: ??? (in /usr/bin/python3.11)
==5813==    by 0x518D23: ??? (in /usr/bin/python3.11)
==5813==    by 0x517E15: _PyObject_MakeTpCall (in /usr/bin/python3.11)
==5813==    by 0x52E996: _PyEval_EvalFrameDefault (in /usr/bin/python3.11)
==5813==    by 0x52360A: PyEval_EvalCode (in /usr/bin/python3.11)
==5813==    by 0x58EC4D: ??? (in /usr/bin/python3.11)
==5813==    by 0x53ACF6: ??? (in /usr/bin/python3.11)
==5813==    by 0x5343AF: _PyEval_EvalFrameDefault (in /usr/bin/python3.11)
==5813==    by 0x55C930: _PyFunction_Vectorcall (in /usr/bin/python3.11)
==5813== 
==5813== 4,920 bytes in 18 blocks are still reachable in loss record 149 of 174
==5813==    at 0x48455EF: calloc (vg_replace_malloc.c:1328)
==5813==    by 0x40125D3: calloc (rtld-malloc.h:44)
==5813==    by 0x40125D3: _dl_check_map_versions (dl-version.c:280)
==5813==    by 0x400B935: dl_open_worker_begin (dl-open.c:600)
==5813==    by 0x4AEBFC9: _dl_catch_exception (dl-error-skeleton.c:208)
==5813==    by 0x400B045: dl_open_worker (dl-open.c:782)
==5813==    by 0x4AEBFC9: _dl_catch_exception (dl-error-skeleton.c:208)
==5813==    by 0x400B437: _dl_open (dl-open.c:884)
==5813==    by 0x4A22437: dlopen_doit (dlopen.c:56)
==5813==    by 0x4AEBFC9: _dl_catch_exception (dl-error-skeleton.c:208)
==5813==    by 0x4AEC07E: _dl_catch_error (dl-error-skeleton.c:227)
==5813==    by 0x4A21F26: _dlerror_run (dlerror.c:138)
==5813==    by 0x4A224E8: dlopen_implementation (dlopen.c:71)
==5813==    by 0x4A224E8: dlopen@@GLIBC_2.34 (dlopen.c:81)
==5813== 
==5813== 5,344 bytes in 5 blocks are still reachable in loss record 150 of 174
==5813==    at 0x48407B4: malloc (vg_replace_malloc.c:381)
==5813==    by 0x51729D: PyDict_Copy (in /usr/bin/python3.11)
==5813==    by 0x518517: ??? (in /usr/bin/python3.11)
==5813==    by 0x517E15: _PyObject_MakeTpCall (in /usr/bin/python3.11)
==5813==    by 0x51F269: _PyObject_FastCallDictTstate (in /usr/bin/python3.11)
==5813==    by 0x53B1BB: ??? (in /usr/bin/python3.11)
==5813==    by 0x53ACF6: ??? (in /usr/bin/python3.11)
==5813==    by 0x53AC2B: PyObject_Vectorcall (in /usr/bin/python3.11)
==5813==    by 0x52B93F: _PyEval_EvalFrameDefault (in /usr/bin/python3.11)
==5813==    by 0x52360A: PyEval_EvalCode (in /usr/bin/python3.11)
==5813==    by 0x58EC4D: ??? (in /usr/bin/python3.11)
==5813==    by 0x53ACF6: ??? (in /usr/bin/python3.11)
==5813== 
==5813== 5,376 bytes in 7 blocks are still reachable in loss record 151 of 174
==5813==    at 0x48407B4: malloc (vg_replace_malloc.c:381)
==5813==    by 0x4FEA8A: ??? (in /usr/bin/python3.11)
==5813==    by 0x502B3D: ??? (in /usr/bin/python3.11)
==5813==    by 0x518D23: ??? (in /usr/bin/python3.11)
==5813==    by 0x5B3D037: ??? (in /usr/lib/python3.11/lib-dynload/_ctypes.cpython-311-x86_64-linux-gnu.so)
==5813==    by 0x517E15: _PyObject_MakeTpCall (in /usr/bin/python3.11)
==5813==    by 0x53B1BB: ??? (in /usr/bin/python3.11)
==5813==    by 0x53ACF6: ??? (in /usr/bin/python3.11)
==5813==    by 0x53AC2B: PyObject_Vectorcall (in /usr/bin/python3.11)
==5813==    by 0x52B93F: _PyEval_EvalFrameDefault (in /usr/bin/python3.11)
==5813==    by 0x52360A: PyEval_EvalCode (in /usr/bin/python3.11)
==5813==    by 0x58EC4D: ??? (in /usr/bin/python3.11)
==5813== 
==5813== 5,898 bytes in 6 blocks are still reachable in loss record 152 of 174
==5813==    at 0x48407B4: malloc (vg_replace_malloc.c:381)
==5813==    by 0x519E29: ??? (in /usr/bin/python3.11)
==5813==    by 0x517E15: _PyObject_MakeTpCall (in /usr/bin/python3.11)
==5813==    by 0x51F269: _PyObject_FastCallDictTstate (in /usr/bin/python3.11)
==5813==    by 0x53B1BB: ??? (in /usr/bin/python3.11)
==5813==    by 0x53ACF6: ??? (in /usr/bin/python3.11)
==5813==    by 0x53AC2B: PyObject_Vectorcall (in /usr/bin/python3.11)
==5813==    by 0x52B93F: _PyEval_EvalFrameDefault (in /usr/bin/python3.11)
==5813==    by 0x52360A: PyEval_EvalCode (in /usr/bin/python3.11)
==5813==    by 0x58EC4D: ??? (in /usr/bin/python3.11)
==5813==    by 0x53ACF6: ??? (in /usr/bin/python3.11)
==5813==    by 0x5343AF: _PyEval_EvalFrameDefault (in /usr/bin/python3.11)
==5813== 
==5813== 6,080 bytes in 7 blocks are still reachable in loss record 153 of 174
==5813==    at 0x48407B4: malloc (vg_replace_malloc.c:381)
==5813==    by 0x53A431: _PyCode_New (in /usr/bin/python3.11)
==5813==    by 0x524892: ??? (in /usr/bin/python3.11)
==5813==    by 0x524D02: ??? (in /usr/bin/python3.11)
==5813==    by 0x5246F6: ??? (in /usr/bin/python3.11)
==5813==    by 0x6336E3: ??? (in /usr/bin/python3.11)
==5813==    by 0x5B3297: ??? (in /usr/bin/python3.11)
==5813==    by 0x52C176: _PyEval_EvalFrameDefault (in /usr/bin/python3.11)
==5813==    by 0x55C930: _PyFunction_Vectorcall (in /usr/bin/python3.11)
==5813==    by 0x54618E: ??? (in /usr/bin/python3.11)
==5813==    by 0x58351A: PyObject_CallMethodObjArgs (in /usr/bin/python3.11)
==5813==    by 0x451A10: ??? (in /usr/bin/python3.11)
==5813== 
==5813== 6,144 bytes in 3 blocks are still reachable in loss record 154 of 174
==5813==    at 0x48407B4: malloc (vg_replace_malloc.c:381)
==5813==    by 0x5147B0: ??? (in /usr/bin/python3.11)
==5813==    by 0x5B536A: ??? (in /usr/bin/python3.11)
==5813==    by 0x52C176: _PyEval_EvalFrameDefault (in /usr/bin/python3.11)
==5813==    by 0x51F066: _PyObject_FastCallDictTstate (in /usr/bin/python3.11)
==5813==    by 0x5B443B: ??? (in /usr/bin/python3.11)
==5813==    by 0x517E15: _PyObject_MakeTpCall (in /usr/bin/python3.11)
==5813==    by 0x53B1BB: ??? (in /usr/bin/python3.11)
==5813==    by 0x53ACF6: ??? (in /usr/bin/python3.11)
==5813==    by 0x53AC2B: PyObject_Vectorcall (in /usr/bin/python3.11)
==5813==    by 0x52B93F: _PyEval_EvalFrameDefault (in /usr/bin/python3.11)
==5813==    by 0x52360A: PyEval_EvalCode (in /usr/bin/python3.11)
==5813== 
==5813== 6,720 bytes in 7 blocks are still reachable in loss record 155 of 174
==5813==    at 0x48407B4: malloc (vg_replace_malloc.c:381)
==5813==    by 0x50825A: PyType_GenericAlloc (in /usr/bin/python3.11)
==5813==    by 0x5185D1: ??? (in /usr/bin/python3.11)
==5813==    by 0x5B3D037: ??? (in /usr/lib/python3.11/lib-dynload/_ctypes.cpython-311-x86_64-linux-gnu.so)
==5813==    by 0x517E15: _PyObject_MakeTpCall (in /usr/bin/python3.11)
==5813==    by 0x53B1BB: ??? (in /usr/bin/python3.11)
==5813==    by 0x53ACF6: ??? (in /usr/bin/python3.11)
==5813==    by 0x53AC2B: PyObject_Vectorcall (in /usr/bin/python3.11)
==5813==    by 0x52B93F: _PyEval_EvalFrameDefault (in /usr/bin/python3.11)
==5813==    by 0x52360A: PyEval_EvalCode (in /usr/bin/python3.11)
==5813==    by 0x58EC4D: ??? (in /usr/bin/python3.11)
==5813==    by 0x53ACF6: ??? (in /usr/bin/python3.11)
==5813== 
==5813== 7,381 bytes in 6 blocks are still reachable in loss record 156 of 174
==5813==    at 0x48455EF: calloc (vg_replace_malloc.c:1328)
==5813==    by 0x400AAE9: calloc (rtld-malloc.h:44)
==5813==    by 0x400AAE9: _dl_new_object (dl-object.c:92)
==5813==    by 0x400651E: _dl_map_object_from_fd (dl-load.c:1063)
==5813==    by 0x4007EF4: _dl_map_object (dl-load.c:2272)
==5813==    by 0x4002280: openaux (dl-deps.c:64)
==5813==    by 0x4AEBFC9: _dl_catch_exception (dl-error-skeleton.c:208)
==5813==    by 0x40025E9: _dl_map_object_deps (dl-deps.c:232)
==5813==    by 0x400B8EC: dl_open_worker_begin (dl-open.c:592)
==5813==    by 0x4AEBFC9: _dl_catch_exception (dl-error-skeleton.c:208)
==5813==    by 0x400B045: dl_open_worker (dl-open.c:782)
==5813==    by 0x4AEBFC9: _dl_catch_exception (dl-error-skeleton.c:208)
==5813==    by 0x400B437: _dl_open (dl-open.c:884)
==5813== 
==5813== 7,952 bytes in 1 blocks are still reachable in loss record 157 of 174
==5813==    at 0x48455EF: calloc (vg_replace_malloc.c:1328)
==5813==    by 0x59F87A7: ??? (in /usr/lib/x86_64-linux-gnu/libtinfo.so.6.4)
==5813==    by 0x59F8F1A: _nc_find_type_entry (in /usr/lib/x86_64-linux-gnu/libtinfo.so.6.4)
==5813==    by 0x59FD6D7: tigetstr_sp (in /usr/lib/x86_64-linux-gnu/libtinfo.so.6.4)
==5813==    by 0x5979681: ??? (in /usr/lib/python3.11/lib-dynload/_curses.cpython-311-x86_64-linux-gnu.so)
==5813==    by 0x5458A2: ??? (in /usr/bin/python3.11)
==5813==    by 0x53AC2B: PyObject_Vectorcall (in /usr/bin/python3.11)
==5813==    by 0x52B93F: _PyEval_EvalFrameDefault (in /usr/bin/python3.11)
==5813==    by 0x51F066: _PyObject_FastCallDictTstate (in /usr/bin/python3.11)
==5813==    by 0x565972: ??? (in /usr/bin/python3.11)
==5813==    by 0x517E54: _PyObject_MakeTpCall (in /usr/bin/python3.11)
==5813==    by 0x52B93F: _PyEval_EvalFrameDefault (in /usr/bin/python3.11)
==5813== 
==5813== 8,640 bytes in 9 blocks are still reachable in loss record 158 of 174
==5813==    at 0x48407B4: malloc (vg_replace_malloc.c:381)
==5813==    by 0x50825A: PyType_GenericAlloc (in /usr/bin/python3.11)
==5813==    by 0x5187C7: ??? (in /usr/bin/python3.11)
==5813==    by 0x517E15: _PyObject_MakeTpCall (in /usr/bin/python3.11)
==5813==    by 0x5125C2: PyObject_CallFunction (in /usr/bin/python3.11)
==5813==    by 0x631A49: PyErr_NewException (in /usr/bin/python3.11)
==5813==    by 0x65AA0EB: PyInit__decimal (in /usr/lib/python3.11/lib-dynload/_decimal.cpython-311-x86_64-linux-gnu.so)
==5813==    by 0x6539FA: ??? (in /usr/bin/python3.11)
==5813==    by 0x54DDD7: ??? (in /usr/bin/python3.11)
==5813==    by 0x5343AF: _PyEval_EvalFrameDefault (in /usr/bin/python3.11)
==5813==    by 0x55C930: _PyFunction_Vectorcall (in /usr/bin/python3.11)
==5813==    by 0x54618E: ??? (in /usr/bin/python3.11)
==5813== 
==5813== 9,600 bytes in 10 blocks are still reachable in loss record 159 of 174
==5813==    at 0x48407B4: malloc (vg_replace_malloc.c:381)
==5813==    by 0x50825A: PyType_GenericAlloc (in /usr/bin/python3.11)
==5813==    by 0x5187C7: ??? (in /usr/bin/python3.11)
==5813==    by 0x517E15: _PyObject_MakeTpCall (in /usr/bin/python3.11)
==5813==    by 0x51F269: _PyObject_FastCallDictTstate (in /usr/bin/python3.11)
==5813==    by 0x53B1BB: ??? (in /usr/bin/python3.11)
==5813==    by 0x53ACF6: ??? (in /usr/bin/python3.11)
==5813==    by 0x53AC2B: PyObject_Vectorcall (in /usr/bin/python3.11)
==5813==    by 0x52B93F: _PyEval_EvalFrameDefault (in /usr/bin/python3.11)
==5813==    by 0x52360A: PyEval_EvalCode (in /usr/bin/python3.11)
==5813==    by 0x58EC4D: ??? (in /usr/bin/python3.11)
==5813==    by 0x53ACF6: ??? (in /usr/bin/python3.11)
==5813== 
==5813== 11,589 bytes in 11 blocks are still reachable in loss record 160 of 174
==5813==    at 0x48407B4: malloc (vg_replace_malloc.c:381)
==5813==    by 0x52AFA1: ??? (in /usr/bin/python3.11)
==5813==    by 0x524A93: ??? (in /usr/bin/python3.11)
==5813==    by 0x524C0D: ??? (in /usr/bin/python3.11)
==5813==    by 0x5246F6: ??? (in /usr/bin/python3.11)
==5813==    by 0x524D02: ??? (in /usr/bin/python3.11)
==5813==    by 0x5246F6: ??? (in /usr/bin/python3.11)
==5813==    by 0x6336E3: ??? (in /usr/bin/python3.11)
==5813==    by 0x5B3297: ??? (in /usr/bin/python3.11)
==5813==    by 0x52C176: _PyEval_EvalFrameDefault (in /usr/bin/python3.11)
==5813==    by 0x55C930: _PyFunction_Vectorcall (in /usr/bin/python3.11)
==5813==    by 0x54618E: ??? (in /usr/bin/python3.11)
==5813== 
==5813== 11,712 bytes in 18 blocks are still reachable in loss record 161 of 174
==5813==    at 0x48407B4: malloc (vg_replace_malloc.c:381)
==5813==    by 0x53A431: _PyCode_New (in /usr/bin/python3.11)
==5813==    by 0x524892: ??? (in /usr/bin/python3.11)
==5813==    by 0x524D02: ??? (in /usr/bin/python3.11)
==5813==    by 0x5246F6: ??? (in /usr/bin/python3.11)
==5813==    by 0x524D02: ??? (in /usr/bin/python3.11)
==5813==    by 0x5246F6: ??? (in /usr/bin/python3.11)
==5813==    by 0x6336E3: ??? (in /usr/bin/python3.11)
==5813==    by 0x5B3297: ??? (in /usr/bin/python3.11)
==5813==    by 0x52C176: _PyEval_EvalFrameDefault (in /usr/bin/python3.11)
==5813==    by 0x55C930: _PyFunction_Vectorcall (in /usr/bin/python3.11)
==5813==    by 0x54618E: ??? (in /usr/bin/python3.11)
==5813== 
==5813== 12,480 bytes in 13 blocks are still reachable in loss record 162 of 174
==5813==    at 0x48407B4: malloc (vg_replace_malloc.c:381)
==5813==    by 0x50825A: PyType_GenericAlloc (in /usr/bin/python3.11)
==5813==    by 0x5187C7: ??? (in /usr/bin/python3.11)
==5813==    by 0x517E15: _PyObject_MakeTpCall (in /usr/bin/python3.11)
==5813==    by 0x51F185: _PyObject_FastCallDictTstate (in /usr/bin/python3.11)
==5813==    by 0x53B1BB: ??? (in /usr/bin/python3.11)
==5813==    by 0x53ACF6: ??? (in /usr/bin/python3.11)
==5813==    by 0x53AC2B: PyObject_Vectorcall (in /usr/bin/python3.11)
==5813==    by 0x52B93F: _PyEval_EvalFrameDefault (in /usr/bin/python3.11)
==5813==    by 0x52360A: PyEval_EvalCode (in /usr/bin/python3.11)
==5813==    by 0x58EC4D: ??? (in /usr/bin/python3.11)
==5813==    by 0x53ACF6: ??? (in /usr/bin/python3.11)
==5813== 
==5813== 13,056 bytes in 17 blocks are still reachable in loss record 163 of 174
==5813==    at 0x48407B4: malloc (vg_replace_malloc.c:381)
==5813==    by 0x4FEA8A: ??? (in /usr/bin/python3.11)
==5813==    by 0x502B3D: ??? (in /usr/bin/python3.11)
==5813==    by 0x518D23: ??? (in /usr/bin/python3.11)
==5813==    by 0x517E15: _PyObject_MakeTpCall (in /usr/bin/python3.11)
==5813==    by 0x51F185: _PyObject_FastCallDictTstate (in /usr/bin/python3.11)
==5813==    by 0x53B1BB: ??? (in /usr/bin/python3.11)
==5813==    by 0x53ACF6: ??? (in /usr/bin/python3.11)
==5813==    by 0x53AC2B: PyObject_Vectorcall (in /usr/bin/python3.11)
==5813==    by 0x52B93F: _PyEval_EvalFrameDefault (in /usr/bin/python3.11)
==5813==    by 0x52360A: PyEval_EvalCode (in /usr/bin/python3.11)
==5813==    by 0x58EC4D: ??? (in /usr/bin/python3.11)
==5813== 
==5813== 15,280 bytes in 3 blocks are still reachable in loss record 164 of 174
==5813==    at 0x48407B4: malloc (vg_replace_malloc.c:381)
==5813==    by 0x500157: ??? (in /usr/bin/python3.11)
==5813==    by 0x508A47: ??? (in /usr/bin/python3.11)
==5813==    by 0x52DD5D: _PyEval_EvalFrameDefault (in /usr/bin/python3.11)
==5813==    by 0x52360A: PyEval_EvalCode (in /usr/bin/python3.11)
==5813==    by 0x58EC4D: ??? (in /usr/bin/python3.11)
==5813==    by 0x53ACF6: ??? (in /usr/bin/python3.11)
==5813==    by 0x53AC2B: PyObject_Vectorcall (in /usr/bin/python3.11)
==5813==    by 0x52B93F: _PyEval_EvalFrameDefault (in /usr/bin/python3.11)
==5813==    by 0x55C930: _PyFunction_Vectorcall (in /usr/bin/python3.11)
==5813==    by 0x54618E: ??? (in /usr/bin/python3.11)
==5813==    by 0x58351A: PyObject_CallMethodObjArgs (in /usr/bin/python3.11)
==5813== 
==5813== 16,128 bytes in 21 blocks are still reachable in loss record 165 of 174
==5813==    at 0x48407B4: malloc (vg_replace_malloc.c:381)
==5813==    by 0x4FEA8A: ??? (in /usr/bin/python3.11)
==5813==    by 0x502B3D: ??? (in /usr/bin/python3.11)
==5813==    by 0x518D23: ??? (in /usr/bin/python3.11)
==5813==    by 0x517E15: _PyObject_MakeTpCall (in /usr/bin/python3.11)
==5813==    by 0x51F269: _PyObject_FastCallDictTstate (in /usr/bin/python3.11)
==5813==    by 0x53B1BB: ??? (in /usr/bin/python3.11)
==5813==    by 0x53ACF6: ??? (in /usr/bin/python3.11)
==5813==    by 0x53AC2B: PyObject_Vectorcall (in /usr/bin/python3.11)
==5813==    by 0x52B93F: _PyEval_EvalFrameDefault (in /usr/bin/python3.11)
==5813==    by 0x52360A: PyEval_EvalCode (in /usr/bin/python3.11)
==5813==    by 0x58EC4D: ??? (in /usr/bin/python3.11)
==5813== 
==5813== 16,600 bytes in 17 blocks are still reachable in loss record 166 of 174
==5813==    at 0x48407B4: malloc (vg_replace_malloc.c:381)
==5813==    by 0x50825A: PyType_GenericAlloc (in /usr/bin/python3.11)
==5813==    by 0x51968E: ??? (in /usr/bin/python3.11)
==5813==    by 0x517E15: _PyObject_MakeTpCall (in /usr/bin/python3.11)
==5813==    by 0x51F269: _PyObject_FastCallDictTstate (in /usr/bin/python3.11)
==5813==    by 0x53B1BB: ??? (in /usr/bin/python3.11)
==5813==    by 0x53ACF6: ??? (in /usr/bin/python3.11)
==5813==    by 0x53AC2B: PyObject_Vectorcall (in /usr/bin/python3.11)
==5813==    by 0x52B93F: _PyEval_EvalFrameDefault (in /usr/bin/python3.11)
==5813==    by 0x52360A: PyEval_EvalCode (in /usr/bin/python3.11)
==5813==    by 0x58EC4D: ??? (in /usr/bin/python3.11)
==5813==    by 0x53ACF6: ??? (in /usr/bin/python3.11)
==5813== 
==5813== 17,053 bytes in 18 blocks are still reachable in loss record 167 of 174
==5813==    at 0x48407B4: malloc (vg_replace_malloc.c:381)
==5813==    by 0x52AFA1: ??? (in /usr/bin/python3.11)
==5813==    by 0x524A93: ??? (in /usr/bin/python3.11)
==5813==    by 0x524BE9: ??? (in /usr/bin/python3.11)
==5813==    by 0x5246F6: ??? (in /usr/bin/python3.11)
==5813==    by 0x524D02: ??? (in /usr/bin/python3.11)
==5813==    by 0x5246F6: ??? (in /usr/bin/python3.11)
==5813==    by 0x6336E3: ??? (in /usr/bin/python3.11)
==5813==    by 0x5B3297: ??? (in /usr/bin/python3.11)
==5813==    by 0x52C176: _PyEval_EvalFrameDefault (in /usr/bin/python3.11)
==5813==    by 0x55C930: _PyFunction_Vectorcall (in /usr/bin/python3.11)
==5813==    by 0x54618E: ??? (in /usr/bin/python3.11)
==5813== 
==5813== 18,240 bytes in 19 blocks are still reachable in loss record 168 of 174
==5813==    at 0x48407B4: malloc (vg_replace_malloc.c:381)
==5813==    by 0x50825A: PyType_GenericAlloc (in /usr/bin/python3.11)
==5813==    by 0x5185D1: ??? (in /usr/bin/python3.11)
==5813==    by 0x517E15: _PyObject_MakeTpCall (in /usr/bin/python3.11)
==5813==    by 0x51F269: _PyObject_FastCallDictTstate (in /usr/bin/python3.11)
==5813==    by 0x53B1BB: ??? (in /usr/bin/python3.11)
==5813==    by 0x53ACF6: ??? (in /usr/bin/python3.11)
==5813==    by 0x53AC2B: PyObject_Vectorcall (in /usr/bin/python3.11)
==5813==    by 0x52B93F: _PyEval_EvalFrameDefault (in /usr/bin/python3.11)
==5813==    by 0x52360A: PyEval_EvalCode (in /usr/bin/python3.11)
==5813==    by 0x58EC4D: ??? (in /usr/bin/python3.11)
==5813==    by 0x53ACF6: ??? (in /usr/bin/python3.11)
==5813== 
==5813== 19,348 bytes in 15 blocks are still reachable in loss record 169 of 174
==5813==    at 0x48455EF: calloc (vg_replace_malloc.c:1328)
==5813==    by 0x400AAE9: calloc (rtld-malloc.h:44)
==5813==    by 0x400AAE9: _dl_new_object (dl-object.c:92)
==5813==    by 0x400651E: _dl_map_object_from_fd (dl-load.c:1063)
==5813==    by 0x4007EF4: _dl_map_object (dl-load.c:2272)
==5813==    by 0x400B884: dl_open_worker_begin (dl-open.c:534)
==5813==    by 0x4AEBFC9: _dl_catch_exception (dl-error-skeleton.c:208)
==5813==    by 0x400B045: dl_open_worker (dl-open.c:782)
==5813==    by 0x4AEBFC9: _dl_catch_exception (dl-error-skeleton.c:208)
==5813==    by 0x400B437: _dl_open (dl-open.c:884)
==5813==    by 0x4A22437: dlopen_doit (dlopen.c:56)
==5813==    by 0x4AEBFC9: _dl_catch_exception (dl-error-skeleton.c:208)
==5813==    by 0x4AEC07E: _dl_catch_error (dl-error-skeleton.c:227)
==5813== 
==5813== 20,688 bytes in 4 blocks are still reachable in loss record 170 of 174
==5813==    at 0x48407B4: malloc (vg_replace_malloc.c:381)
==5813==    by 0x500157: ??? (in /usr/bin/python3.11)
==5813==    by 0x508A47: ??? (in /usr/bin/python3.11)
==5813==    by 0x501D1F: ??? (in /usr/bin/python3.11)
==5813==    by 0x518D23: ??? (in /usr/bin/python3.11)
==5813==    by 0x517E15: _PyObject_MakeTpCall (in /usr/bin/python3.11)
==5813==    by 0x51F269: _PyObject_FastCallDictTstate (in /usr/bin/python3.11)
==5813==    by 0x53B1BB: ??? (in /usr/bin/python3.11)
==5813==    by 0x53ACF6: ??? (in /usr/bin/python3.11)
==5813==    by 0x53AC2B: PyObject_Vectorcall (in /usr/bin/python3.11)
==5813==    by 0x52B93F: _PyEval_EvalFrameDefault (in /usr/bin/python3.11)
==5813==    by 0x52360A: PyEval_EvalCode (in /usr/bin/python3.11)
==5813== 
==5813== 30,768 bytes in 15 blocks are still reachable in loss record 171 of 174
==5813==    at 0x48407B4: malloc (vg_replace_malloc.c:381)
==5813==    by 0x500157: ??? (in /usr/bin/python3.11)
==5813==    by 0x508A47: ??? (in /usr/bin/python3.11)
==5813==    by 0x52DD5D: _PyEval_EvalFrameDefault (in /usr/bin/python3.11)
==5813==    by 0x52360A: PyEval_EvalCode (in /usr/bin/python3.11)
==5813==    by 0x58EC4D: ??? (in /usr/bin/python3.11)
==5813==    by 0x53ACF6: ??? (in /usr/bin/python3.11)
==5813==    by 0x5343AF: _PyEval_EvalFrameDefault (in /usr/bin/python3.11)
==5813==    by 0x55C930: _PyFunction_Vectorcall (in /usr/bin/python3.11)
==5813==    by 0x54618E: ??? (in /usr/bin/python3.11)
==5813==    by 0x58351A: PyObject_CallMethodObjArgs (in /usr/bin/python3.11)
==5813==    by 0x451A10: ??? (in /usr/bin/python3.11)
==5813== 
==5813== 37,480 bytes in 39 blocks are still reachable in loss record 172 of 174
==5813==    at 0x48407B4: malloc (vg_replace_malloc.c:381)
==5813==    by 0x50825A: PyType_GenericAlloc (in /usr/bin/python3.11)
==5813==    by 0x51968E: ??? (in /usr/bin/python3.11)
==5813==    by 0x5B48BB: ??? (in /usr/bin/python3.11)
==5813==    by 0x547AC5: ??? (in /usr/bin/python3.11)
==5813==    by 0x56A493: PyObject_Call (in /usr/bin/python3.11)
==5813==    by 0x5343AF: _PyEval_EvalFrameDefault (in /usr/bin/python3.11)
==5813==    by 0x51F066: _PyObject_FastCallDictTstate (in /usr/bin/python3.11)
==5813==    by 0x5B443B: ??? (in /usr/bin/python3.11)
==5813==    by 0x517E15: _PyObject_MakeTpCall (in /usr/bin/python3.11)
==5813==    by 0x53B1BB: ??? (in /usr/bin/python3.11)
==5813==    by 0x53ACF6: ??? (in /usr/bin/python3.11)
==5813== 
==5813== 131,072 bytes in 1 blocks are still reachable in loss record 173 of 174
==5813==    at 0x48455EF: calloc (vg_replace_malloc.c:1328)
==5813==    by 0x62CA06: ??? (in /usr/bin/python3.11)
==5813==    by 0x4FB423: ??? (in /usr/bin/python3.11)
==5813==    by 0x4FAF08: _PyObject_GC_New (in /usr/bin/python3.11)
==5813==    by 0x4FAD69: PyList_New (in /usr/bin/python3.11)
==5813==    by 0x4F9361: ??? (in /usr/bin/python3.11)
==5813==    by 0x628925: ??? (in /usr/bin/python3.11)
==5813==    by 0x62863A: Py_InitializeFromConfig (in /usr/bin/python3.11)
==5813==    by 0x6278E8: ??? (in /usr/bin/python3.11)
==5813==    by 0x62772F: ??? (in /usr/bin/python3.11)
==5813==    by 0x6275C6: Py_BytesMain (in /usr/bin/python3.11)
==5813==    by 0x49C4249: (below main) (libc_start_call_main.h:58)
==5813== 
==5813== 262,144 bytes in 1 blocks are still reachable in loss record 174 of 174
==5813==    at 0x48455EF: calloc (vg_replace_malloc.c:1328)
==5813==    by 0x62C989: ??? (in /usr/bin/python3.11)
==5813==    by 0x4FB423: ??? (in /usr/bin/python3.11)
==5813==    by 0x4FAF08: _PyObject_GC_New (in /usr/bin/python3.11)
==5813==    by 0x4FAD69: PyList_New (in /usr/bin/python3.11)
==5813==    by 0x4F9361: ??? (in /usr/bin/python3.11)
==5813==    by 0x628925: ??? (in /usr/bin/python3.11)
==5813==    by 0x62863A: Py_InitializeFromConfig (in /usr/bin/python3.11)
==5813==    by 0x6278E8: ??? (in /usr/bin/python3.11)
==5813==    by 0x62772F: ??? (in /usr/bin/python3.11)
==5813==    by 0x6275C6: Py_BytesMain (in /usr/bin/python3.11)
==5813==    by 0x49C4249: (below main) (libc_start_call_main.h:58)
==5813== 
==5813== LEAK SUMMARY:
==5813==    definitely lost: 0 bytes in 0 blocks
==5813==    indirectly lost: 0 bytes in 0 blocks
==5813==      possibly lost: 0 bytes in 0 blocks
==5813==    still reachable: 886,700 bytes in 531 blocks
==5813==         suppressed: 0 bytes in 0 blocks
==5813== 
==5813== ERROR SUMMARY: 0 errors from 0 contexts (suppressed: 0 from 0)
